Workbook

Sheet 流程指引
A1: 商机-项目关键节点评审管理流程指引
A2: 版本：V1.0 | 生效日期：2026年 月 日 | 编制：李晓 | 审核：CMO/企划办
A4: 一、管理目的与适用范围
A5: 本流程指引旨在规范公司商机-项目全生命周期关键节点的评审管控，覆盖市场营销部、G1和B2业务线。通过建立标准化的评审规则与红黄绿灯分级机制，实现项目风险的前置识别、分级管控与高效决策，确保公司项目质量与经营安全。 适用范围：公司所有商机-项目，涵盖以下四大关键节点：①POC投入 ②售前立项评审 ③投标决策评审 ④项目关键事项决策 评审分级：部门级项目评审会（常规项目）→ XO级项目评审会（重大/高风险项目）。触发XO级评审的场景详见各环节具体规则。
A7: 二、红黄绿灯分级评审机制
A8: 绿灯（免上会） | C8: 所有评审指标均满足"免上会"标准 → 项目无需上会评审，智能体评审为绿灯后即可通过，直接推进至下一阶段。市场营销支持处留档备查。
A9: 黄灯（上会决策） | C9: 存在一项或多项指标触发"上会决策"标准 → 项目需提交至线下评审会进行决策。会议分级：部门级评审会（常规黄灯项目）或XO级评审会（触发XO级升级条件的项目）。
A10: 红灯（红线禁止） | C10: 存在任一指标触发"红线禁止"标准 → 项目打回，要求销售/项目经理与客户重新协商调整后再次提交评审。红线项不可豁免。
A12: 三、各环节评审流程详述
A14: 3.1 项目POC投入（邮件审批）
B15: 事项 | C15: 申请人 | D15: 审批方式 | E15: 审批人 | F15: 审批要点 | G15: 分级 | H15: 使用模板 | I15: 后续动作 | J15: 备注
B16: 项目POC投入 | C16: 销售经理 | D16: 邮件审批 | E16: 区域交付负责人 | F16: 销售经理发送邮件申请，由区域交付负责人评估交付资源情况，确认资源OK后安排交付。 | G16: 无分级 （不纳入红黄绿灯机制） | H16: 《POC投入申请表》 | I16: 交付完成后归档 | J16: 未在产品POC范围内的售前投入，均需完成售前立项评审
A18: 3.2 售前立项评审（项目评审委员会决策）
A19: 【流程步骤】 Step 1 信息收集：销售经理/项目经理填写《售前立项评审-信息收集与前置评审表》的"项目基础信息"及"可由销售经理/项目经理判断的规则指标"，提交至销售支持组。 Step 2 前置评审：销售支持组 分发至各业务/职能部门（交付负责人、业财、采购经理、法务、公共事务等），各部门在规定时间内完成各自负责指标的核实与风险判定，针对无法量化指标需填写前置评审意见及红黄绿灯等级。 Step 3 风险评定：销售支持组汇总前置评审意见表，并使用评审智能体进行项目风险评定，输出项目灯态和风险报告（红、黄灯需输出）。 Step 4 分类处理： · 绿灯项目 → 免上会，邮件输出智能体评审结论并留档备查，项目推进至下一阶段。 · 红灯项目 → 打回，销售经理与客户重新协商，调整后可再次提交。 · 黄灯项目 → 进入线下评审会，根据触发条件确定会议级别（部门级/XO级）。 Step 5 评审决策：评审会输出决策结果，销售支持组/企划办归档并跟踪后续执行。
B20: 申请人 | C20: 协同人 | D20: 使用模板 | E20: 前置评审成员 | F20: 部门级决策机制 | G20: XO级决策机制 | H20: 部门级提报机制 | I20: XO级提报机制 | J20: 评审后续
B21: 销售经理 | C21: 项目经理、解决方案 | D21: 《售前立项评审-信息收集与前置评审表》 《项目贡献毛利率及成本预算表》 | E21: 交付负责人、产研负责人、财务BP、采购BP、法务、公共事务等 | F21: 决策方式：部门级项目评审会 会议周期：每周二 主述人：销售经理 决策人：部门级项目评审委员会 主办组织：销售支持组 | G21: 决策方式：XO级项目评审会 会议周期：每周五 主述人：销售经理 决策人：XO级项目评审委员会 主办组织：企划办 | H21: 提报路径：销售经理→销售支持组 部门级时间要求： ①提前1周进行项目提报 ②提前2个工作日完成材料提交，材料提交前可自行通过智能体判断项目灯态 ③每周一销售支持组汇总智能体项目灯态，绿灯项目免上会，红灯项目驳回，黄灯项目注意项目关键风险点评审会决策，并邮件发出 | I21: 提报路径：销售经理→销售支持组 时间要求：提前完成部门级评审会 | J21: 评审通过后，由项目经理发起PMS项目建立申请，将评审决策文件、项目贡献毛利率及成本预算表（初算）作为审批附件上传；由交付负责人审批通过
A23: 3.3 投标决策评审（项目评审委员会决策）
A24: 【流程步骤】 Step 1 信息收集：销售经理填写《投标决策评审-信息收集与前置评审表》的"项目基础信息"及"可由销售经理判断的规则指标"，提交至销售支持组。 Step 2 前置评审：销售支持组 分发至各业务/职能部门（交付负责人、业财、采购经理、法务、公共事务等），各部门在规定时间内完成各自负责指标的核实与风险判定，针对无法量化指标需填写前置评审意见及红黄绿灯等级。 Step 3 风险评定：销售支持组汇总前置评审意见表，并使用评审智能体进行项目风险评定，输出项目灯态和风险报告（红、黄灯需输出）。 Step 4 分类处理： · 绿灯项目 → 免上会，邮件输出智能体评审结论并留档备查，项目推进至下一阶段。 · 红灯项目 → 打回，销售经理与客户重新协商，调整后可再次提交。 · 黄灯项目 → 进入线下评审会，根据触发条件确定会议级别（部门级/XO级）。 Step 5 评审决策：评审会输出决策结果，销售支持组/企划办归档并跟踪后续执行。
B25: 申请人 | C25: 协同人 | D25: 使用模板 | E25: 前置评审成员 | F25: 部门级决策机制 | G25: XO级决策机制 | H25: 部门级提报机制 | I25: XO级提报机制 | J25: 评审后续
B26: 销售经理 | C26: 项目经理、解决方案 | D26: 《投标决策评审-信息收集与前置评审表》 《项目贡献毛利率及成本预算表》 | E26: 交付负责人、产研负责人、财务BP、采购BP、法务、公共事务等 | F26: 决策方式：部门级项目评审会 会议周期：每周二 主述人：销售经理 决策人：部门级项目评审委员会 主办组织：销售支持组 | G26: 决策方式：XO级项目评审会 会议周期：每周五 主述人：销售经理 决策人：XO级项目评审委员会 主办组织：企划办 | H26: 提报路径：销售经理→销售支持组 部门级时间要求： ①提前1周进行项目提报 ②提前2个工作日完成材料提交，材料提交前可自行通过智能体判断项目灯态 ③每周一销售支持组汇总智能体项目灯态，绿灯项目免上会，红灯项目驳回，黄灯项目注意项目关键风险点评审会决策，并邮件发出 | I26: 提报路径：销售经理→销售支持组 时间要求：提前完成部门级评审会 | J26: 评审通过后，由项目经理发起PMS项目建立申请，将评审决策文件、项目贡献毛利率及成本预算表（概算）作为审批附件上传；由交付负责人审批通过。 评审不通过且前期已有预投入，需项目经理进行PMS项目关闭，通知项目组成员在3个工作日内完成收尾。
A28: 3.4 项目关键事项决策（项目评审委员会决策）
A29: 【流程步骤】 Step 1 信息收集：项目经理填写《项目关键事项决策-信息收集与前置评审表》的"项目基础信息"及"可由项目经理判断的规则指标"，提交至销售支持组。 Step 2 前置评审：销售支持组 分发至各业务/职能部门（交付负责人、业财、采购经理、法务、公共事务等），各部门在规定时间内完成各自负责指标的核实与风险判定，针对无法量化指标需填写前置评审意见及红黄绿灯等级。 Step 3 风险评定：销售支持组汇总前置评审意见表，并使用评审智能体进行项目风险评定，输出项目灯态和风险报告（红、黄灯需输出）。 Step 4 分类处理： · 绿灯项目 → 免上会，邮件输出智能体评审结论并留档备查，项目推进至下一阶段。 · 红灯项目 → 打回，销售经理与客户重新协商，调整后可再次提交。 · 黄灯项目 → 进入线下评审会，根据触发条件确定会议级别（部门级/XO级）。 Step 5 评审决策：评审会输出决策结果，销售支持组/企划办归档并跟踪后续执行。
B30: 申请人 | C30: 协同人 | D30: 使用模板 | E30: 前置评审成员 | F30: 部门级决策机制 | G30: XO级决策机制 | H30: 部门级提报机制 | I30: XO级提报机制 | J30: 评审后续
B31: 项目经理 | C31: 销售经理 | D31: 《项目关键事项决策-信息收集与前置评审表》 《项目贡献毛利率及成本预算表》 《项目变更申请表》（如涉及变更） | E31: 区域交付负责人、项目管理部负责人、业财、采购经理（如有） | F31: 决策方式：部门级项目评审会 会议周期：每周二 主述人：项目经理 决策人：部门级项目评审委员会 主办组织：项目管理部 | G31: 决策方式：XO级项目评审会 会议周期：每周五 主述人：项目管理部负责人 决策人：XO级项目评审委员会 主办组织：企划办 | H31: 提报路径：项目经理→销售支持组 时间要求： ①提前5个工作日进行提报 ②提前2个工作日完成材料提交 ③每周一销售支持组汇总智能体项目灯态，绿灯项目免上会，红灯项目驳回，黄灯项目注意项目关键风险点评审会决策，并邮件发出 | I31: 提报路径：项目经理→销售支持组 时间要求： 提前完成部门级评审会 | J31: 评审通过后，由项目经理发起PMS项目变更申请（如涉及变更），将评审决策文件、项目贡献毛利率及成本预算表（变更版）作为审批附件上传；由交付负责人审批通过。
A33: 四、触发XO级评审会的场景（部门级 → XO级升级条件）
A34: 序号 | B34: 触发场景 | H34: 升级级别
A35: 1 | B35: 项目运维周期：大于3年 | H35: XO级
A36: 2 | B36: 存在指定供应商 | H36: XO级
A37: 3 | B37: 部门级评审意见未达成一致 | H37: XO级
A38: 4 | B38: 毛利维度：项目贡献毛利率＜0% | H38: XO级
A39: 5 | B39: 合同金额：大于500万 | H39: XO级
A40: 6 | B40: 提前投入大于50万 | H40: XO级
A41: 7 | B41: 过单项目（分包比例大于70%） | H41: XO级
A42: 8 | B42: 项目合同存在提供担保或为他人提供担保 | H42: XO级
A43: 9 | B43: 项目合同存在竞业等事项 | H43: XO级
A44: 10 | B44: 存在项目推广激励（to对外，比例≥15%或金额≥30w） | H44: XO级
A45: 11 | B45: 存在项目推广激励（to顺丰体系内、激励制度规则条款外） | H45: XO级
A48: 五、关键角色与职责
A49: 序号 | B49: 角色 | D49: 职责说明
A50: 1 | B50: 销售经理 | D50: 售前立项/投标决策的发起人，负责填写项目基础信息及可判断的指标，与客户协商调整红灯事项
...

Sheet 售前立项评审-信息收集与前置评审
A1: 售前立项评审 — 信息收集与前置评审表
A4: 商机名称 | D4: 昆山市消防要素可视化分析平台 | G4: 商机代码 | I4: PL00008068
A5: 最终客户名称 | D5: 昆山市消防救援大队 | G5: 商机阶段 | I5: 提前投入
A6: 业务线 | D6: G1 | G6: 营销区域 | I6: 华北营销处-区域
A7: 预计合同金额（万元） | D7: 30 | G7: 预计签单时间 | I7: 46365
A8: 销售经理 | D8: 陈俊 | G8: 项目经理 | I8: 樊茫
A9: 项目概述 | D9: 当前，昆山市消防救援大队已建成 “火眼系统”，具备火灾风险单位智能研判、火灾警情实时监测等能力，汇聚了重点单位、历史火情、隐患排查等海量消防业务数据。但系统存在业务数据与空间地理信息脱节、风险分布不直观、应急调度缺乏空间底图支撑、多源数据难以一体化分析等问题，无法满足现代化消防 “精准监管、快速响应、科学决策” 需求。为激活 “火眼系统” 数据价值，推进智慧城市与智慧消防建设，亟需建设昆山市消防要素可视化分析平台，通过空间网格关联、GIS 底图可视化及多维度数据分析，实现火眼系统风险、警情、隐患、资源等数据与地理空间深度融合，构建消防要素 “一张图” 统管模式，全面提升全市火灾风险防控、应急救援指挥和消防治理精细化水平。 提前投入共计3.13万元，明细如下： ①项目经理：正编投入1人，3.5人天，5936元。 ②交付岗位：正编投入1人，15人天，25440元。
A10: 是否涉及测绘（涉及外业采集或地图） | D10: 否 | G10: 是否涉及分包提前进场 | I10: 否
A11: 预计售前投入成本（万元） | D11: 3.13 | G11: 预计售前实施周期 | I11: 1个月
A13: Part B：非量化类关键评审指标-前置评审
A14: 序号 | B14: 评审维度 （部门） | C14: 评判指标 | D14: 辅助指标/说明 | E14: 绿灯标准 （免上会） | F14: 黄灯标准 （上会决策） | H14: 红灯标准 （红线禁止） | I14: 风险等级 （红/黄/绿） | J14: 前置评审意见 | K14: 前置评审人 （签字）
I15: 部门评审↓ | J15: 部门评审↓ | K15: 部门评审↓
A16: 1 | B16: 业务 | C16: 技术可行性 | E16: 无技术风险 | F16: 存在交付侧技术风险，但在客户需求边界/预期交付边界控制的情况下，可完成交付 | H16: 技术侧无法交付，因成本/资质问题无法分包 | I16: 绿灯 | J16: 同意，定制化开发 | K16: 何明
A17: 2 | B17: 业务 | C17: 交付资源风险 | D17: 客户侧要求的售前投入交付节点及周期 | E17: 资源无风险 | F17: 交付实施资源当前周期内存在明确缺口 | I17: 绿灯 | J17: 同意，无资源风险 | K17: 何明
A18: 3 | B18: 合规 | C18: 合同交付物（测绘项目） | D18: 涉及外业采集或地图数据 | E18: 合同交付物无外业采集和地图数据相关内容 | F18: 合同交付物有外业采集和地图数据相关内容 | I18: 绿灯 | J18: 不涉及 | K18: /
A19: 4 | B19: 采购 | C19: 存在分包提前投入 | F19: 分包提前介入 | I19: 绿灯 | J19: 不涉及 | K19: /
A20: 5 | B20: 财务 | C20: 客户过往合作信誉 | D20: 过往投入转单率 | E20: 无诉讼欠款、无逾期欠款、无沉默的历史交付成本 | F20: 存在逾期欠款 or 存在沉默的历史交付成本 | H20: 存在未完结诉讼（直接+间接） 存在历史坏账 | I20: 绿灯 | J20: 1）无逾期欠款，但若今年无法签单，则影响今年利润-3.13万 | K20: 洪慧敏

Sheet 投标决策评审-信息收集与前置评审
A1: 投标决策评审 — 信息收集与前置评审表
A3: Part A：项目基础信息（由申请人填写）
A4: 商机名称 | D4: 昆山市消防要素可视化分析平台 | G4: 商机代码 | I4: PL00008068
A5: 商机阶段 | D5: 投标 | G5: 营销区域 | I5: 华北营销处-区域
A6: 业务线 | D6: G1 | G6: 最终客户名称 | I6: 昆山市消防救援大队
A7: 销售经理 | D7: ='附1-预算表'!F2 -> 陈俊 | G7: 项目经理 | I7: ='附1-预算表'!H2 -> 樊茫
A8: 预计合同金额（万元） | D8: 35 | G8: 预计签单时间 | I8: 46315
A9: 预计贡献毛利率（%） | D9: ='附1-预算表'!H8 -> 0.15083238 | G9: 项目已发生成本（万元） | I9: 2.8
A10: 项目运维周期 | D10: 2年 | G10: 是否存在转包限制（客户/客户上游禁止转包） | I10: 否
A11: 项目概述 | D11: 项目建设内容：当前，昆山市消防救援大队已建成 “火眼系统”，具备火灾风险单位智能研判、火灾警情实时监测等能力，汇聚了重点单位、历史火情、隐患排查等海量消防业务数据。但系统存在业务数据与空间地理信息脱节、风险分布不直观、应急调度缺乏空间底图支撑、多源数据难以一体化分析等问题，无法满足现代化消防 “精准监管、快速响应、科学决策” 需求。为激活 “火眼系统” 数据价值，推进智慧城市与智慧消防建设，亟需建设昆山市消防要素可视化分析平台，通过空间网格关联、GIS 底图可视化及多维度数据分析，实现火眼系统风险、警情、隐患、资源等数据与地理空间深度融合，构建消防要素 “一张图” 统管模式，全面提升全市火灾风险防控、应急救援指挥和消防治理精细化水平。 项目对丰图的价值：对丰图而言，是公司在昆山市迈向公共安全垂直领域的战略支点：以昆山市空间数据底座为基础，打通其它垂直业务部门落地的示范路径；推动通用时空底座向业务赋能演进；同时带动商业形态由一次性建设向「平台 + 数据 + 运营」持续服务升级。
A12: 签约路径 | D12: 昆山数字智能科技有限公司→丰图科技（深圳）有限公司
A13: 是否涉及测绘（涉及外业采集或地图） | D13: 否 | G13: 是否涉及甲导资质 | I13: 否
A14: 是否涉密项目（涉及保密资质，涉密项目请先联系保密办） | D14: 否
A15: 分包总金额（万元） | D15: 5 | G15: 指定类分包金额（万元） | I15: 5
A16: 测绘类分包金额（万元） | D16: 0 | G16: 分包是否涉及公司核心能力 | I16: 否
A17: 项目推广激励面向对象 | D17: 内部 | G17: 项目推广激励（万元）
A18: 结算方式 | D18: 银行转账 | G18: 预计回款时间 | I18: 预计26年Q4回款30%，27年Q2回款60%，29年Q2回款10%
A19: 付款条件 | D19: ①首付款：合同签订15个工作日内，乙方开具发票送达甲方后，30个工作日内，甲方支付合同金额的30%；②验收款：项目验收合格并正式交付使用后，乙方开具发票送达甲方后，30个工作日内，甲方支 付合同总额的_60%作为进度款。③尾款：系统正常运行2年后无重大质量问题且经甲方确认，乙方开具发票送达甲方后，30个工作日内，甲方支付10%的合同余款。
A20: 合同背靠背场景 | D20: 回款+验收=均非背靠背 | G20: 确收方式及预估确收时间 | I20: 终验100%确收，预计27年Q2终验
A21: 合同是否存在提供担保或为他人提供担保 | D21: 否 | G21: 合同是否存在竞业条款 | I21: 否
A22: 合同是否有转包限制 | D22: 否 | G22: 项目是否涉及硬件所有权归属 | I22: 否
A23: 是否涉及SF小哥相关业务 | D23: 否 | G23: 是否涉及数据跨境传输或红线禁止数据 | I23: 否
A24: 项目所在地省份 | D24: 江苏省 | G24: 产品售卖类型 | I24: 非标品
A25: B2业务类型 | D25: 请选择 | G25: 标品售价标准 | I25: 不涉及标品
A26: 是否涉及数据评审 | D26: 否
A27: 预期实现方式 | D27: 自主进行技术开发与系统集成，按 "网格管理平台 → 消防GIS可视化展示" 两大模块实施建设，统一交付后由甲方验收。
A28: 数据交付字段/内容 | D28: 不涉及独立数据交付。项目交付物为软件系统、代码及技术文档；
A29: 数据合规性审查内容 | D29: 无
A31: Part B：非量化类关键评审指标-前置评审
A32: 序号 | B32: 评审维度 （部门） | C32: 评判指标 | D32: 辅助指标/说明 | E32: 绿灯标准 （免上会） | F32: 黄灯标准 （上会决策） | H32: 红灯标准 （红线禁止） | I32: 风险等级 （红/黄/绿） | J32: 前置评审意见 | K32: 前置评审人 （签字）
I33: 部门评审↓ | J33: 部门评审↓ | K33: 部门评审↓
A34: 1 | B34: 业务/采购 | C34: 分包合理性 | D34: 分包能力是否核心能力、是否指定性、付款条款不合理、下游分包方资质 | E34: 非公司核心能力分包，且非指定性分包、测绘类项目下游分包方有测绘资质、付款条款为背靠背、供应商资质合格 | F34: 公司核心能力被分包（指定性分包需上XO级）、付款条款不为背靠背、测绘类项目下游供应商无测绘资质、供应商资质不合格等 | I34: 绿灯 | J34: 指定供应商苏州长平，为原客户火眼系统的建设单位，本次分包内容为系统对接接口开放，费用为固定费用5万，请业务部门确认。 | K34: 采购BP/FDE
A35: 2 | B35: 业务 | C35: 技术可行性 | E35: 无技术风险 | F35: 存在交付侧技术风险，但在客户需求边界/预期交付边界控制情况下可完成交付 | H35: 技术侧无法交付，因成本/资质问题无法分包 | I35: 绿灯 | J35: 同意 | K35: FDE工程师
A36: 3 | B36: 财务 | C36: 客户历史欠款 | D36: 逾期天数/逾期金额 | E36: 无；或存在终验款和质保金逾期，销售愿意背书在90天内拿回终验款 | F36: 其他逾期款情况 | I36: 绿灯 | K36: 财务BP
A37: 4 | B37: 财务 | C37: 签约客户/最终客户信用评估 | D37: 客户评级制度、工商公开信息等 | E37: 政府/央企/国有企业等优质客户 非国有小微企业满足：成立≥5年、人员≥10、近三月有中标、法人无失信、无诉讼 | F37: "皮包公司"或财政和资金状况较差 | H37: 黑名单客户 | I37: 绿灯 | K37: 财务BP
A38: 5 | B38: 财务 | C38: 集团公司关联交易金额 | D38: 年度关联交易预算金额 | E38: 累计关联交易预算金额≤100w | F38: 累计关联交易预算金额＞100w | I38: 绿灯 | K38: 财务BP
A39: 6 | B39: 财务 | C39: 付款条件 | E39: 1、明确有预付款条款，且约定具体付款期间 2、硬件销售部分100%预付 3、软件销售部分100%预付或**%预付，验收后10日内支付剩余 | F39: 1、无预付条款，或无约定具体付款期间 2、硬件销售部分非100%预付，但无垫资（供应商承担） 3、软件销售部分不满足免上会条件，且非背靠背 | H39: 1、硬件销售部分非100%预付，存在垫资 2、软件销售部分为背靠背 | I39: 绿灯 | J39: 1、毛利风险较低：贡毛＞0%，高于基准线； 2、回款风险较低：政府直签项目，昆山数字智能科技有限公司其他合作项目回款情况良好； 3、售前投入：截止到2026年8月31日，交付投入2.8万； 4、确收方式：终验确收； 5、回款条件：首付款30%，验收60%，2年质保10%（预计26年回30%） | K39: 财务BP
A40: 7 | B40: 法务 | C40: 上游签约路径公司情况 | D40: 异常经营记录、营业执照、失信名单、与丰图之间是否存在诉讼、被执行记录、行政处罚记录 | E40: 1、无异常记录 2、与丰图无诉讼案件；或诉讼中丰图为第三人，不涉及义务承担 3、无被执行记录；或已执行完毕且与项目无关 4、无处罚记录；或非近三年已履行完毕且与项目无关 | F40: 1、与丰图有诉讼案件，但丰图为第三人涉及义务承担、已判决/和解但款项未完全支付、或已完结 2、有执行纪录，近三年已执行完毕，与项目相关或涉及金钱给付 3、有行政处罚纪录，但近三年已履行完毕且与项目无关或不涉及资质处罚 | H40: 1、存在异常经营记录；营业执照被吊销；列入失信名单；被提起破产清算等 2、与丰图有诉讼案件，且丰图作为原告/被告，未开庭/未和解 3、有执行纪录，且执行中状态；未履行义务；列入失信被执行人 4、有行政处罚纪录，且未履行完毕；涉及资质处罚 | I40: 绿灯 | J40: 1、截至20260921，与昆山数字智能科技有限公司之间无诉讼，无相关异常经营情形； 2、已公示《昆山数字智能科技有限公司关于昆山市消防要素可视化分析平台项目竞争性谈判采购公告》，金额35万。 | K40: 法务
A41: 8 | B41: 法务 | C41: 转包限制风险 | D41: 客户转包或丰图直签分包限制 | E41: 丰图内部关联交易无需二次评审 | F41: 有背靠背转移风险约定且可转移给供应商 | H41: 背靠背约定但丰图自行交付/供应商无法满足风险转移，违约责任超X万 | I41: 绿灯 | J41: 不涉及 | K41: 法务
A42: 9 | B42: 合规 | C42: 合规风险 | D42: 甲测/甲导资质风险、审图风险、涉密项目资质风险 | E42: 1. 无风险； 2. 已有管控举措。风险可控，不影响丰图资质。 | F42: 1. 风险存在不确定性； 2. 对资质存在明确影响，但不严重，影响范围可接受。 | H42: 对资质存在明确影响，非常严重，影响范围不可接受。 | I42: 绿灯 | J42: 不涉及保密资质 | K42: 合规
...

Sheet 项目关键事项决策-信息收集与前置评审
A1: 项目关键事项决策 — 信息收集与前置评审表
A3: Part A：项目基础信息（由申请人填写-不涉及可直接留/）
A4: 项目名称 | G4: 项目代码
A5: 销售经理 | G5: 项目经理
A6: 业务线 | D6: G1 / B2 / G2（请选择） | G6: 营销区域 | I6: 请选择
A7: 最终客户 | G7: 项目阶段 | I7: 请选择
A8: 原合同金额（万元） | G8: 原贡献毛利率（%）
A9: 决策事项类型 | D9: 请选择
A10: 决策事项概述
A11: 涉及 签单与投标决策差异 / 项目成本变动 / 分包变化 时填写
A12: 变更后合同金额（万元） | G12: 变更后贡献毛利率（%）
A13: 原分包金额 | G13: 变更后分包金额
A14: 原交付成本 | G14: 变更后交付成本
A15: 原销售成本 | G15: 变更后销售成本
A16: 是否涉及分包合同超进度支付 | D16: 是 / 否（如有，请说明情况）
A17: 是否涉及签约路径变化 | D17: 是 / 否（如有，请说明情况）
A18: 是否涉及交付内容变化 | D18: 是 / 否（如有，请说明情况）
A20: Part B：非量化类关键评审指标-前置评审
A21: 序号 | B21: 评审维度 （部门） | C21: 评判指标 | D21: 辅助指标/说明 | E21: 绿灯标准 （免上会） | F21: 黄灯标准 （上会决策） | H21: 红灯标准 （红线禁止） | I21: 风险等级 （红/黄/绿） | J21: 前置评审意见 | K21: 前置评审人 （签字）
I22: 部门评审↓ | J22: 部门评审↓ | K22: 部门评审↓
A23: 1 | B23: 业务 | C23: 技术可行性 | E23: 无技术风险 | F23: 存在交付侧技术风险，但在客户需求边界/预期交付边界控制情况下可完成交付 | H23: 技术侧无法交付，因成本/资质问题无法分包 | K23: FDE工程师
A24: 2 | B24: 业务/采购 | C24: 分包合理性 | D24: 分包能力是否核心能力、是否指定性、付款条款不合理、下游分包方资质 | E24: 非公司核心能力分包，且非指定性分包、测绘类项目下游分包方有测绘资质、付款条款为背靠背、供应商资质合格 | F24: 公司核心能力被分包（指定性分包需上XO级）、付款条款不为背靠背、测绘类项目下游供应商无测绘资质、供应商资质不合格等 | K24: 采购BP/FDE
A25: 3 | B25: 财务/法务 | C25: 签单与评审的签约差异 | E25: 签约路径/客户变化但无风险 | F25: 签约路径/客户变化且有风险 | K25: 财务BP/法务
A26: 4 | B26: 财务 | C26: 项目核减 | E26: 因交付内容减少、考核扣分等合理原因导致的审计核减 | F26: 因化债导致的合同金额核减 因非合理原因导致的核减 | K26: 财务BP

Sheet 附1-预算表
A1: 昆山市消防要素可视化分析平台-预算表（项目经理提供数据； 单位：元）
A2: 所属部门 | B2: 泛政业务一部 | C2: 项目名称（内部） | D2: 昆山市消防要素可视化分析平台 | E2: 商务经理 | F2: 陈俊 | G2: 项目经理 | H2: 樊茫 | I2: 渠道调节系数 | J2: 1
A3: 所属营销大区 | B3: 华北营销处 | C3: 客户名称 | D3: 昆山市消防大队 | E3: 商机代码 | F3: PL00008068 | G3: 项目代码 | H3: FT20260246 | I3: 预计签单时间 | J3: 46315
A4: 预计开始时间 | B4: 46315 | C4: 预计终验时间 | D4: 46680 | E4: 运维周期（质保期） | F4: 2年 | G4: 项目阶段 | H4: 投标决策 | I4: 项目难度系数 | J4: 0.7
A5: 成本测算 | B5: 合同金额 | D5: 项目收入 | E5: 分包采购成本 | F5: 软件类生产外包 | G5: 项目净收入 | H5: 交付成本 （含数据类生产外包） | I5: 标品成本
B6: 350000 | D6: =B6/(1+6%) -> 330188.68 | E6: =G10 -> 50000 | F6: =G11 -> 0 | G6: =D6-(E6+F6)/1.06-B8 -> 283018.87 | H6: =SUM(G19:G28) -> 151325 | I6: ='附3-交付成本评估'!CK2 -> 0
A7: 毛利/率测算 | B7: 灵活用工 | D7: 销售成本 （含税金，不含激励） | E7: 销售考核利润 （含税金，不含激励） | F7: 销售考核毛利率 | G7: 贡献毛利 （已扣除激励） | H7: 贡献毛利率 | I7: 交付成本占净收入比 （与决算偏差±10%以内） | J7: 销售总成本占净收入比
B8: =G12 -> 0 | D8: =SUM(G13:G17) -> 65111.887 | E8: =G6-D8 -> 217906.98 | F8: =E8/D6 -> 0.65994686 | G8: =G6-D8-H6-G18 -> 49803.144 | H8: =G8/D6 -> 0.15083238 | I8: =H6/G6 -> 0.53468167 | J8: =SUM(G13:G18)/G6 -> 0.28934723
A9: 序号 | B9: 成本大类 | D9: 成本小类 | E9: 计算逻辑说明 | G9: 成本小计 | H9: 成本占项目收入比 | I9: 成本评估备注
A10: 1 | B10: 分成分包 | D10: / | E10: 1、项目集成分包、项目日常运维分包费用 2、定制化软件开发的分包费用 3、技术服务费 | G10: 50000 | H10: =G10/1.06/$D$6 -> 0.14285714 | I10: 公司名称：苏州长平信息科技有限公司，火情数据接口对接，5万元；
B11: 软件类生产外包 | D11: / | E11: 软件类生产相关的内、外业人员的生产外包人力成本 | G11: ='附3-交付成本评估'!BF2+'附3-交付成本评估'!BL2+'附3-交付成本评估'!CB2+'附3-交付成本评估'!CH2 -> 0 | H11: =G11/$D$6 -> 0 | I11: 丰图产品不具备交付能力但是从项目层面需要进行包装整合。比如三维建模，BIM数据生产。
B12: 灵活用工 | D12: / | E12: 小创云等灵活用工平台的费用预算 | G12: 0 | H12: =G12/$D$6 -> 0 | I12: 从净收入中剔除，即【净收入=收入-分包-软件类生产外包-灵活用工】
A13: 2 | B13: 销售成本 | C13: 人力成本 | D13: 自有人员 | E13: 自有市场营销部人员成本（含销售、解决方案、CMO办公室、招投标组人力成本） | G13: =(B6-E6)/10000*1727 -> 51810 | H13: =G13/$D$6 -> 0.15691029 | I13: 按财务最新发布，26年销售人力标准成本=净签单/万*1727元。 示例：某项目合同总额500万，分包300万，26年销售人力标准成本=（500-300）*1727=345400元。
C14: 销售费用包 | D14: 差旅费 | E14: 项目客户拜访等发生的差旅（需包含解决方案成本） | H14: =G14/$D$6 -> 0
D15: 招待费 | E15: 项目客户拜访等发生的招待费用（需包含解决方案成本） | G15: 10000 | H15: =G15/$D$6 -> 0.030285714 | I15: 预算招待费用1万元
D16: 市场营销 | E16: 市场营销费用、投标阶段的专家费等 | H16: =G16/$D$6 -> 0
D17: 税金 | E17: 税后收入*1％（已设置公式，自动计算） | G17: =D6*1% -> 3301.8868 | H17: =G17/$D$6 -> 0.01
D18: 销售及售前激励 | E18: 销售考核利润（不含激励）*7.7%（包含销售与售前的激励） （已设置公式，自动计算） | G18: =E8*7.7% -> 16778.838 | H18: =G18/$D$6 -> 0.050815908 | I18: *部分银行项目销售及售前激励=销售考核利润（不含激励）*5.7%*0.4
A19: 3 | B19: 交付成本 | C19: 人力成本 | D19: 自有人员 | E19: 1、用于本项目交付实施的技术架构、研发、产品经理、交付运营、测试、运维等自有员工成本（需包含项目运维成本） | G19: ='附3-交付成本评估'!P2+'附3-交付成本评估'!BW2 -> 29680 | H19: =G19/$D$6 -> 0.089888 | I19: 预计交付岗位：正编投入17.5人天，19680元。
D20: 研发外包 | E20: 1、用于本项目交付实施的项目助理、研发、产品经理、交付运营、测试、运维等外包员工成本 | G20: ='附3-交付成本评估'!Q2+'附3-交付成本评估'!BX2 -> 70645 | H20: =G20/$D$6 -> 0.21395343 | I20: 预计投入： ①前端外包：预计投入50人天，50*995=49750元 ②后端外报：预计投入11人天，11*995=10945 元 ③运维：预计投入5人天，5*995=4975元 ④运维阶段：研发外包5人天，5*995=4975元
C21: 生产人员成本 | D21: 数据类生产外包 | E21: 数据类生产相关的内、外业人员的生产外包人力成本 | G21: ='附3-交付成本评估'!BD2+'附3-交付成本评估'!BK2+'附3-交付成本评估'!BZ2+'附3-交付成本评估'!CG2 -> 0 | H21: =G21/$D$6 -> 0 | I21: 丰图产品具备交付能力只是用了生产资源来执行交付。比如地址治理，地图生产，数据服务交付运营等
C22: 差旅招待 | D22: 差旅费 | E22: 项目实施人员出差的长途交通费+补助+住宿费（酒店、租房、物业水电费） | G22: ='附3-交付成本评估'!BJ2+'附3-交付成本评估'!CF2 -> 2800 | H22: =G22/$D$6 -> 0.00848 | I22: 预计研发交通差旅： 700*2*2=2800元
C23: 项目管理费 | D23: 自有人员 | E23: 项目经理自有人员人力成本 | G23: ='附3-交付成本评估'!X2+'附3-交付成本评估'!BT2 -> 42400 | H23: =G23/$D$6 -> 0.12841143 | I23: 项目经理： 交付阶段预计投入20人天：20*1696=33920元 运维阶段预计投入5人天：5*1696=8480元
D24: 差旅、市内交通 | E24: 差旅、市内交通 | G24: ='附3-交付成本评估'!BH2+'附3-交付成本评估'!CD2 -> 2800 | H24: =G24/$D$6 -> 0.00848 | I24: 预计投入项目经理交通差旅： 700*2*2=2800元
D25: 招待费 | E25: 关键里程碑、验收推动招待费用 | G25: 1000 | H25: =G25/$D$6 -> 0.0030285714 | I25: 推动项目验收，实施招待预计1000元
D26: 项目验收 | E26: 项目技术评审专家费等 | G26: 1000 | H26: =G26/$D$6 -> 0.0030285714 | I26: 项目验收聘请一名外部专家，预算1000元
D27: 综合办公 | E27: 项目资料打印、资料邮寄、设备邮寄相关的快递费；项目实施需要采购的办公耗材，如插线板、路由器等；办公资产采购等 | G27: 1000 | H27: =G27/$D$6 -> 0.0030285714 | I27: 验收材料打印预计1000元
D28: 专业服务 | E28: 审计律师费用、顾问费用、其它咨询费用 | H28: =G28/$D$6 -> 0
A29: 制表人： | B29: 樊茫 | E29: 复核人： | G29: 何明
A30: 填写说明：标黄的部分为需人工填写，白色区域有公式带出对应数值。

Sheet 附2-产品与服务清单
A1: 填写责任人：解决方案 前置输入项：交付成本清单（功能项需映射标准产品名称）
A2: 一、产品份额表
A3: 项目名称：
A4: 序号 | B4: 产品名称 | C4: 产品刊例价（元） | D4: 产品报价（元） | E4: 产品折扣（=D/C） | F4: 产品交付成本（元） | G4: 产品交付总人天 | H4: 产品毛利 | I4: 说明
A5: 注： | B5: 从已有的标准产品清单目录中选择 | C5: 参考标准报价 | D5: 建设方案报价单金额 | E5: =产品报价/产品刊例价 | F5: 基于实施成本分拆，总成本<=实施总成本 | G5: 交付成本人天数 | H5: （=1-产品交付成本/（产品报价/1.06）） | I5: 特殊折扣说明
A6: 1 | B6: 统一地址运营 | C6: 347000 | D6: 229150 | E6: =D6/C6 -> 0.66037464 | F6: 86240 | G6: =SUMIFS('附3-交付成本评估'!P:P,'附3-交付成本评估'!C:C,B6)+SUMIFS('附3-交付成本评估'!Q:Q,'附3-交付成本评估'!C:C,B6)+SUMIFS('附3-交付成本评估'!R:R,'附3-交付成本评估'!C:C,B6) -> 0 | H6: =1-F6/(D6/1.06) -> 0.60107179
A7: 2 | B7: 项目定制 | E7: =D7/C7 -> #DIV/0! | G7: =SUMIFS('附3-交付成本评估'!P:P,'附3-交付成本评估'!C:C,B7)+SUMIFS('附3-交付成本评估'!Q:Q,'附3-交付成本评估'!C:C,B7)+SUMIFS('附3-交付成本评估'!R:R,'附3-交付成本评估'!C:C,B7) -> 41869 | H7: =1-F7/(D7/1.06) -> #DIV/0!
A8: 3 | B8: 项目分包 | E8: =D8/C8 -> #DIV/0! | G8: =SUMIFS('附3-交付成本评估'!P:P,'附3-交付成本评估'!C:C,B8)+SUMIFS('附3-交付成本评估'!Q:Q,'附3-交付成本评估'!C:C,B8)+SUMIFS('附3-交付成本评估'!R:R,'附3-交付成本评估'!C:C,B8) -> 0 | H8: =1-F8/(D8/1.06) -> #DIV/0!
A9: 固定行 | B9: 项目合计 | C9: / | D9: 项目金额汇总 | E9: / | F9: 交付成本汇总 | G9: 交付人天汇总 | H9: 项目毛利 （注：不含销售成本/项目经理/项目管理成本等） | I9: 注：此处项目毛利≠项目贡毛（不含销售成本/项目经理/项目管理成本等）
A10: 合计值 | B10: / | C10: / | D10: =SUM(D6:D8) -> 229150 | E10: / | H10: =1-F10/(D10/1.06) -> 1 | I10: /
A12: 二、产品细项表
A13: 注：标品份额细拆（产品功能模块、刊例价、报价、折扣、功能模块说明）
A14: 标准产品明细
A15: 序号 | B15: 产品名称 | C15: 产品模块 | D15: 产品刊例价 | E15: 产品报价 | F15: 产品折扣 | G15: 产品交付总成本 | H15: 产品交付总人天 | I15: 产品交付-产研人天（正编+外包） | J15: 产品交付-生产外包人天 | K15: 产品毛利 | L15: 说明
A16: 注： | B16: 从已有的标准产品清单目录中选择 | C16: 标准产品方案的明细拆分 | D16: 参考标准报价 | E16: 建设方案报价单金额 | F16: =产品金额/产品刊例价 | G16: 基于实施成本分拆，总成本<=实施总成本 | H16: 交付成本人天数 | K16: （=1-产品交付成本/（产品报价/1.06））
A17: 1-1 | B17: 统一地址运营 | C17: 地址标准化治理工程 | D17: 347000 | E17: 229150 | F17: =E17/D17 -> 0.66037464 | G17: 86240 | H17: =I17+J17 -> 0 | I17: =SUMIFS('附3-交付成本评估'!T:T,'附3-交付成本评估'!C:C,B17,'附3-交付成本评估'!D:D,C17)+SUMIFS('附3-交付成本评估'!U:U,'附3-交付成本评估'!C:C,B17,'附3-交付成本评估'!D:D,C17) -> 0 | J17: =SUMIFS('附3-交付成本评估'!V:V,'附3-交付成本评估'!C:C,B17,'附3-交付成本评估'!D:D,C17) -> 0 | K17: =1-G17/(E17/1.06) -> 0.60107179
A18: 1-2 | B18: 地址资源运营平台 | C18: 地址服务平台 | H18: =I18+J18 -> 0 | I18: =SUMIFS('附3-交付成本评估'!T:T,'附3-交付成本评估'!C:C,B18,'附3-交付成本评估'!D:D,C18)+SUMIFS('附3-交付成本评估'!U:U,'附3-交付成本评估'!C:C,B18,'附3-交付成本评估'!D:D,C18) -> 0 | J18: =SUMIFS('附3-交付成本评估'!V:V,'附3-交付成本评估'!C:C,B18,'附3-交付成本评估'!D:D,C18) -> 0 | K18: =1-G18/(E18/1.06) -> #DIV/0!
A19: 1-3 | B19: 地址资源运营平台 | C19: 数据更新服务 | H19: =I19+J19 -> 0 | I19: =SUMIFS('附3-交付成本评估'!T:T,'附3-交付成本评估'!C:C,B19,'附3-交付成本评估'!D:D,C19)+SUMIFS('附3-交付成本评估'!U:U,'附3-交付成本评估'!C:C,B19,'附3-交付成本评估'!D:D,C19) -> 0 | J19: =SUMIFS('附3-交付成本评估'!V:V,'附3-交付成本评估'!C:C,B19,'附3-交付成本评估'!D:D,C19) -> 0 | K19: =1-G19/(E19/1.06) -> #DIV/0!
A20: 2-1 | H20: =I20+J20 -> 0 | I20: =SUMIFS('附3-交付成本评估'!T:T,'附3-交付成本评估'!C:C,B20,'附3-交付成本评估'!D:D,C20)+SUMIFS('附3-交付成本评估'!U:U,'附3-交付成本评估'!C:C,B20,'附3-交付成本评估'!D:D,C20) -> 0 | J20: =SUMIFS('附3-交付成本评估'!V:V,'附3-交付成本评估'!C:C,B20,'附3-交付成本评估'!D:D,C20) -> 0 | K20: =1-G20/(E20/1.06) -> #DIV/0!
A21: 2-2 | H21: =I21+J21 -> 0 | I21: =SUMIFS('附3-交付成本评估'!T:T,'附3-交付成本评估'!C:C,B21,'附3-交付成本评估'!D:D,C21)+SUMIFS('附3-交付成本评估'!U:U,'附3-交付成本评估'!C:C,B21,'附3-交付成本评估'!D:D,C21) -> 0 | J21: =SUMIFS('附3-交付成本评估'!V:V,'附3-交付成本评估'!C:C,B21,'附3-交付成本评估'!D:D,C21) -> 0 | K21: =1-G21/(E21/1.06) -> #DIV/0!

Sheet 附3-交付成本评估
A1: 项目名称：昆山GA动态巡防系统
A2: 合计值 | J2: =SUM(J5:J42) -> 0 | K2: =SUM(K5:K42) -> 0 | L2: =SUM(L5:L42) -> 0 | M2: =SUM(M5:M42) -> 0 | N2: =SUM(N5:N42) -> 129270 | O2: =SUM(O5:O42) -> 33920 | P2: =SUM(P5:P42) -> 29680 | Q2: =SUM(Q5:Q42) -> 65670 | ... BL2: =SUM(BL5:BL42) -> 0 | BN2: =SUM(BN5:BN42) -> 0 | BO2: =SUM(BO5:BO42) -> 0 | BP2: =SUM(BP5:BP42) -> 0 | BQ2: =SUM(BQ5:BQ42) -> 0 | BR2: =SUM(BR5:BR42) -> 13455 | BS2: =SUM(BS5:BS42) -> 5 | BT2: =SUM(BT5:BT42) -> 8480 | BU2: =SUM(BU5:BU42) -> 0 | ... CH2: =SUM(CH5:CH42) -> 0 | CJ2: =SUM(CJ5:CJ42) -> 0 | CK2: =SUM(CK5:CK42) -> 0
A3: 序号 | B3: 解决方案评估 | I3: 标品研发负责人评估 | J3: 1.0 实施阶段- 销售成本 | N3: 1.1 实施阶段- 交付人力成本 | W3: ① 项目经理： | Y3: ② 产品售前岗： | AC3: ③ 产 品 岗： | AG3: ④ 前 端 岗： | AK3: ⑤ 后 端 岗： | AO3: ⑥ 大数据开发岗： | AS3: ⑦ 交 付 岗： | AW3: ⑧ 架 构： | AY3: ⑨ 其他：测试、UI、实施中运维投入 | BC3: ⑩ 生产外包-数据类： | BE3: ⑪ 生产外包-软件类： | BG3: 1.2 实施阶段- 交付差旅招待 | BM3: ★工作量评估负责人 （可补充说明成本评估备注） | BN3: 2.0 运维阶段- 销售成本 | BR3: 2.1 运维阶段-人力成本： | BS3: ① 项 目 经 理： | BU3: ② 产 研 投 入： | BY3: ③ 生产外包-数据类： | CA3: ④ 生产外包-软件类： | CC3: 2.2 运维阶段-差旅成本 | CI3: 按岗位人员投入人数说明 | CJ3: 标品
B4: 建设内容 | C4: 对应标准产品名称 （下拉选择） | D4: 建设内容-细分模块 | E4: 具体功能项 | F4: 功能描述 | G4: 最终交付物 | H4: 交付方式 | I4: 是否标品交付 | J4: 销售-人力成本 | K4: 销售-差旅 | L4: 销售-招待费 | M4: 销售-市场营销 | N4: 实施阶段- 人力成本总额 | O4: ① 实施阶段- 人力成本总额 （项目经理） | P4: ② 实施阶段- 人力成本总额 （产研正编） | Q4: ③ 实施阶段- 人力成本总额 （产研外包） | R4: ④ 实施阶段- 人力成本总额 （生产外包） | S4: 实施阶段- 人天汇总 （项目经理） | T4: 实施阶段- 人天汇总 （产研正编） | U4: 实施阶段- 人天汇总 （产研外包） | V4: 实施阶段- 人天汇总 （生产外包） | W4: 项目经理 正编人天 | X4: 项目经理 正编金额 | Y4: 产品售前 正编人天 | Z4: 产品售前 外包人天 | AA4: 产品售前 正编金额 | AB4: 产品售前 外包金额 | AC4: 产品 正编人天 | AD4: 产品 外包人天 | AE4: 产品 正编金额 | AF4: 产品 外包金额 | AG4: 前端 正编人天 | AH4: 前端 外包人天 | AI4: 前端 正编金额 | AJ4: 前端 外包金额 | AK4: 后端 正编人天 | AL4: 后端 外包人天 | AM4: 后端 正编金额 | AN4: 后端 外包金额 | AO4: 大数据开发 正编人天 | AP4: 大数据开发 外包人天 | AQ4: 大数据开发 正编金额 | AR4: 大数据开发 外包金额 | AS4: 交付 正编人天 | AT4: 交付 外包人天 | AU4: 交付 正编金额 | AV4: 交付 外包金额 | AW4: 架构 正编人天 | AX4: 架构 正编金额 | AY4: 其他 正编人天 | AZ4: 其他 外包人天 | BA4: 其他 正编金额 | BB4: 其他 外包金额 | BC4: 生产外包 人天 | BD4: 生产外包 金额 | BE4: 生产外包 人天 | BF4: 生产外包 金额 | BG4: 实施阶段- 差旅成本总额 | BH4: 实施阶段-差旅成本 项目经理-差旅、市内交通 | BI4: 实施阶段-差旅成本 项目经理-招待费 | BJ4: 实施阶段-差旅成本 产研（正编+外包） | BK4: 实施阶段-差旅成本 生产外包（数据类） | BL4: 实施阶段-差旅成本 生产外包（软件类） | BN4: 销售-人力成本 | BO4: 销售-差旅 | BP4: 销售-招待费 | BQ4: 销售-市场营销 | BR4: 运维阶段- 人力成本总额 | BS4: 项目经理 正编人天 | BT4: 项目经理 正编金额 | BU4: 产研 正编人天 | BV4: 产研 外包人天 | BW4: 产研 正编金额 | BX4: 产研 外包金额 | BY4: 生产外包 人天 | BZ4: 生产外包 金额 | CA4: 生产外包 人天 | CB4: 生产外包 金额 | CC4: 运维阶段- 差旅成本总额 | CD4: 运维阶段-差旅成本 项目经理-差旅、市内交通 | CE4: 运维阶段-差旅成本 项目经理-招待费 | CF4: 运维阶段-差旅成本 产研（正编+外包） | CG4: 运维阶段-差旅成本 生产外包（数据类） | CH4: 运维阶段-差旅成本 生产外包（软件类） | CJ4: 人天 | CK4: 金额 | CL4: 标品成本评估-说明
A5: 1 | B5: 昆山市消防要素可视化分析平台 | C5: 数据工程 | D5: 数据接入与服务 | E5: 火灾数据接入 | F5: 接入昆山消防大队辖区火情相关数据，如：火灾警情、起火原因、发生时间、地理坐标等数据。 | G5: 数据对接 | H5: 交付运营 | N5: =O5+P5+Q5+R5 -> 43983 | O5: =X5 -> 33920 | P5: =AA5+AE5+AI5+AM5+AQ5+AU5+AX5+BA5 -> 5088 | Q5: =AB5+AF5+AJ5+AN5+AR5+AV5+BB5 -> 4975 | R5: =BD5+BF5 -> 0 | S5: =W5 -> 20 | T5: =Y5+AC5+AG5+AK5+AO5+AS5+AW5+AY5 -> 3 | U5: =Z5+AD5+AH5+AL5+AP5+AT5+AZ5 -> 5 | V5: =BC5+BE5 -> 0 | W5: 20 | X5: =W5*1696 -> 33920 | AB5: =Z5*995 -> 0 | AE5: =AC5*1696 -> 0 | AF5: =AD5*995 -> 0 | AJ5: =AH5*995 -> 0 | AN5: =AL5*995 -> 0 | AR5: =AP5*995 -> 0 | AS5: 3 | AU5: =AS5*1696 -> 5088 | AV5: =AT5*995 -> 0 | AZ5: 5 | BB5: =AZ5*995 -> 4975 | BD5: =BC5*320 -> 0 | BF5: =BE5*320 -> 0 | BG5: =SUM(BH5:BL5) -> 5600 | BH5: 2800 | BJ5: 2800 | BR5: =SUM(BT5,BW5,BX5,BZ5,CB5) -> 13455 | BS5: 5 | BT5: =BS5*1696 -> 8480 | BV5: 5 | BX5: =BV5*995 -> 4975 | BZ5: =BY5*320 -> 0 | CB5: =CA5*320 -> 0 | CC5: =SUM(CD5:CH5) -> 0 | CI5: 岗位（正编/外包）：人数+对应投入人天 ①产品岗：正编投入_人；外包投入_人 ②前端岗：正编投入_人；外包投入_人 ③后端岗：正编投入_人；外包投入_人 ④大数据开发：正编投入_人；外包投入_人 ⑤交付岗：正编投入_人 ⑥架构岗：正编投入_人；外包投入_人 ⑦其他：正编投入_人；外包投入_人 ...... | CL5: 产品、研发：
A6: 2 | C6: 数据工程 | F6: 接入昆山消防大队辖区内高风险单位名单数据，如：单位基础信息、风险等级、地址经纬度、管辖单位等数据。 | H6: 交付运营 | N6: =O6+P6+Q6+R6 -> 5088 | O6: =X6 -> 0 | P6: =AA6+AE6+AI6+AM6+AQ6+AU6+AX6+BA6 -> 5088 | Q6: =AB6+AF6+AJ6+AN6+AR6+AV6+BB6 -> 0 | R6: =BD6+BF6 -> 0 | S6: =W6 -> 0 | T6: =Y6+AC6+AG6+AK6+AO6+AS6+AW6+AY6 -> 3 | U6: =Z6+AD6+AH6+AL6+AP6+AT6+AZ6 -> 0 | V6: =BC6+BE6 -> 0 | X6: =W6*1696 -> 0 | AB6: =Z6*995 -> 0 | AE6: =AC6*1696 -> 0 | AF6: =AD6*995 -> 0 | AJ6: =AH6*995 -> 0 | AN6: =AL6*995 -> 0 | AR6: =AP6*995 -> 0 | AS6: 3 | AU6: =AS6*1696 -> 5088 | AV6: =AT6*995 -> 0 | BB6: =AZ6*995 -> 0 | BD6: =BC6*320 -> 0 | BF6: =BE6*320 -> 0 | BG6: =SUM(BH6:BL6) -> 0 | BR6: =SUM(BT6,BW6,BX6,BZ6,CB6) -> 0 | BX6: =BV6*995 -> 0 | BZ6: =BY6*320 -> 0 | CB6: =CA6*320 -> 0 | CC6: =SUM(CD6:CH6) -> 0
A7: 3 | C7: 数据工程 | F7: 接入公安实有单位数据基础信息（单位类型、物业单位名称、火灾风险积分、单位人数、所属消防中队）、消防要素（包含自动消防设施、危化学品、粉尘、出租房、九小场所、燃气、新业态场所、三合一场所、住宿、食堂、特殊人群、高危气体），并将其信息并且匹配至所属网格。 更新频率：月度 | H7: 交付运营 | N7: =O7+P7+Q7+R7 -> 5088 | O7: =X7 -> 0 | P7: =AA7+AE7+AI7+AM7+AQ7+AU7+AX7+BA7 -> 5088 | Q7: =AB7+AF7+AJ7+AN7+AR7+AV7+BB7 -> 0 | R7: =BD7+BF7 -> 0 | S7: =W7 -> 0 | T7: =Y7+AC7+AG7+AK7+AO7+AS7+AW7+AY7 -> 3 | U7: =Z7+AD7+AH7+AL7+AP7+AT7+AZ7 -> 0 | V7: =BC7+BE7 -> 0 | X7: =W7*1696 -> 0 | AB7: =Z7*995 -> 0 | AE7: =AC7*1696 -> 0 | AF7: =AD7*995 -> 0 | AJ7: =AH7*995 -> 0 | AN7: =AL7*995 -> 0 | AR7: =AP7*995 -> 0 | AS7: 3 | AU7: =AS7*1696 -> 5088 | AV7: =AT7*995 -> 0 | BB7: =AZ7*995 -> 0 | BD7: =BC7*320 -> 0 | BF7: =BE7*320 -> 0 | BG7: =SUM(BH7:BL7) -> 0 | BR7: =SUM(BT7,BW7,BX7,BZ7,CB7) -> 0 | BX7: =BV7*995 -> 0 | BZ7: =BY7*320 -> 0 | CB7: =CA7*320 -> 0 | CC7: =SUM(CD7:CH7) -> 0
A8: 4 | C8: 数据工程 | E8: 物联网设备接入 | F8: 系统支持接入辖区内消防重点单位视频监控资源，完成监控点位标准化GIS地图上图部署，实现视频点位可视化撒点、一键预览播放、点位信息查询等基础视频可视化应用能力，具体功能如下： 1、视频资源统一接入：支持对接消防重点单位现有视频监控设备，兼容主流视频协议，实现监控视频资源的统一汇聚、在线接入、状态识别，支持设备在线/离线状态自动识别。 2、GIS地图可视化撒点：根据监控设备实际经纬度坐标，在电子地图上精准展示视频监控点位，以专属图标分层展示，点位分布清晰直观，支持地图缩放、平移联动显示，缩放过程中自动适配点位展示效果。 3、点位信息一键查询：点击地图视频撒点图标，可弹窗展示该监控点位基础信息，包含设备名称、所属重点单位、安装位置、设备状态、设备编号等台账信息，实现点位信息可视化溯源。 4、地图点位一键视频播放：支持点击地图监控图标，快速调取实时视频画面，实现单路视频实时预览播放，画面流畅稳定，支持窗口悬浮播放、放大全屏播放基础能力。 5、视频点位分层展示管理：支持按重点单位类型、区域、设备状态对视频点位进行筛选展示，可开启/关闭视频图层，实现监控资源分层、分类可视化管理。 6、异常状态可视化提醒：对接入异常、离线故障、信号中断的监控点位，地图图标自动差异化标识，直观展示设备运行状态，便于运维人员及时排查整改。 | H8: 研发 | N8: =O8+P8+Q8+R8 -> 5382 | O8: =X8 -> 0 | P8: =AA8+AE8+AI8+AM8+AQ8+AU8+AX8+BA8 -> 3392 | Q8: =AB8+AF8+AJ8+AN8+AR8+AV8+BB8 -> 1990 | R8: =BD8+BF8 -> 0 | S8: =W8 -> 0 | T8: =Y8+AC8+AG8+AK8+AO8+AS8+AW8+AY8 -> 2 | U8: =Z8+AD8+AH8+AL8+AP8+AT8+AZ8 -> 2 | V8: =BC8+BE8 -> 0 | X8: =W8*1696 -> 0 | AB8: =Z8*995 -> 0 | AE8: =AC8*1696 -> 0 | AF8: =AD8*995 -> 0 | AH8: 2 | AJ8: =AH8*995 -> 1990 | AN8: =AL8*995 -> 0 | AR8: =AP8*995 -> 0 | AS8: 2 | AU8: =AS8*1696 -> 3392 | AV8: =AT8*995 -> 0 | BB8: =AZ8*995 -> 0 | BD8: =BC8*320 -> 0 | BF8: =BE8*320 -> 0 | BG8: =SUM(BH8:BL8) -> 0 | BR8: =SUM(BT8,BW8,BX8,BZ8,CB8) -> 0 | BX8: =BV8*995 -> 0 | BZ8: =BY8*320 -> 0 | CB8: =CA8*320 -> 0 | CC8: =SUM(CD8:CH8) -> 0
A9: 5 | C9: 项目定制 | D9: 全域消防要素态势一张图 | E9: 地图底座 | F9: 对接昆山市公共智慧底座地图服务，支持矢量地图、影像地图切换； | G9: 全域消防要素态势一张图 | H9: 研发 | N9: =O9+P9+Q9+R9 -> 1843 | O9: =X9 -> 0 | P9: =AA9+AE9+AI9+AM9+AQ9+AU9+AX9+BA9 -> 848 | Q9: =AB9+AF9+AJ9+AN9+AR9+AV9+BB9 -> 995 | R9: =BD9+BF9 -> 0 | S9: =W9 -> 0 | T9: =Y9+AC9+AG9+AK9+AO9+AS9+AW9+AY9 -> 0.5 | U9: =Z9+AD9+AH9+AL9+AP9+AT9+AZ9 -> 1 | V9: =BC9+BE9 -> 0 | X9: =W9*1696 -> 0 | AB9: =Z9*995 -> 0 | AE9: =AC9*1696 -> 0 | AF9: =AD9*995 -> 0 | AH9: 1 | AJ9: =AH9*995 -> 995 | AN9: =AL9*995 -> 0 | AR9: =AP9*995 -> 0 | AS9: 0.5 | AU9: =AS9*1696 -> 848 | AV9: =AT9*995 -> 0 | BB9: =AZ9*995 -> 0 | BD9: =BC9*320 -> 0 | BF9: =BE9*320 -> 0 | BG9: =SUM(BH9:BL9) -> 0 | BR9: =SUM(BT9,BW9,BX9,BZ9,CB9) -> 0 | BX9: =BV9*995 -> 0 | BZ9: =BY9*320 -> 0 | CB9: =CA9*320 -> 0 | CC9: =SUM(CD9:CH9) -> 0
A10: 6 | C10: 项目定制 | E10: 地图基础工具 | F10: 包含坐标拾取、坐标定位、地图测距、地图缩放、地图切换等功能。 | H10: 研发 | N10: =O10+P10+Q10+R10 -> 1843 | O10: =X10 -> 0 | P10: =AA10+AE10+AI10+AM10+AQ10+AU10+AX10+BA10 -> 848 | Q10: =AB10+AF10+AJ10+AN10+AR10+AV10+BB10 -> 995 | R10: =BD10+BF10 -> 0 | S10: =W10 -> 0 | T10: =Y10+AC10+AG10+AK10+AO10+AS10+AW10+AY10 -> 0.5 | U10: =Z10+AD10+AH10+AL10+AP10+AT10+AZ10 -> 1 | V10: =BC10+BE10 -> 0 | X10: =W10*1696 -> 0 | AB10: =Z10*995 -> 0 | AE10: =AC10*1696 -> 0 | AF10: =AD10*995 -> 0 | AH10: 1 | AJ10: =AH10*995 -> 995 | AN10: =AL10*995 -> 0 | AR10: =AP10*995 -> 0 | AS10: 0.5 | AU10: =AS10*1696 -> 848 | AV10: =AT10*995 -> 0 | BB10: =AZ10*995 -> 0 | BD10: =BC10*320 -> 0 | BF10: =BE10*320 -> 0 | BG10: =SUM(BH10:BL10) -> 0 | BR10: =SUM(BT10,BW10,BX10,BZ10,CB10) -> 0 | BX10: =BV10*995 -> 0 | BZ10: =BY10*320 -> 0 | CB10: =CA10*320 -> 0 | CC10: =SUM(CD10:CH10) -> 0
A11: 7 | C11: 项目定制 | E11: 搜索 | F11: 多维度复合关键词检索，支持单位名称、单位属性地址、警情编号、网格、风险等级多条件模糊搜索； 搜索结果以列表分页展示，展示完整要素详情；点击列表条目自动定位跳转至地图对应点位，地图点位高亮闪烁；支持搜索结果批量导出Excel；支持搜索历史记录保存。 | H11: 研发 | N11: =O11+P11+Q11+R11 -> 2838 | O11: =X11 -> 0 | P11: =AA11+AE11+AI11+AM11+AQ11+AU11+AX11+BA11 -> 848 | Q11: =AB11+AF11+AJ11+AN11+AR11+AV11+BB11 -> 1990 | R11: =BD11+BF11 -> 0 | S11: =W11 -> 0 | T11: =Y11+AC11+AG11+AK11+AO11+AS11+AW11+AY11 -> 0.5 | U11: =Z11+AD11+AH11+AL11+AP11+AT11+AZ11 -> 2 | V11: =BC11+BE11 -> 0 | X11: =W11*1696 -> 0 | AB11: =Z11*995 -> 0 | AE11: =AC11*1696 -> 0 | AF11: =AD11*995 -> 0 | AH11: 1 | AJ11: =AH11*995 -> 995 | AL11: 1 | AN11: =AL11*995 -> 995 | AR11: =AP11*995 -> 0 | AS11: 0.5 | AU11: =AS11*1696 -> 848 | AV11: =AT11*995 -> 0 | BB11: =AZ11*995 -> 0 | BD11: =BC11*320 -> 0 | BF11: =BE11*320 -> 0 | BG11: =SUM(BH11:BL11) -> 0 | BR11: =SUM(BT11,BW11,BX11,BZ11,CB11) -> 0 | BX11: =BV11*995 -> 0 | BZ11: =BY11*320 -> 0 | CB11: =CA11*320 -> 0 | CC11: =SUM(CD11:CH11) -> 0
A12: 8 | C12: 项目定制 | E12: 行政区划图层 | F12: 加载昆山市、镇（街道）两级行政区划边界，支持鼠标悬浮查看区域名称； 支持地图下钻：全市→镇街；上卷返回上级视图；区域边界高亮闪烁； 按行政区划进行消防指标统计：警情数量、高风险单位数量、物联设备数量，统计指标以弹窗卡片展示。 | H12: 研发 | N12: =O12+P12+Q12+R12 -> 2838 | O12: =X12 -> 0 | P12: =AA12+AE12+AI12+AM12+AQ12+AU12+AX12+BA12 -> 848 | Q12: =AB12+AF12+AJ12+AN12+AR12+AV12+BB12 -> 1990 | R12: =BD12+BF12 -> 0 | S12: =W12 -> 0 | T12: =Y12+AC12+AG12+AK12+AO12+AS12+AW12+AY12 -> 0.5 | U12: =Z12+AD12+AH12+AL12+AP12+AT12+AZ12 -> 2 | V12: =BC12+BE12 -> 0 | X12: =W12*1696 -> 0 | AB12: =Z12*995 -> 0 | AE12: =AC12*1696 -> 0 | AF12: =AD12*995 -> 0 | AH12: 1 | AJ12: =AH12*995 -> 995 | AL12: 1 | AN12: =AL12*995 -> 995 | AR12: =AP12*995 -> 0 | AS12: 0.5 | AU12: =AS12*1696 -> 848 | AV12: =AT12*995 -> 0 | BB12: =AZ12*995 -> 0 | BD12: =BC12*320 -> 0 | BF12: =BE12*320 -> 0 | BG12: =SUM(BH12:BL12) -> 0 | BR12: =SUM(BT12,BW12,BX12,BZ12,CB12) -> 0 | BX12: =BV12*995 -> 0 | BZ12: =BY12*320 -> 0 | CB12: =CA12*320 -> 0 | CC12: =SUM(CD12:CH12) -> 0
A13: 9 | C13: 项目定制 | E13: 综治网格图层 | F13: 加载完整综治网格边界数据，地图渲染网格面图层；鼠标悬浮显示网格编码、网格名称、网格面积； 网格内统计本网格火灾警情、高风险单位、监控设备数量；支持网格筛选过滤，可按网格编码查询定位。 | H13: 研发 | N13: =O13+P13+Q13+R13 -> 2838 | O13: =X13 -> 0 | P13: =AA13+AE13+AI13+AM13+AQ13+AU13+AX13+BA13 -> 848 | Q13: =AB13+AF13+AJ13+AN13+AR13+AV13+BB13 -> 1990 | R13: =BD13+BF13 -> 0 | S13: =W13 -> 0 | T13: =Y13+AC13+AG13+AK13+AO13+AS13+AW13+AY13 -> 0.5 | U13: =Z13+AD13+AH13+AL13+AP13+AT13+AZ13 -> 2 | V13: =BC13+BE13 -> 0 | X13: =W13*1696 -> 0 | AB13: =Z13*995 -> 0 | AE13: =AC13*1696 -> 0 | AF13: =AD13*995 -> 0 | AH13: 1 | AJ13: =AH13*995 -> 995 | AL13: 1 | AN13: =AL13*995 -> 995 | AR13: =AP13*995 -> 0 | AS13: 0.5 | AU13: =AS13*1696 -> 848 | AV13: =AT13*995 -> 0 | BB13: =AZ13*995 -> 0 | BD13: =BC13*320 -> 0 | BF13: =BE13*320 -> 0 | BG13: =SUM(BH13:BL13) -> 0 | BR13: =SUM(BT13,BW13,BX13,BZ13,CB13) -> 0 | BX13: =BV13*995 -> 0 | BZ13: =BY13*320 -> 0 | CB13: =CA13*320 -> 0 | CC13: =SUM(CD13:CH13) -> 0
A14: 10 | C14: 项目定制 | E14: 消防中队管理区图层 | F14: 加载各消防中队管辖责任区边界图层；点击辖区弹窗展示中队名称、中队地址、联系电话、值班人员； 辖区内统计：历史警情统计、重点单位统计、风险单位分布统计、监控设备统计；支持按中队筛选地图要素，快速过滤出该中队管辖范围内全部消防要素。 | H14: 研发 | N14: =O14+P14+Q14+R14 -> 2838 | O14: =X14 -> 0 | P14: =AA14+AE14+AI14+AM14+AQ14+AU14+AX14+BA14 -> 848 | Q14: =AB14+AF14+AJ14+AN14+AR14+AV14+BB14 -> 1990 | R14: =BD14+BF14 -> 0 | S14: =W14 -> 0 | T14: =Y14+AC14+AG14+AK14+AO14+AS14+AW14+AY14 -> 0.5 | U14: =Z14+AD14+AH14+AL14+AP14+AT14+AZ14 -> 2 | V14: =BC14+BE14 -> 0 | X14: =W14*1696 -> 0 | AB14: =Z14*995 -> 0 | AE14: =AC14*1696 -> 0 | AF14: =AD14*995 -> 0 | AH14: 1 | AJ14: =AH14*995 -> 995 | AL14: 1 | AN14: =AL14*995 -> 995 | AR14: =AP14*995 -> 0 | AS14: 0.5 | AU14: =AS14*1696 -> 848 | AV14: =AT14*995 -> 0 | BB14: =AZ14*995 -> 0 | BD14: =BC14*320 -> 0 | BF14: =BE14*320 -> 0 | BG14: =SUM(BH14:BL14) -> 0 | BR14: =SUM(BT14,BW14,BX14,BZ14,CB14) -> 0 | BX14: =BV14*995 -> 0 | BZ14: =BY14*320 -> 0 | CB14: =CA14*320 -> 0 | CC14: =SUM(CD14:CH14) -> 0
A15: 11 | C15: 项目定制 | E15: 火情热力图 | F15: 基于历史火灾警情空间坐标，采用核密度分析算法生成动态渐变热力图层； 支持时间筛选：可自定义时间范围，选择近7天、30天、半年、全年或者自定义起止时间，热力图随时间条件动态重计算渲染；支持热力图层显隐控制；支持热力图截图导出。 | H15: 研发 | N15: =O15+P15+Q15+R15 -> 3833 | O15: =X15 -> 0 | P15: =AA15+AE15+AI15+AM15+AQ15+AU15+AX15+BA15 -> 848 | Q15: =AB15+AF15+AJ15+AN15+AR15+AV15+BB15 -> 2985 | R15: =BD15+BF15 -> 0 | S15: =W15 -> 0 | T15: =Y15+AC15+AG15+AK15+AO15+AS15+AW15+AY15 -> 0.5 | U15: =Z15+AD15+AH15+AL15+AP15+AT15+AZ15 -> 3 | V15: =BC15+BE15 -> 0 | X15: =W15*1696 -> 0 | AB15: =Z15*995 -> 0 | AE15: =AC15*1696 -> 0 | AF15: =AD15*995 -> 0 | AH15: 2 | AJ15: =AH15*995 -> 1990 | AL15: 1 | AN15: =AL15*995 -> 995 | AR15: =AP15*995 -> 0 | AS15: 0.5 | AU15: =AS15*1696 -> 848 | AV15: =AT15*995 -> 0 | BB15: =AZ15*995 -> 0 | BD15: =BC15*320 -> 0 | BF15: =BE15*320 -> 0 | BG15: =SUM(BH15:BL15) -> 0 | BR15: =SUM(BT15,BW15,BX15,BZ15,CB15) -> 0 | BX15: =BV15*995 -> 0 | BZ15: =BY15*320 -> 0 | CB15: =CA15*320 -> 0 | CC15: =SUM(CD15:CH15) -> 0
A16: 12 | C16: 项目定制 | E16: 高峰时段分析 | F16: 统计0-24小时每个小时火灾警情发生频次，柱状图可视化展示；支持按年、季度、月、周时间维度筛选；支持按行政区划、中队辖区做筛选，查看不同区域火灾高发时段；图表支持导出图片、导出Excel原始统计数据。 | H16: 研发 | N16: =O16+P16+Q16+R16 -> 3833 | O16: =X16 -> 0 | P16: =AA16+AE16+AI16+AM16+AQ16+AU16+AX16+BA16 -> 848 | Q16: =AB16+AF16+AJ16+AN16+AR16+AV16+BB16 -> 2985 | R16: =BD16+BF16 -> 0 | S16: =W16 -> 0 | T16: =Y16+AC16+AG16+AK16+AO16+AS16+AW16+AY16 -> 0.5 | U16: =Z16+AD16+AH16+AL16+AP16+AT16+AZ16 -> 3 | V16: =BC16+BE16 -> 0 | X16: =W16*1696 -> 0 | AB16: =Z16*995 -> 0 | AE16: =AC16*1696 -> 0 | AF16: =AD16*995 -> 0 | AH16: 2 | AJ16: =AH16*995 -> 1990 | AL16: 1 | AN16: =AL16*995 -> 995 | AR16: =AP16*995 -> 0 | AS16: 0.5 | AU16: =AS16*1696 -> 848 | AV16: =AT16*995 -> 0 | BB16: =AZ16*995 -> 0 | BD16: =BC16*320 -> 0 | BF16: =BE16*320 -> 0 | BG16: =SUM(BH16:BL16) -> 0 | BR16: =SUM(BT16,BW16,BX16,BZ16,CB16) -> 0 | BX16: =BV16*995 -> 0 | BZ16: =BY16*320 -> 0 | CB16: =CA16*320 -> 0 | CC16: =SUM(CD16:CH16) -> 0
A17: 13 | C17: 项目定制 | E17: 重复报警点监测 | F17: 空间聚类算法识别半径50米范围内，1年内发生≥2次警情点位 顽固隐患点在地图特殊标记展示；点击点位展示全部历史警情记录、报警时间、起火原因 | H17: 研发 | N17: =O17+P17+Q17+R17 -> 3833 | O17: =X17 -> 0 | P17: =AA17+AE17+AI17+AM17+AQ17+AU17+AX17+BA17 -> 848 | Q17: =AB17+AF17+AJ17+AN17+AR17+AV17+BB17 -> 2985 | R17: =BD17+BF17 -> 0 | S17: =W17 -> 0 | T17: =Y17+AC17+AG17+AK17+AO17+AS17+AW17+AY17 -> 0.5 | U17: =Z17+AD17+AH17+AL17+AP17+AT17+AZ17 -> 3 | V17: =BC17+BE17 -> 0 | X17: =W17*1696 -> 0 | AB17: =Z17*995 -> 0 | AE17: =AC17*1696 -> 0 | AF17: =AD17*995 -> 0 | AH17: 2 | AJ17: =AH17*995 -> 1990 | AL17: 1 | AN17: =AL17*995 -> 995 | AR17: =AP17*995 -> 0 | AS17: 0.5 | AU17: =AS17*1696 -> 848 | AV17: =AT17*995 -> 0 | BB17: =AZ17*995 -> 0 | BD17: =BC17*320 -> 0 | BF17: =BE17*320 -> 0 | BG17: =SUM(BH17:BL17) -> 0 | BR17: =SUM(BT17,BW17,BX17,BZ17,CB17) -> 0 | BX17: =BV17*995 -> 0 | BZ17: =BY17*320 -> 0 | CB17: =CA17*320 -> 0 | CC17: =SUM(CD17:CH17) -> 0
A18: 14 | C18: 项目定制 | E18: 起火原因聚类统计 | F18: 按行政区划、消防中队统计起火原因：电气故障、燃气泄漏、吸烟、自燃、外来火源、生产作业等类型；饼图、柱状图展示各类起火原因占比；支持时间范围筛选；支持原因占比排序，快速定位区域突出火灾风险；统计图表支持导出图片、导出原始统计表格。 | H18: 研发 | N18: =O18+P18+Q18+R18 -> 3833 | O18: =X18 -> 0 | P18: =AA18+AE18+AI18+AM18+AQ18+AU18+AX18+BA18 -> 848 | Q18: =AB18+AF18+AJ18+AN18+AR18+AV18+BB18 -> 2985 | R18: =BD18+BF18 -> 0 | S18: =W18 -> 0 | T18: =Y18+AC18+AG18+AK18+AO18+AS18+AW18+AY18 -> 0.5 | U18: =Z18+AD18+AH18+AL18+AP18+AT18+AZ18 -> 3 | V18: =BC18+BE18 -> 0 | X18: =W18*1696 -> 0 | AB18: =Z18*995 -> 0 | AE18: =AC18*1696 -> 0 | AF18: =AD18*995 -> 0 | AH18: 2 | AJ18: =AH18*995 -> 1990 | AL18: 1 | AN18: =AL18*995 -> 995 | AR18: =AP18*995 -> 0 | AS18: 0.5 | AU18: =AS18*1696 -> 848 | AV18: =AT18*995 -> 0 | BB18: =AZ18*995 -> 0 | BD18: =BC18*320 -> 0 | BF18: =BE18*320 -> 0 | BG18: =SUM(BH18:BL18) -> 0 | BR18: =SUM(BT18,BW18,BX18,BZ18,CB18) -> 0 | BX18: =BV18*995 -> 0 | BZ18: =BY18*320 -> 0 | CB18: =CA18*320 -> 0 | CC18: =SUM(CD18:CH18) -> 0
A19: 15 | C19: 项目定制 | E19: 风险等级热力图 | F19: 基于单位风险等级数据，生成热力图； 算法计算生成全域风险热力图层，直观展示高风险聚集区域；支持按单位类型过滤，只看某一类单位风险热力；支持热力图层开关、透明度调节，支持截图导出。 | H19: 研发 | N19: =O19+P19+Q19+R19 -> 3833 | O19: =X19 -> 0 | P19: =AA19+AE19+AI19+AM19+AQ19+AU19+AX19+BA19 -> 848 | Q19: =AB19+AF19+AJ19+AN19+AR19+AV19+BB19 -> 2985 | R19: =BD19+BF19 -> 0 | S19: =W19 -> 0 | T19: =Y19+AC19+AG19+AK19+AO19+AS19+AW19+AY19 -> 0.5 | U19: =Z19+AD19+AH19+AL19+AP19+AT19+AZ19 -> 3 | V19: =BC19+BE19 -> 0 | X19: =W19*1696 -> 0 | AB19: =Z19*995 -> 0 | AE19: =AC19*1696 -> 0 | AF19: =AD19*995 -> 0 | AH19: 2 | AJ19: =AH19*995 -> 1990 | AL19: 1 | AN19: =AL19*995 -> 995 | AR19: =AP19*995 -> 0 | AS19: 0.5 | AU19: =AS19*1696 -> 848 | AV19: =AT19*995 -> 0 | BB19: =AZ19*995 -> 0 | BD19: =BC19*320 -> 0 | BF19: =BE19*320 -> 0 | BG19: =SUM(BH19:BL19) -> 0 | BR19: =SUM(BT19,BW19,BX19,BZ19,CB19) -> 0 | BX19: =BV19*995 -> 0 | BZ19: =BY19*320 -> 0 | CB19: =CA19*320 -> 0 | CC19: =SUM(CD19:CH19) -> 0
A20: 16 | C20: 项目定制 | E20: 单位类型分布图 | F20: 支持显示大型商业综合体、学校、医院、高层住宅、养老院、二级重点单位、工贸企业等单位分类，不同类别配置独立图标、颜色； 支持按单位类型筛选过滤地图显示火灾风险要素，例如：自动消防设施、危化学品、粉尘、出租房、九小场所、燃气、新业态场所、三合一场所、住宿、食堂、特殊人群、高危气体）=等。 | H20: 研发 | N20: =O20+P20+Q20+R20 -> 3833 | O20: =X20 -> 0 | P20: =AA20+AE20+AI20+AM20+AQ20+AU20+AX20+BA20 -> 848 | Q20: =AB20+AF20+AJ20+AN20+AR20+AV20+BB20 -> 2985 | R20: =BD20+BF20 -> 0 | S20: =W20 -> 0 | T20: =Y20+AC20+AG20+AK20+AO20+AS20+AW20+AY20 -> 0.5 | U20: =Z20+AD20+AH20+AL20+AP20+AT20+AZ20 -> 3 | V20: =BC20+BE20 -> 0 | X20: =W20*1696 -> 0 | AB20: =Z20*995 -> 0 | AE20: =AC20*1696 -> 0 | AF20: =AD20*995 -> 0 | AH20: 2 | AJ20: =AH20*995 -> 1990 | AL20: 1 | AN20: =AL20*995 -> 995 | AR20: =AP20*995 -> 0 | AS20: 0.5 | AU20: =AS20*1696 -> 848 | AV20: =AT20*995 -> 0 | BB20: =AZ20*995 -> 0 | BD20: =BC20*320 -> 0 | BF20: =BE20*320 -> 0 | BG20: =SUM(BH20:BL20) -> 0 | BR20: =SUM(BT20,BW20,BX20,BZ20,CB20) -> 0 | BX20: =BV20*995 -> 0 | BZ20: =BY20*320 -> 0 | CB20: =CA20*320 -> 0 | CC20: =SUM(CD20:CH20) -> 0
A21: 17 | C21: 项目定制 | E21: 单位消防元素展示 | F21: 检索定位独立管理主体（单位/楼宇/园区），点击单位点位弹窗展示单位全量消防要素信息：建筑概况、所属消防中队、消防设施清单（消火栓、灭火器、喷淋等）、火灾风险积分、火灾风险要素。 | H21: 研发 | N21: =O21+P21+Q21+R21 -> 3833 | O21: =X21 -> 0 | P21: =AA21+AE21+AI21+AM21+AQ21+AU21+AX21+BA21 -> 848 | Q21: =AB21+AF21+AJ21+AN21+AR21+AV21+BB21 -> 2985 | R21: =BD21+BF21 -> 0 | S21: =W21 -> 0 | T21: =Y21+AC21+AG21+AK21+AO21+AS21+AW21+AY21 -> 0.5 | U21: =Z21+AD21+AH21+AL21+AP21+AT21+AZ21 -> 3 | V21: =BC21+BE21 -> 0 | X21: =W21*1696 -> 0 | AB21: =Z21*995 -> 0 | AE21: =AC21*1696 -> 0 | AF21: =AD21*995 -> 0 | AH21: 2 | AJ21: =AH21*995 -> 1990 | AL21: 1 | AN21: =AL21*995 -> 995 | AR21: =AP21*995 -> 0 | AS21: 0.5 | AU21: =AS21*1696 -> 848 | AV21: =AT21*995 -> 0 | BB21: =AZ21*995 -> 0 | BD21: =BC21*320 -> 0 | BF21: =BE21*320 -> 0 | BG21: =SUM(BH21:BL21) -> 0 | BR21: =SUM(BT21,BW21,BX21,BZ21,CB21) -> 0 | BX21: =BV21*995 -> 0 | BZ21: =BY21*320 -> 0 | CB21: =CA21*320 -> 0 | CC21: =SUM(CD21:CH21) -> 0
A22: 18 | C22: 数智网格化系统 | D22: 图层综合管理 | E22: 普通管理 | F22: 提供点线面图层的编排管理功能，支持图层的新建、修改、删除、显隐、排序、详情查看等功能 | G22: 网格管理平台 | H22: 交付运营 | N22: =O22+P22+Q22+R22 -> 1990 | O22: =X22 -> 0 | P22: =AA22+AE22+AI22+AM22+AQ22+AU22+AX22+BA22 -> 0 | Q22: =AB22+AF22+AJ22+AN22+AR22+AV22+BB22 -> 1990 | R22: =BD22+BF22 -> 0 | S22: =W22 -> 0 | T22: =Y22+AC22+AG22+AK22+AO22+AS22+AW22+AY22 -> 0 | U22: =Z22+AD22+AH22+AL22+AP22+AT22+AZ22 -> 2 | V22: =BC22+BE22 -> 0 | X22: =W22*1696 -> 0 | AB22: =Z22*995 -> 0 | AE22: =AC22*1696 -> 0 | AF22: =AD22*995 -> 0 | AH22: 2 | AJ22: =AH22*995 -> 1990 | AN22: =AL22*995 -> 0 | AR22: =AP22*995 -> 0 | AU22: =AS22*1696 -> 0 | AV22: =AT22*995 -> 0 | BB22: =AZ22*995 -> 0 | BD22: =BC22*320 -> 0 | BF22: =BE22*320 -> 0 | BG22: =SUM(BH22:BL22) -> 0 | BR22: =SUM(BT22,BW22,BX22,BZ22,CB22) -> 0 | BX22: =BV22*995 -> 0 | BZ22: =BY22*320 -> 0 | CB22: =CA22*320 -> 0 | CC22: =SUM(CD22:CH22) -> 0
A23: 19 | C23: 数智网格化系统 | E23: 图层数据 | F23: 提供点线面图层的数据管理功能，支持图层数据的导入、导出、清空及要素数据的属性管理。线下上传，支持CSV、GEOJSON、SHP（zip格式）文件格式；线上对接，支持WFS服务格式。 | H23: 交付运营 | N23: =O23+P23+Q23+R23 -> 1990 | O23: =X23 -> 0 | P23: =AA23+AE23+AI23+AM23+AQ23+AU23+AX23+BA23 -> 0 | Q23: =AB23+AF23+AJ23+AN23+AR23+AV23+BB23 -> 1990 | R23: =BD23+BF23 -> 0 | S23: =W23 -> 0 | T23: =Y23+AC23+AG23+AK23+AO23+AS23+AW23+AY23 -> 0 | U23: =Z23+AD23+AH23+AL23+AP23+AT23+AZ23 -> 2 | V23: =BC23+BE23 -> 0 | X23: =W23*1696 -> 0 | AB23: =Z23*995 -> 0 | AE23: =AC23*1696 -> 0 | AF23: =AD23*995 -> 0 | AH23: 2 | AJ23: =AH23*995 -> 1990 | AN23: =AL23*995 -> 0 | AR23: =AP23*995 -> 0 | AU23: =AS23*1696 -> 0 | AV23: =AT23*995 -> 0 | BB23: =AZ23*995 -> 0 | BD23: =BC23*320 -> 0 | BF23: =BE23*320 -> 0 | BG23: =SUM(BH23:BL23) -> 0 | BR23: =SUM(BT23,BW23,BX23,BZ23,CB23) -> 0 | BX23: =BV23*995 -> 0 | BZ23: =BY23*320 -> 0 | CB23: =CA23*320 -> 0 | CC23: =SUM(CD23:CH23) -> 0
A24: 20 | C24: 数智网格化系统 | E24: 要素绘制 | F24: 提供画点、画线、画面的要素绘制能力，其中画面支持自由画面、圆形画面、矩形画面等方式，并支持对面的合并、拆分、挖孔、删飞地、填挖孔等编辑功能。 | H24: 交付运营 | N24: =O24+P24+Q24+R24 -> 1990 | O24: =X24 -> 0 | P24: =AA24+AE24+AI24+AM24+AQ24+AU24+AX24+BA24 -> 0 | Q24: =AB24+AF24+AJ24+AN24+AR24+AV24+BB24 -> 1990 | R24: =BD24+BF24 -> 0 | S24: =W24 -> 0 | T24: =Y24+AC24+AG24+AK24+AO24+AS24+AW24+AY24 -> 0 | U24: =Z24+AD24+AH24+AL24+AP24+AT24+AZ24 -> 2 | V24: =BC24+BE24 -> 0 | X24: =W24*1696 -> 0 | AB24: =Z24*995 -> 0 | AE24: =AC24*1696 -> 0 | AF24: =AD24*995 -> 0 | AH24: 2 | AJ24: =AH24*995 -> 1990 | AN24: =AL24*995 -> 0 | AR24: =AP24*995 -> 0 | AU24: =AS24*1696 -> 0 | AV24: =AT24*995 -> 0 | BB24: =AZ24*995 -> 0 | BD24: =BC24*320 -> 0 | BF24: =BE24*320 -> 0 | BG24: =SUM(BH24:BL24) -> 0 | BR24: =SUM(BT24,BW24,BX24,BZ24,CB24) -> 0 | BX24: =BV24*995 -> 0 | BZ24: =BY24*320 -> 0 | CB24: =CA24*320 -> 0 | CC24: =SUM(CD24:CH24) -> 0
A25: 21 | C25: 数智网格化系统 | E25: 要素编辑 | F25: 提供已绘制的点/线/面要素编辑功能，包含属性、样式、边界的编辑，支持上传图片、删除要素。 | H25: 交付运营 | N25: =O25+P25+Q25+R25 -> 1990 | O25: =X25 -> 0 | P25: =AA25+AE25+AI25+AM25+AQ25+AU25+AX25+BA25 -> 0 | Q25: =AB25+AF25+AJ25+AN25+AR25+AV25+BB25 -> 1990 | R25: =BD25+BF25 -> 0 | S25: =W25 -> 0 | T25: =Y25+AC25+AG25+AK25+AO25+AS25+AW25+AY25 -> 0 | U25: =Z25+AD25+AH25+AL25+AP25+AT25+AZ25 -> 2 | V25: =BC25+BE25 -> 0 | X25: =W25*1696 -> 0 | AB25: =Z25*995 -> 0 | AE25: =AC25*1696 -> 0 | AF25: =AD25*995 -> 0 | AH25: 2 | AJ25: =AH25*995 -> 1990 | AN25: =AL25*995 -> 0 | AR25: =AP25*995 -> 0 | AU25: =AS25*1696 -> 0 | AV25: =AT25*995 -> 0 | BB25: =AZ25*995 -> 0 | BD25: =BC25*320 -> 0 | BF25: =BE25*320 -> 0 | BG25: =SUM(BH25:BL25) -> 0 | BR25: =SUM(BT25,BW25,BX25,BZ25,CB25) -> 0 | BX25: =BV25*995 -> 0 | BZ25: =BY25*320 -> 0 | CB25: =CA25*320 -> 0 | CC25: =SUM(CD25:CH25) -> 0
A26: 22 | C26: 数智网格化系统 | E26: 要素样式 | F26: 提供整个点/线/面图层的样式设置功能，点图层支持设置默认统一样式、分类样式、聚合样式、热力图等，线/面图层支持设置默认单一样式、分类样式。 | H26: 交付运营 | N26: =O26+P26+Q26+R26 -> 1990 | O26: =X26 -> 0 | P26: =AA26+AE26+AI26+AM26+AQ26+AU26+AX26+BA26 -> 0 | Q26: =AB26+AF26+AJ26+AN26+AR26+AV26+BB26 -> 1990 | R26: =BD26+BF26 -> 0 | S26: =W26 -> 0 | T26: =Y26+AC26+AG26+AK26+AO26+AS26+AW26+AY26 -> 0 | U26: =Z26+AD26+AH26+AL26+AP26+AT26+AZ26 -> 2 | V26: =BC26+BE26 -> 0 | X26: =W26*1696 -> 0 | AB26: =Z26*995 -> 0 | AE26: =AC26*1696 -> 0 | AF26: =AD26*995 -> 0 | AH26: 2 | AJ26: =AH26*995 -> 1990 | AN26: =AL26*995 -> 0 | AR26: =AP26*995 -> 0 | AU26: =AS26*1696 -> 0 | AV26: =AT26*995 -> 0 | BB26: =AZ26*995 -> 0 | BD26: =BC26*320 -> 0 | BF26: =BE26*320 -> 0 | BG26: =SUM(BH26:BL26) -> 0 | BR26: =SUM(BT26,BW26,BX26,BZ26,CB26) -> 0 | BX26: =BV26*995 -> 0 | BZ26: =BY26*320 -> 0 | CB26: =CA26*320 -> 0 | CC26: =SUM(CD26:CH26) -> 0
A27: 23 | C27: 数智网格化系统 | D27: 网格绘制 | E27: 网格绘制工具 | F27: 提供网格绘制管理工具，包括网格的新增、编辑、删除、合并、拆分、挖空、删除飞地、填充挖空、接边自动吸附、接边联动编辑功能，在网格绘制过程中，维护网格边界 | H27: 交付运营 | N27: =O27+P27+Q27+R27 -> 1990 | O27: =X27 -> 0 | P27: =AA27+AE27+AI27+AM27+AQ27+AU27+AX27+BA27 -> 0 | Q27: =AB27+AF27+AJ27+AN27+AR27+AV27+BB27 -> 1990 | R27: =BD27+BF27 -> 0 | S27: =W27 -> 0 | T27: =Y27+AC27+AG27+AK27+AO27+AS27+AW27+AY27 -> 0 | U27: =Z27+AD27+AH27+AL27+AP27+AT27+AZ27 -> 2 | V27: =BC27+BE27 -> 0 | X27: =W27*1696 -> 0 | AB27: =Z27*995 -> 0 | AE27: =AC27*1696 -> 0 | AF27: =AD27*995 -> 0 | AH27: 2 | AJ27: =AH27*995 -> 1990 | AN27: =AL27*995 -> 0 | AR27: =AP27*995 -> 0 | AU27: =AS27*1696 -> 0 | AV27: =AT27*995 -> 0 | BB27: =AZ27*995 -> 0 | BD27: =BC27*320 -> 0 | BF27: =BE27*320 -> 0 | BG27: =SUM(BH27:BL27) -> 0 | BR27: =SUM(BT27,BW27,BX27,BZ27,CB27) -> 0 | BX27: =BV27*995 -> 0 | BZ27: =BY27*320 -> 0 | CB27: =CA27*320 -> 0 | CC27: =SUM(CD27:CH27) -> 0
A28: 24 | C28: 数智网格化系统 | E28: 问题检查工具 | F28: 提供网格边界拓扑问题检查工具，检查网格数据问题，包括缝隙和压盖问题检查和自相交问题检查 | H28: 交付运营 | N28: =O28+P28+Q28+R28 -> 1990 | O28: =X28 -> 0 | P28: =AA28+AE28+AI28+AM28+AQ28+AU28+AX28+BA28 -> 0 | Q28: =AB28+AF28+AJ28+AN28+AR28+AV28+BB28 -> 1990 | R28: =BD28+BF28 -> 0 | S28: =W28 -> 0 | T28: =Y28+AC28+AG28+AK28+AO28+AS28+AW28+AY28 -> 0 | U28: =Z28+AD28+AH28+AL28+AP28+AT28+AZ28 -> 2 | V28: =BC28+BE28 -> 0 | X28: =W28*1696 -> 0 | AB28: =Z28*995 -> 0 | AE28: =AC28*1696 -> 0 | AF28: =AD28*995 -> 0 | AH28: 2 | AJ28: =AH28*995 -> 1990 | AN28: =AL28*995 -> 0 | AR28: =AP28*995 -> 0 | AU28: =AS28*1696 -> 0 | AV28: =AT28*995 -> 0 | BB28: =AZ28*995 -> 0 | BD28: =BC28*320 -> 0 | BF28: =BE28*320 -> 0 | BG28: =SUM(BH28:BL28) -> 0 | BR28: =SUM(BT28,BW28,BX28,BZ28,CB28) -> 0 | BX28: =BV28*995 -> 0 | BZ28: =BY28*320 -> 0 | CB28: =CA28*320 -> 0 | CC28: =SUM(CD28:CH28) -> 0
A29: 25 | C29: 数智网格化系统 | E29: 审核反馈记录 | F29: 提供已编辑未提交、已提交待审核的网格数据的反馈记录查看功能，支持提交网格、撤销编辑、继续编辑、撤销提交和查看日志等网格操作 | H29: 交付运营 | N29: =O29+P29+Q29+R29 -> 1990 | O29: =X29 -> 0 | P29: =AA29+AE29+AI29+AM29+AQ29+AU29+AX29+BA29 -> 0 | Q29: =AB29+AF29+AJ29+AN29+AR29+AV29+BB29 -> 1990 | R29: =BD29+BF29 -> 0 | S29: =W29 -> 0 | T29: =Y29+AC29+AG29+AK29+AO29+AS29+AW29+AY29 -> 0 | U29: =Z29+AD29+AH29+AL29+AP29+AT29+AZ29 -> 2 | V29: =BC29+BE29 -> 0 | X29: =W29*1696 -> 0 | AB29: =Z29*995 -> 0 | AE29: =AC29*1696 -> 0 | AF29: =AD29*995 -> 0 | AH29: 2 | AJ29: =AH29*995 -> 1990 | AN29: =AL29*995 -> 0 | AR29: =AP29*995 -> 0 | AU29: =AS29*1696 -> 0 | AV29: =AT29*995 -> 0 | BB29: =AZ29*995 -> 0 | BD29: =BC29*320 -> 0 | BF29: =BE29*320 -> 0 | BG29: =SUM(BH29:BL29) -> 0 | BR29: =SUM(BT29,BW29,BX29,BZ29,CB29) -> 0 | BX29: =BV29*995 -> 0 | BZ29: =BY29*320 -> 0 | CB29: =CA29*320 -> 0 | CC29: =SUM(CD29:CH29) -> 0
A30: 26 | C30: 数智网格化系统 | E30: 图层组管理 | F30: 提供图层组的展示和操作管理功能，支持图层组的增删改、数据导入导出、版本管理功能，其中版本支持新建、查看、回滚、删除、对比、导出等功能 | H30: 交付运营 | N30: =O30+P30+Q30+R30 -> 1990 | O30: =X30 -> 0 | P30: =AA30+AE30+AI30+AM30+AQ30+AU30+AX30+BA30 -> 0 | Q30: =AB30+AF30+AJ30+AN30+AR30+AV30+BB30 -> 1990 | R30: =BD30+BF30 -> 0 | S30: =W30 -> 0 | T30: =Y30+AC30+AG30+AK30+AO30+AS30+AW30+AY30 -> 0 | U30: =Z30+AD30+AH30+AL30+AP30+AT30+AZ30 -> 2 | V30: =BC30+BE30 -> 0 | X30: =W30*1696 -> 0 | AB30: =Z30*995 -> 0 | AE30: =AC30*1696 -> 0 | AF30: =AD30*995 -> 0 | AH30: 2 | AJ30: =AH30*995 -> 1990 | AN30: =AL30*995 -> 0 | AR30: =AP30*995 -> 0 | AU30: =AS30*1696 -> 0 | AV30: =AT30*995 -> 0 | BB30: =AZ30*995 -> 0 | BD30: =BC30*320 -> 0 | BF30: =BE30*320 -> 0 | BG30: =SUM(BH30:BL30) -> 0 | BR30: =SUM(BT30,BW30,BX30,BZ30,CB30) -> 0 | BX30: =BV30*995 -> 0 | BZ30: =BY30*320 -> 0 | CB30: =CA30*320 -> 0 | CC30: =SUM(CD30:CH30) -> 0
A31: 27 | C31: 数智网格化系统 | E31: 网格数据管理 | F31: 提供列表式的网格数据管理功能，包含网格数据的父子级联树展示，支持网格数据记录的新增、编辑、删除及批量导出 | H31: 交付运营 | N31: =O31+P31+Q31+R31 -> 1990 | O31: =X31 -> 0 | P31: =AA31+AE31+AI31+AM31+AQ31+AU31+AX31+BA31 -> 0 | Q31: =AB31+AF31+AJ31+AN31+AR31+AV31+BB31 -> 1990 | R31: =BD31+BF31 -> 0 | S31: =W31 -> 0 | T31: =Y31+AC31+AG31+AK31+AO31+AS31+AW31+AY31 -> 0 | U31: =Z31+AD31+AH31+AL31+AP31+AT31+AZ31 -> 2 | V31: =BC31+BE31 -> 0 | X31: =W31*1696 -> 0 | AB31: =Z31*995 -> 0 | AE31: =AC31*1696 -> 0 | AF31: =AD31*995 -> 0 | AH31: 2 | AJ31: =AH31*995 -> 1990 | AN31: =AL31*995 -> 0 | AR31: =AP31*995 -> 0 | AU31: =AS31*1696 -> 0 | AV31: =AT31*995 -> 0 | BB31: =AZ31*995 -> 0 | BD31: =BC31*320 -> 0 | BF31: =BE31*320 -> 0 | BG31: =SUM(BH31:BL31) -> 0 | BX31: =BV31*995 -> 0 | BZ31: =BY31*320 -> 0 | CB31: =CA31*320 -> 0 | CC31: =SUM(CD31:CH31) -> 0
A32: 28 | C32: 数智网格化系统 | D32: 网格管理 | E32: 网格审核管理 | F32: 提供待审核网格记录的查看、审核功能，提供已审核网格记录的查看功能 | H32: 交付运营 | N32: =O32+P32+Q32+R32 -> 1990 | O32: =X32 -> 0 | P32: =AA32+AE32+AI32+AM32+AQ32+AU32+AX32+BA32 -> 0 | Q32: =AB32+AF32+AJ32+AN32+AR32+AV32+BB32 -> 1990 | R32: =BD32+BF32 -> 0 | S32: =W32 -> 0 | T32: =Y32+AC32+AG32+AK32+AO32+AS32+AW32+AY32 -> 0 | U32: =Z32+AD32+AH32+AL32+AP32+AT32+AZ32 -> 2 | V32: =BC32+BE32 -> 0 | X32: =W32*1696 -> 0 | AB32: =Z32*995 -> 0 | AE32: =AC32*1696 -> 0 | AF32: =AD32*995 -> 0 | AH32: 2 | AJ32: =AH32*995 -> 1990 | AN32: =AL32*995 -> 0 | AR32: =AP32*995 -> 0 | AU32: =AS32*1696 -> 0 | AV32: =AT32*995 -> 0 | BB32: =AZ32*995 -> 0 | BD32: =BC32*320 -> 0 | BF32: =BE32*320 -> 0 | BG32: =SUM(BH32:BL32) -> 0 | BX32: =BV32*995 -> 0 | BZ32: =BY32*320 -> 0 | CB32: =CA32*320 -> 0 | CC32: =SUM(CD32:CH32) -> 0
A33: 29 | C33: 数智网格化系统 | E33: 网格权限管理 | F33: 提供网格数据权限分配功能，支持图层组创建者给网格绘制员分配不同的网格辖区权限，避免误操作不属于自己辖区的网格数据 | H33: 交付运营 | N33: =O33+P33+Q33+R33 -> 1990 | O33: =X33 -> 0 | P33: =AA33+AE33+AI33+AM33+AQ33+AU33+AX33+BA33 -> 0 | Q33: =AB33+AF33+AJ33+AN33+AR33+AV33+BB33 -> 1990 | R33: =BD33+BF33 -> 0 | S33: =W33 -> 0 | T33: =Y33+AC33+AG33+AK33+AO33+AS33+AW33+AY33 -> 0 | U33: =Z33+AD33+AH33+AL33+AP33+AT33+AZ33 -> 2 | V33: =BC33+BE33 -> 0 | X33: =W33*1696 -> 0 | AB33: =Z33*995 -> 0 | AE33: =AC33*1696 -> 0 | AF33: =AD33*995 -> 0 | AH33: 2 | AJ33: =AH33*995 -> 1990 | AN33: =AL33*995 -> 0 | AR33: =AP33*995 -> 0 | AU33: =AS33*1696 -> 0 | AV33: =AT33*995 -> 0 | BB33: =AZ33*995 -> 0 | BD33: =BC33*320 -> 0 | BF33: =BE33*320 -> 0 | BG33: =SUM(BH33:BL33) -> 0 | BX33: =BV33*995 -> 0 | BZ33: =BY33*320 -> 0 | CB33: =CA33*320 -> 0 | CC33: =SUM(CD33:CH33) -> 0
A34: 30 | C34: 数智网格化系统 | E34: 网格模板管理 | F34: 提供网格模板管理功能，支持在新建图层组时一键复用 | H34: 交付运营 | N34: =O34+P34+Q34+R34 -> 1990 | O34: =X34 -> 0 | P34: =AA34+AE34+AI34+AM34+AQ34+AU34+AX34+BA34 -> 0 | Q34: =AB34+AF34+AJ34+AN34+AR34+AV34+BB34 -> 1990 | R34: =BD34+BF34 -> 0 | S34: =W34 -> 0 | T34: =Y34+AC34+AG34+AK34+AO34+AS34+AW34+AY34 -> 0 | U34: =Z34+AD34+AH34+AL34+AP34+AT34+AZ34 -> 2 | V34: =BC34+BE34 -> 0 | X34: =W34*1696 -> 0 | AB34: =Z34*995 -> 0 | AE34: =AC34*1696 -> 0 | AF34: =AD34*995 -> 0 | AH34: 2 | AJ34: =AH34*995 -> 1990 | AN34: =AL34*995 -> 0 | AR34: =AP34*995 -> 0 | AU34: =AS34*1696 -> 0 | AV34: =AT34*995 -> 0 | BB34: =AZ34*995 -> 0 | BD34: =BC34*320 -> 0 | BF34: =BE34*320 -> 0 | BG34: =SUM(BH34:BL34) -> 0 | BX34: =BV34*995 -> 0 | BZ34: =BY34*320 -> 0 | CB34: =CA34*320 -> 0 | CC34: =SUM(CD34:CH34) -> 0
A35: 31 | C35: 数智网格化系统 | D35: 后台管理 | E35: 用户管理 | F35: 用于对平台的用户信息进行管理，保证启用的用户能够登录平台，提供用户的新增、编辑、删除、查询、导出等功能 | H35: 交付运营 | N35: =O35+P35+Q35+R35 -> 1990 | O35: =X35 -> 0 | P35: =AA35+AE35+AI35+AM35+AQ35+AU35+AX35+BA35 -> 0 | Q35: =AB35+AF35+AJ35+AN35+AR35+AV35+BB35 -> 1990 | R35: =BD35+BF35 -> 0 | S35: =W35 -> 0 | T35: =Y35+AC35+AG35+AK35+AO35+AS35+AW35+AY35 -> 0 | U35: =Z35+AD35+AH35+AL35+AP35+AT35+AZ35 -> 2 | V35: =BC35+BE35 -> 0 | X35: =W35*1696 -> 0 | AB35: =Z35*995 -> 0 | AE35: =AC35*1696 -> 0 | AF35: =AD35*995 -> 0 | AH35: 2 | AJ35: =AH35*995 -> 1990 | AN35: =AL35*995 -> 0 | AR35: =AP35*995 -> 0 | AU35: =AS35*1696 -> 0 | AV35: =AT35*995 -> 0 | BB35: =AZ35*995 -> 0 | BD35: =BC35*320 -> 0 | BF35: =BE35*320 -> 0 | BG35: =SUM(BH35:BL35) -> 0 | BX35: =BV35*995 -> 0 | BZ35: =BY35*320 -> 0 | CB35: =CA35*320 -> 0 | CC35: =SUM(CD35:CH35) -> 0
A36: 32 | C36: 数智网格化系统 | E36: 角色管理 | F36: 用于管理用户组对应角色权限，能够在此模块中对角色进行功能菜单权限和数据权限的配置，保障不同的用户具有不同的系统和功能权限，支持角色的新增、修改、删除、查询等 | H36: 交付运营 | N36: =O36+P36+Q36+R36 -> 0 | O36: =X36 -> 0 | P36: =AA36+AE36+AI36+AM36+AQ36+AU36+AX36+BA36 -> 0 | Q36: =AB36+AF36+AJ36+AN36+AR36+AV36+BB36 -> 0 | R36: =BD36+BF36 -> 0 | S36: =W36 -> 0 | T36: =Y36+AC36+AG36+AK36+AO36+AS36+AW36+AY36 -> 0 | U36: =Z36+AD36+AH36+AL36+AP36+AT36+AZ36 -> 0 | V36: =BC36+BE36 -> 0 | X36: =W36*1696 -> 0 | AB36: =Z36*995 -> 0 | AE36: =AC36*1696 -> 0 | AF36: =AD36*995 -> 0 | AJ36: =AH36*995 -> 0 | AN36: =AL36*995 -> 0 | AR36: =AP36*995 -> 0 | AU36: =AS36*1696 -> 0 | AV36: =AT36*995 -> 0 | BB36: =AZ36*995 -> 0 | BD36: =BC36*320 -> 0 | BF36: =BE36*320 -> 0 | BG36: =SUM(BH36:BL36) -> 0 | BX36: =BV36*995 -> 0 | BZ36: =BY36*320 -> 0 | CB36: =CA36*320 -> 0 | CC36: =SUM(CD36:CH36) -> 0
A37: 33 | C37: 数智网格化系统 | E37: 部门管理 | F37: 用于对用户所属部门进行管理，支持部门的新增、修改、删除、查询等 | H37: 交付运营 | N37: =O37+P37+Q37+R37 -> 0 | O37: =X37 -> 0 | P37: =AA37+AE37+AI37+AM37+AQ37+AU37+AX37+BA37 -> 0 | Q37: =AB37+AF37+AJ37+AN37+AR37+AV37+BB37 -> 0 | R37: =BD37+BF37 -> 0 | S37: =W37 -> 0 | T37: =Y37+AC37+AG37+AK37+AO37+AS37+AW37+AY37 -> 0 | U37: =Z37+AD37+AH37+AL37+AP37+AT37+AZ37 -> 0 | V37: =BC37+BE37 -> 0 | X37: =W37*1696 -> 0 | AB37: =Z37*995 -> 0 | AE37: =AC37*1696 -> 0 | AF37: =AD37*995 -> 0 | AJ37: =AH37*995 -> 0 | AN37: =AL37*995 -> 0 | AR37: =AP37*995 -> 0 | AU37: =AS37*1696 -> 0 | AV37: =AT37*995 -> 0 | BB37: =AZ37*995 -> 0 | BD37: =BC37*320 -> 0 | BF37: =BE37*320 -> 0 | BG37: =SUM(BH37:BL37) -> 0 | BX37: =BV37*995 -> 0 | BZ37: =BY37*320 -> 0 | CB37: =CA37*320 -> 0 | CC37: =SUM(CD37:CH37) -> 0
A38: 34 | C38: 数智网格化系统 | E38: 字典管理 | F38: 字典管理用于保障产品部分功能能够在项目中实现组件化、可配置，常见用途如地图信息的配置、城市配置、服务参数配置等，支持字典的查询、新增、修改、删除等操作。 | H38: 交付运营 | N38: =O38+P38+Q38+R38 -> 0 | O38: =X38 -> 0 | P38: =AA38+AE38+AI38+AM38+AQ38+AU38+AX38+BA38 -> 0 | Q38: =AB38+AF38+AJ38+AN38+AR38+AV38+BB38 -> 0 | R38: =BD38+BF38 -> 0 | S38: =W38 -> 0 | T38: =Y38+AC38+AG38+AK38+AO38+AS38+AW38+AY38 -> 0 | U38: =Z38+AD38+AH38+AL38+AP38+AT38+AZ38 -> 0 | V38: =BC38+BE38 -> 0 | X38: =W38*1696 -> 0 | AB38: =Z38*995 -> 0 | AE38: =AC38*1696 -> 0 | AF38: =AD38*995 -> 0 | AJ38: =AH38*995 -> 0 | AN38: =AL38*995 -> 0 | AR38: =AP38*995 -> 0 | AU38: =AS38*1696 -> 0 | AV38: =AT38*995 -> 0 | BB38: =AZ38*995 -> 0 | BD38: =BC38*320 -> 0 | BF38: =BE38*320 -> 0 | BG38: =SUM(BH38:BL38) -> 0 | BX38: =BV38*995 -> 0 | BZ38: =BY38*320 -> 0 | CB38: =CA38*320 -> 0 | CC38: =SUM(CD38:CH38) -> 0
A39: 35 | C39: 数智网格化系统 | E39: 权限配置 | F39: 权限配置管理功能权限和数据权限，可以按角色严格限制按钮权限避免越权和限制数据可见范围，支持配置权限的查询、新增、修改、删除等操作。 | H39: 交付运营 | N39: =O39+P39+Q39+R39 -> 0 | O39: =X39 -> 0 | P39: =AA39+AE39+AI39+AM39+AQ39+AU39+AX39+BA39 -> 0 | Q39: =AB39+AF39+AJ39+AN39+AR39+AV39+BB39 -> 0 | R39: =BD39+BF39 -> 0 | S39: =W39 -> 0 | T39: =Y39+AC39+AG39+AK39+AO39+AS39+AW39+AY39 -> 0 | U39: =Z39+AD39+AH39+AL39+AP39+AT39+AZ39 -> 0 | V39: =BC39+BE39 -> 0 | X39: =W39*1696 -> 0 | AB39: =Z39*995 -> 0 | AE39: =AC39*1696 -> 0 | AF39: =AD39*995 -> 0 | AJ39: =AH39*995 -> 0 | AN39: =AL39*995 -> 0 | AR39: =AP39*995 -> 0 | AU39: =AS39*1696 -> 0 | AV39: =AT39*995 -> 0 | BB39: =AZ39*995 -> 0 | BD39: =BC39*320 -> 0 | BF39: =BE39*320 -> 0 | BG39: =SUM(BH39:BL39) -> 0 | BX39: =BV39*995 -> 0 | BZ39: =BY39*320 -> 0 | CB39: =CA39*320 -> 0 | CC39: =SUM(CD39:CH39) -> 0
A40: 36 | C40: 数智网格化系统 | E40: 权限字典 | F40: 权限字典主要用于设置数据权限的字典配置和枚举，为平台的通用字典设置，支持字典的查询、新增、修改、删除等操作 | H40: 交付运营 | N40: =O40+P40+Q40+R40 -> 0 | O40: =X40 -> 0 | P40: =AA40+AE40+AI40+AM40+AQ40+AU40+AX40+BA40 -> 0 | Q40: =AB40+AF40+AJ40+AN40+AR40+AV40+BB40 -> 0 | R40: =BD40+BF40 -> 0 | S40: =W40 -> 0 | T40: =Y40+AC40+AG40+AK40+AO40+AS40+AW40+AY40 -> 0 | U40: =Z40+AD40+AH40+AL40+AP40+AT40+AZ40 -> 0 | V40: =BC40+BE40 -> 0 | X40: =W40*1696 -> 0 | AB40: =Z40*995 -> 0 | AE40: =AC40*1696 -> 0 | AF40: =AD40*995 -> 0 | AJ40: =AH40*995 -> 0 | AN40: =AL40*995 -> 0 | AR40: =AP40*995 -> 0 | AU40: =AS40*1696 -> 0 | AV40: =AT40*995 -> 0 | BB40: =AZ40*995 -> 0 | BD40: =BC40*320 -> 0 | BF40: =BE40*320 -> 0 | BG40: =SUM(BH40:BL40) -> 0 | BX40: =BV40*995 -> 0 | BZ40: =BY40*320 -> 0 | CB40: =CA40*320 -> 0 | CC40: =SUM(CD40:CH40) -> 0
...

Sheet 附4-运维成本评估（决算用）
A1: 项目名称：
A2: 运维阶段起止时间 | F2: 运维阶段总成本
A3: 合计值 | I3: =SUM(I6:I15) -> 0 | J3: =SUM(J6:J15) -> 0 | K3: =SUM(K6:K15) -> 0 | L3: =SUM(L6:L15) -> 0 | M3: =SUM(M6:M15) -> 0 | N3: =SUM(N6:N15) -> 0 | O3: =SUM(O6:O15) -> 0 | P3: =SUM(P6:P15) -> 0 | ... U3: =SUM(U6:U15) -> 0 | X3: =SUM(X6:X15) -> 0 | Y3: =SUM(Y6:Y15) -> 0 | Z3: =SUM(Z6:Z15) -> 0 | AA3: =SUM(AA6:AA15) -> 0 | AB3: =SUM(AB6:AB15) -> 0 | AC3: =SUM(AC6:AC15) -> 0 | AD3: /
A4: 序号 | B4: 解决方案评估 | I4: 2.0 运维阶段- 销售成本 | M4: 2.1 运维阶段-人力成本： | N4: ① 项 目 经 理： | P4: ② 产 研 投 入： | T4: ③ 生产外包-数据类： | V4: ④ 生产外包-软件类： | X4: 2.2 运维阶段-差旅成本 | AD4: 按岗位人员投入人数说明
B5: 建设内容 | C5: 对应标准产品名称 （下拉选择） | D5: 建设内容-细分模块 | E5: 具体功能项 | F5: 功能描述 | G5: 最终交付物 | H5: 交付方式 | I5: 销售-人力成本 | J5: 销售-差旅 | K5: 销售-招待费 | L5: 销售-市场营销 | M5: 运维阶段- 人力成本总额 | N5: 项目经理 正编人天 | O5: 项目经理 正编金额 | P5: 产研 正编人天 | Q5: 产研 外包人天 | R5: 产研 正编金额 | S5: 产研 外包金额 | T5: 生产外包 人天 | U5: 生产外包 金额 | V5: 生产外包 人天 | W5: 生产外包 金额 | X5: 运维阶段- 差旅成本总额 | Y5: 运维阶段-差旅成本 项目经理-差旅、市内交通 | Z5: 运维阶段-差旅成本 项目经理-招待费 | AA5: 运维阶段-差旅成本 产研（正编+外包） | AB5: 运维阶段-差旅成本 生产外包（数据类） | AC5: 运维阶段-差旅成本 生产外包（软件类）
A6: 1 | C6: 统一地址运营 | M6: =SUM(O6,R6,S6,U6) -> 0 | O6: =N6*1750 -> 0 | R6: =P6*1750 -> 0 | S6: =Q6*890 -> 0 | U6: =T6*320 -> 0 | W6: =V6*320 -> 0 | X6: =SUM(Y6:AC6) -> 0 | AD6: 岗位（正编/外包）：人数+对应投入人天 ①产品岗：正编投入_人；外包投入_人 ②前端岗：正编投入_人；外包投入_人 ③后端岗：正编投入_人；外包投入_人 ④大数据开发：正编投入_人；外包投入_人 ⑤交付岗：正编投入_人 ⑥架构岗：正编投入_人；外包投入_人 ⑦其他：正编投入_人；外包投入_人 ......
A7: 2 | C7: 统一地址运营 | M7: =SUM(O7,R7,S7,U7) -> 0 | O7: =N7*1750 -> 0 | R7: =P7*1750 -> 0 | S7: =Q7*890 -> 0 | U7: =T7*320 -> 0 | W7: =V7*320 -> 0 | X7: =SUM(Y7:AC7) -> 0
A8: 3 | C8: 统一地址运营 | M8: =SUM(O8,R8,S8,U8) -> 0 | O8: =N8*1750 -> 0 | R8: =P8*1750 -> 0 | S8: =Q8*890 -> 0 | U8: =T8*320 -> 0 | W8: =V8*320 -> 0 | X8: =SUM(Y8:AC8) -> 0
A9: 4 | C9: 统一地址运营 | M9: =SUM(O9,R9,S9,U9) -> 0 | O9: =N9*1750 -> 0 | R9: =P9*1750 -> 0 | S9: =Q9*890 -> 0 | U9: =T9*320 -> 0 | W9: =V9*320 -> 0 | X9: =SUM(Y9:AC9) -> 0
A10: 5 | C10: 统一地址运营 | M10: =SUM(O10,R10,S10,U10) -> 0 | O10: =N10*1750 -> 0 | R10: =P10*1750 -> 0 | S10: =Q10*890 -> 0 | U10: =T10*320 -> 0 | W10: =V10*320 -> 0 | X10: =SUM(Y10:AC10) -> 0
A11: 6 | C11: 统一地址运营 | M11: =SUM(O11,R11,S11,U11) -> 0 | O11: =N11*1750 -> 0 | R11: =P11*1750 -> 0 | S11: =Q11*890 -> 0 | U11: =T11*320 -> 0 | W11: =V11*320 -> 0 | X11: =SUM(Y11:AC11) -> 0
A12: 7 | C12: 统一地址运营 | M12: =SUM(O12,R12,S12,U12) -> 0 | O12: =N12*1750 -> 0 | R12: =P12*1750 -> 0 | S12: =Q12*890 -> 0 | U12: =T12*320 -> 0 | W12: =V12*320 -> 0 | X12: =SUM(Y12:AC12) -> 0
A13: 8 | C13: 统一地址运营 | M13: =SUM(O13,R13,S13,U13) -> 0 | O13: =N13*1750 -> 0 | R13: =P13*1750 -> 0 | S13: =Q13*890 -> 0 | U13: =T13*320 -> 0 | W13: =V13*320 -> 0 | X13: =SUM(Y13:AC13) -> 0
A14: 9 | C14: 统一地址运营 | M14: =SUM(O14,R14,S14,U14) -> 0 | O14: =N14*1750 -> 0 | R14: =P14*1750 -> 0 | S14: =Q14*890 -> 0 | U14: =T14*320 -> 0 | W14: =V14*320 -> 0 | X14: =SUM(Y14:AC14) -> 0
A15: 10 | C15: 统一地址运营 | M15: =SUM(O15,R15,S15,U15) -> 0 | O15: =N15*1750 -> 0 | R15: =P15*1750 -> 0 | S15: =Q15*890 -> 0 | U15: =T15*320 -> 0 | W15: =V15*320 -> 0 | X15: =SUM(Y15:AC15) -> 0
A17: 填写说明： 1、红色部分由解决方案填写，蓝色部分由项目经理填写，橙色部分由交付运营填写，绿色部分由产研侧填写 2、总成本=项目经理成本（含差旅）+交付实施成本（含差旅）+标品成本 3、人天单价参考（执行时间：2025年7月1日起）： ①产研自有人天（不区分级别）：1750元/天； ②研发外包人员（不区分级别）：890元/天； ③生产外包人员（不区分级别）：320元/天
