Workbook

Sheet 流程指引
A1: 商机-项目关键节点评审管理流程指引
A2: 版本：V1.0 | 生效日期：2026年 月 日 | 编制：李晓 | 审核：CMO/企划办
A4: 一、管理目的与适用范围
A5: 本流程指引旨在规范公司商机-项目全生命周期关键节点的评审管控，覆盖市场营销部、G1和B2业务线。通过建立标准化的评审规则与红黄绿灯分级机制，实现项目风险的前置识别、分级管控与高效决策，确保公司项目质量与经营安全。 适用范围：公司所有商机-项目，涵盖以下四大关键节点：①POC投入 ②售前立项评审 ③投标决策评审 ④项目关键事项决策 评审分级：部门级项目评审会（常规项目）→ XO级项目评审会（重大/高风险项目）。触发XO级评审的场景详见各环节具体规则。
A7: 二、红黄绿灯分级评审机制
A8: 绿灯（免上会） | C8: 所有评审指标均满足"免上会"标准 → 项目无需上会评审，智能体评审为绿灯后即可通过，直接推进至下一阶段。市场营销支持处留档备查。
A9: 黄灯（上会决策） | C9: 存在一项或多项指标触发"上会决策"标准 → 项目需提交至线下评审会进行决策。会议分级：部门级评审会（常规黄灯项目）或XO级评审会（触发XO级升级条件的项目）。
A10: 红灯（红线禁止） | C10: 存在任一指标触发"红线禁止"标准 → 项目打回，要求销售/项目经理与客户重新协商调整后再次提交评审。红线项不可豁免。
A12: 三、各环节评审流程详述
A14: 3.1 项目POC投入（邮件审批）
B15: 事项 | C15: 申请人 | D15: 审批方式 | E15: 审批人 | F15: 审批要点 | G15: 分级 | H15: 使用模板 | I15: 后续动作 | J15: 备注
B16: 项目POC投入 | C16: 销售经理 | D16: 邮件审批 | E16: 区域交付负责人 | F16: 销售经理发送邮件申请，由区域交付负责人评估交付资源情况，确认资源OK后安排交付。 | G16: 无分级 （不纳入红黄绿灯机制） | H16: 《POC投入申请表》 | I16: 交付完成后归档 | J16: 未在产品POC范围内的售前投入，均需完成售前立项评审
A18: 3.2 售前立项评审（项目评审委员会决策）
A19: 【流程步骤】 Step 1 信息收集：销售经理/项目经理填写《售前立项评审-信息收集与前置评审表》的"项目基础信息"及"可由销售经理/项目经理判断的规则指标"，提交至销售支持组。 Step 2 前置评审：销售支持组 分发至各业务/职能部门（交付负责人、业财、采购经理、法务、公共事务等），各部门在规定时间内完成各自负责指标的核实与风险判定，针对无法量化指标需填写前置评审意见及红黄绿灯等级。 Step 3 风险评定：销售支持组汇总前置评审意见表，并使用评审智能体进行项目风险评定，输出项目灯态和风险报告（红、黄灯需输出）。 Step 4 分类处理： · 绿灯项目 → 免上会，邮件输出智能体评审结论并留档备查，项目推进至下一阶段。 · 红灯项目 → 打回，销售经理与客户重新协商，调整后可再次提交。 · 黄灯项目 → 进入线下评审会，根据触发条件确定会议级别（部门级/XO级）。 Step 5 评审决策：评审会输出决策结果，销售支持组/企划办归档并跟踪后续执行。
B20: 申请人 | C20: 协同人 | D20: 使用模板 | E20: 前置评审成员 | F20: 部门级决策机制 | G20: XO级决策机制 | H20: 部门级提报机制 | I20: XO级提报机制 | J20: 评审后续
B21: 销售经理 | C21: 项目经理、解决方案 | D21: 《售前立项评审-信息收集与前置评审表》 《项目贡献毛利率及成本预算表》 | E21: 交付负责人、产研负责人、财务BP、采购BP、法务、公共事务等 | F21: 决策方式：部门级项目评审会 会议周期：每周二 主述人：销售经理 决策人：部门级项目评审委员会 主办组织：销售支持组 | G21: 决策方式：XO级项目评审会 会议周期：每周五 主述人：销售经理 决策人：XO级项目评审委员会 主办组织：企划办 | H21: 提报路径：销售经理→销售支持组 部门级时间要求： ①提前1周进行项目提报 ②提前2个工作日完成材料提交，材料提交前可自行通过智能体判断项目灯态 ③每周一销售支持组汇总智能体项目灯态，绿灯项目免上会，红灯项目驳回，黄灯项目注意项目关键风险点评审会决策，并邮件发出 | I21: 提报路径：销售经理→销售支持组 时间要求：提前完成部门级评审会 | J21: 评审通过后，由项目经理发起PMS项目建立申请，将评审决策文件、项目贡献毛利率及成本预算表（初算）作为审批附件上传；由交付负责人审批通过
A23: 3.3 投标决策评审（项目评审委员会决策）
A24: 【流程步骤】 Step 1 信息收集：销售经理填写《投标决策评审-信息收集与前置评审表》的"项目基础信息"及"可由销售经理判断的规则指标"，提交至销售支持组。 Step 2 前置评审：销售支持组 分发至各业务/职能部门（交付负责人、业财、采购经理、法务、公共事务等），各部门在规定时间内完成各自负责指标的核实与风险判定，针对无法量化指标需填写前置评审意见及红黄绿灯等级。 Step 3 风险评定：销售支持组汇总前置评审意见表，并使用评审智能体进行项目风险评定，输出项目灯态和风险报告（红、黄灯需输出）。 Step 4 分类处理： · 绿灯项目 → 免上会，邮件输出智能体评审结论并留档备查，项目推进至下一阶段。 · 红灯项目 → 打回，销售经理与客户重新协商，调整后可再次提交。 · 黄灯项目 → 进入线下评审会，根据触发条件确定会议级别（部门级/XO级）。 Step 5 评审决策：评审会输出决策结果，销售支持组/企划办归档并跟踪后续执行。
B25: 申请人 | C25: 协同人 | D25: 使用模板 | E25: 前置评审成员 | F25: 部门级决策机制 | G25: XO级决策机制 | H25: 部门级提报机制 | I25: XO级提报机制 | J25: 评审后续
B26: 销售经理 | C26: 项目经理、解决方案 | D26: 《投标决策评审-信息收集与前置评审表》 《项目贡献毛利率及成本预算表》 | E26: 交付负责人、产研负责人、财务BP、采购BP、法务、公共事务等 | F26: 决策方式：部门级项目评审会 会议周期：每周二 主述人：销售经理 决策人：部门级项目评审委员会 主办组织：销售支持组 | G26: 决策方式：XO级项目评审会 会议周期：每周五 主述人：销售经理 决策人：XO级项目评审委员会 主办组织：企划办 | H26: 提报路径：销售经理→销售支持组 部门级时间要求： ①提前1周进行项目提报 ②提前2个工作日完成材料提交，材料提交前可自行通过智能体判断项目灯态 ③每周一销售支持组汇总智能体项目灯态，绿灯项目免上会，红灯项目驳回，黄灯项目注意项目关键风险点评审会决策，并邮件发出 | I26: 提报路径：销售经理→销售支持组 时间要求：提前完成部门级评审会 | J26: 评审通过后，由项目经理发起PMS项目建立申请，将评审决策文件、项目贡献毛利率及成本预算表（概算）作为审批附件上传；由交付负责人审批通过。 评审不通过且前期已有预投入，需项目经理进行PMS项目关闭，通知项目组成员在3个工作日内完成收尾。
A28: 3.4 项目关键事项决策（项目评审委员会决策）
A29: 【流程步骤】 Step 1 信息收集：项目经理填写《项目关键事项决策-信息收集与前置评审表》的"项目基础信息"及"可由项目经理判断的规则指标"，提交至销售支持组。 Step 2 前置评审：销售支持组 分发至各业务/职能部门（交付负责人、业财、采购经理、法务、公共事务等），各部门在规定时间内完成各自负责指标的核实与风险判定，针对无法量化指标需填写前置评审意见及红黄绿灯等级。 Step 3 风险评定：销售支持组汇总前置评审意见表，并使用评审智能体进行项目风险评定，输出项目灯态和风险报告（红、黄灯需输出）。 Step 4 分类处理： · 绿灯项目 → 免上会，邮件输出智能体评审结论并留档备查，项目推进至下一阶段。 · 红灯项目 → 打回，销售经理与客户重新协商，调整后可再次提交。 · 黄灯项目 → 进入线下评审会，根据触发条件确定会议级别（部门级/XO级）。 Step 5 评审决策：评审会输出决策结果，销售支持组/企划办归档并跟踪后续执行。
B30: 申请人 | C30: 协同人 | D30: 使用模板 | E30: 前置评审成员 | F30: 部门级决策机制 | G30: XO级决策机制 | H30: 部门级提报机制 | I30: XO级提报机制 | J30: 评审后续
B31: 项目经理 | C31: 销售经理 | D31: 《项目关键事项决策-信息收集与前置评审表》 《项目贡献毛利率及成本预算表》 《项目变更申请表》（如涉及变更） | E31: 区域交付负责人、项目管理部负责人、业财、采购经理（如有） | F31: 决策方式：部门级项目评审会 会议周期：每周二 主述人：项目经理 决策人：部门级项目评审委员会 主办组织：项目管理部 | G31: 决策方式：XO级项目评审会 会议周期：每周五 主述人：项目管理部负责人 决策人：XO级项目评审委员会 主办组织：企划办 | H31: 提报路径：项目经理→销售支持组 时间要求： ①提前5个工作日进行提报 ②提前2个工作日完成材料提交 ③每周一销售支持组汇总智能体项目灯态，绿灯项目免上会，红灯项目驳回，黄灯项目注意项目关键风险点评审会决策，并邮件发出 | I31: 提报路径：项目经理→销售支持组 时间要求： 提前完成部门级评审会 | J31: 评审通过后，由项目经理发起PMS项目变更申请（如涉及变更），将评审决策文件、项目贡献毛利率及成本预算表（变更版）作为审批附件上传；由交付负责人审批通过。
A33: 四、触发XO级评审会的场景（部门级 → XO级升级条件）
A34: 序号 | B34: 触发场景 | H34: 升级级别
A35: 1 | B35: 项目运维周期：大于3年 | H35: XO级
A36: 2 | B36: 存在指定供应商 | H36: XO级
A37: 3 | B37: 部门级评审意见未达成一致 | H37: XO级
A38: 4 | B38: 毛利维度：项目贡献毛利率＜0% | H38: XO级
A39: 5 | B39: 合同金额：大于500万 | H39: XO级
A40: 6 | B40: 提前投入大于50万 | H40: XO级
A41: 7 | B41: 过单项目（分包比例大于70%） | H41: XO级
A42: 8 | B42: 项目合同存在提供担保或为他人提供担保 | H42: XO级
A43: 9 | B43: 项目合同存在竞业等事项 | H43: XO级
A44: 10 | B44: 存在项目推广激励（to对外，比例≥15%或金额≥30w） | H44: XO级
A45: 11 | B45: 存在项目推广激励（to顺丰体系内、激励制度规则条款外） | H45: XO级
A48: 五、关键角色与职责
A49: 序号 | B49: 角色 | D49: 职责说明
A50: 1 | B50: 销售经理 | D50: 售前立项/投标决策的发起人，负责填写项目基础信息及可判断的指标，与客户协商调整红灯事项
...

Sheet 售前立项评审-信息收集与前置评审
A1: 售前立项评审 — 信息收集与前置评审表
A3: Part A：项目基础信息（由申请人填写）
A4: 商机名称 | G4: 商机代码
A5: 最终客户名称 | G5: 商机阶段
A6: 业务线 | D6: G1 / B2 / G2（请选择） | G6: 营销区域 | I6: 请选择
A7: 预计合同金额（万元） | G7: 预计签单时间
A8: 销售经理 | G8: 项目经理
A9: 项目概述
A10: 是否涉及测绘（涉及外业采集或地图） | D10: 是 / 否（请选择） | G10: 是否涉及分包提前进场 | I10: 是 / 否（请选择）
A11: 预计售前投入成本（万元） | G11: 预计售前实施周期
A13: Part B：非量化类关键评审指标-前置评审
A14: 序号 | B14: 评审维度 （部门） | C14: 评判指标 | D14: 辅助指标/说明 | E14: 绿灯标准 （免上会） | F14: 黄灯标准 （上会决策） | H14: 红灯标准 （红线禁止） | I14: 风险等级 （红/黄/绿） | J14: 前置评审意见 | K14: 前置评审人 （签字）
I15: 部门评审↓ | J15: 部门评审↓ | K15: 部门评审↓
A16: 1 | B16: 业务 | C16: 技术可行性 | E16: 无技术风险 | F16: 存在交付侧技术风险，但在客户需求边界/预期交付边界控制的情况下，可完成交付 | H16: 技术侧无法交付，因成本/资质问题无法分包 | K16: FDE工程师
A17: 2 | B17: 业务 | C17: 交付资源风险 | D17: 客户侧要求的售前投入交付节点及周期 | E17: 资源无风险 | F17: 交付实施资源当前周期内存在明确缺口 | K17: FDE工程师
A18: 3 | B18: 合规 | C18: 合同交付物（测绘项目） | D18: 涉及外业采集或地图数据 | E18: 合同交付物无外业采集和地图数据相关内容 | F18: 合同交付物有外业采集和地图数据相关内容 | K18: 合规BP
A19: 4 | B19: 采购 | C19: 存在分包提前投入 | F19: 分包提前介入 | K19: 采购BP
A20: 5 | B20: 财务 | C20: 客户过往合作信誉 | D20: 过往投入转单率 | E20: 无诉讼欠款、无逾期欠款、无沉默的历史交付成本 | F20: 存在逾期欠款 or 存在沉默的历史交付成本 | H20: 存在未完结诉讼（直接+间接） 存在历史坏账 | K20: 财务BP

Sheet 投标决策评审-信息收集与前置评审
A1: 投标决策评审 — 信息收集与前置评审表
A3: Part A：项目基础信息（由申请人填写）
A4: 商机名称 | D4: 江西省天地图POI数据服务项目 | G4: 商机代码 | I4: PL00008572
A5: 商机阶段 | D5: 投标决策 | G5: 营销区域 | I5: 华北营销处-渠道
A6: 业务线 | D6: G1 | G6: 最终客户名称 | I6: 江西省自然资源测绘与监测院
A7: 销售经理 | D7: 王超 | G7: 项目经理 | I7: 冯金华
A8: 预计合同金额（万元） | D8: ='附1-预算表'!B6/10000 -> 24 | G8: 预计签单时间 | I8: 46325
A9: 预计贡献毛利率（%） | D9: ='附1-预算表'!H8 -> 0.055247274 | G9: 项目已发生成本（万元） | I9: 0
A10: 项目运维周期 | D10: 1年 | G10: 是否存在转包限制（客户/客户上游禁止转包） | I10: 否
A11: 项目概述 | D11: 项目建设内容：提供自有的江西省全省范围的POI原始数据，POI数据的字段信息须包括ID、名称、坐标、地址、大类、中类、小类、类型编号。需完全覆盖江西省全省行政区域，包括11个市，100个县区的全量数据，数据量不低于220万，其中江西省的萍乡、南昌、抚州、赣州4个地市需对政府及管理机构、公检法机构、宗教社团、社会福利机构、公共服务、商业服务、住宅设施、科教文卫、休闲度假、风景名胜、企事业单位、交通运输等12类政务兴趣点进行治理提供，其余7个地市按照政府及管理机构、社会福利机构、住宅设施、科教文卫、企事业单位、交通运输6类别进行治理提供。
A12: 签约路径 | D12: 江西省自然资源测绘与监测院→易智瑞信息技术有限公司→航天云际时空信息技术（重庆）有限公司→丰图科技（深圳）有限公司
A13: 是否涉及测绘（涉及外业采集或地图） | D13: 否 | G13: 是否涉及甲导资质 | I13: 否
A14: 是否涉密项目（涉及保密资质，涉密项目请先联系保密办） | D14: 否
A15: 分包总金额（万元） | D15: 0 | G15: 指定类分包金额（万元） | I15: 0
A16: 测绘类分包金额（万元） | D16: 0 | G16: 分包是否涉及公司核心能力 | I16: 否
A17: 项目推广激励面向对象 | D17: 无 | G17: 项目推广激励（万元） | I17: 0
A18: 结算方式 | D18: 银行转账 | G18: 预计回款时间 | I18: 预计26年Q4回款40%，27年Q2回款60%
A19: 付款条件 | D19: 首付款40%，数据交付验收后付60%
A20: 合同背靠背场景 | D20: 回款+验收=全部背靠背 | G20: 确收方式及预估确收时间 | I20: 一次性确收，预计在27年Q1确收
A21: 合同是否存在提供担保或为他人提供担保 | D21: 否 | G21: 合同是否存在竞业条款 | I21: 否
A22: 合同是否有转包限制 | D22: 否 | G22: 项目是否涉及硬件所有权归属 | I22: 不涉及
A23: 是否涉及SF小哥相关业务 | D23: 否 | G23: 是否涉及数据跨境传输或红线禁止数据 | I23: 否
A24: 项目所在地省份 | D24: 江西省 | G24: 产品售卖类型 | I24: 非标品
A25: B2业务类型 | D25: 请选择 | G25: 标品售价标准 | I25: 不涉及标品
A26: 是否涉及数据评审 | D26: 是
A27: 预期实现方式 | D27: 提供江西全省的POI数据，对其中的4个地市的POI的分类按照天地图的12大类进行映射，对剩余7个地市的分类按天地图的6大类进行映射。只提供POI的名称、地址、坐标、分类，不涉及运单数据或其它敏感数据。
A28: 数据交付字段/内容 | D28: 数据名称：POI数据； 数据字段：唯一ID、名称、坐标、地址、大类、中类、小类、类型编号； 数据范围：江西省； 时间要求：POI数据的更新时间要求是签订合同的前一季度的数据。
A29: 数据合规性审查内容 | D29: 输出全市POI数据，只需提供唯一ID、名称、坐标、地址、大类、中类、小类、类型编号这几个字段，不涉及提供原始数据或涉密数据。
A31: Part B：非量化类关键评审指标-前置评审
A32: 序号 | B32: 评审维度 （部门） | C32: 评判指标 | D32: 辅助指标/说明 | E32: 绿灯标准 （免上会） | F32: 黄灯标准 （上会决策） | H32: 红灯标准 （红线禁止） | I32: 风险等级 （红/黄/绿） | J32: 前置评审意见 | K32: 前置评审人 （签字）
I33: 部门评审↓ | J33: 部门评审↓ | K33: 部门评审↓
A34: 1 | B34: 业务/采购 | C34: 分包合理性 | D34: 分包能力是否核心能力、是否指定性、付款条款不合理、下游分包方资质 | E34: 非公司核心能力分包，且非指定性分包、测绘类项目下游分包方有测绘资质、付款条款为背靠背、供应商资质合格 | F34: 公司核心能力被分包（指定性分包需上XO级）、付款条款不为背靠背、测绘类项目下游供应商无测绘资质、供应商资质不合格等 | I34: 绿灯 | J34: 项目无分包 | K34: 采购BP/FDE
A35: 2 | B35: 业务 | C35: 技术可行性 | E35: 无技术风险 | F35: 存在交付侧技术风险，但在客户需求边界/预期交付边界控制情况下可完成交付 | H35: 技术侧无法交付，因成本/资质问题无法分包 | I35: 绿灯 | J35: 同意 | K35: FDE工程师
A36: 3 | B36: 财务 | C36: 客户历史欠款 | D36: 逾期天数/逾期金额 | E36: 无；或存在终验款和质保金逾期，销售愿意背书在90天内拿回终验款 | F36: 其他逾期款情况 | I36: 绿灯 | J36: 客户无欠款 | K36: 财务BP
A37: 4 | B37: 财务 | C37: 签约客户/最终客户信用评估 | D37: 客户评级制度、工商公开信息等 | E37: 政府/央企/国有企业等优质客户 非国有小微企业满足：成立≥5年、人员≥10、近三月有中标、法人无失信、无诉讼 | F37: "皮包公司"或财政和资金状况较差 | H37: 黑名单客户 | I37: 绿灯 | K37: 财务BP
A38: 5 | B38: 财务 | C38: 集团公司关联交易金额 | D38: 年度关联交易预算金额 | E38: 累计关联交易预算金额≤100w | F38: 累计关联交易预算金额＞100w | I38: 绿灯 | K38: 财务BP
A39: 6 | B39: 财务 | C39: 付款条件 | E39: 1、明确有预付款条款，且约定具体付款期间 2、硬件销售部分100%预付 3、软件销售部分100%预付或**%预付，验收后10日内支付剩余 | F39: 1、无预付条款，或无约定具体付款期间 2、硬件销售部分非100%预付，但无垫资（供应商承担） 3、软件销售部分不满足免上会条件，且非背靠背 | H39: 1、硬件销售部分非100%预付，存在垫资 2、软件销售部分为背靠背 | I39: 绿灯 | J39: 1、毛利风险较低：贡毛＞0%，高于基准线； 2、回款风险较低：政府转包项目，总集（易智瑞信息技术有限公司），丰图为第3包，江西省自然资源测绘与监测院为首次合作； 3、售前投入：截止到2026年8月31日，无交付投入； 4、确收方式：终验确收； 5、回款条件：首付款40%，数据交付验收60%（预计26年回40%） | K39: 财务BP
A40: 7 | B40: 法务 | C40: 上游签约路径公司情况 | D40: 异常经营记录、营业执照、失信名单、与丰图之间是否存在诉讼、被执行记录、行政处罚记录 | E40: 1、无异常记录 2、与丰图无诉讼案件；或诉讼中丰图为第三人，不涉及义务承担 3、无被执行记录；或已执行完毕且与项目无关 4、无处罚记录；或非近三年已履行完毕且与项目无关 | F40: 1、与丰图有诉讼案件，但丰图为第三人涉及义务承担、已判决/和解但款项未完全支付、或已完结 2、有执行纪录，近三年已执行完毕，与项目相关或涉及金钱给付 3、有行政处罚纪录，但近三年已履行完毕且与项目无关或不涉及资质处罚 | H40: 1、存在异常经营记录；营业执照被吊销；列入失信名单；被提起破产清算等 2、与丰图有诉讼案件，且丰图作为原告/被告，未开庭/未和解 3、有执行纪录，且执行中状态；未履行义务；列入失信被执行人 4、有行政处罚纪录，且未履行完毕；涉及资质处罚 | I40: 绿灯 | J40: 1、截至20260920，上游与丰图之间不存在诉讼； 2、总集易智瑞近期有被执行记录（2026-08-02，111.28万），商务侧反馈客情较好，总体可控，提请商务侧注意把控回款。 | K40: 法务
A41: 8 | B41: 法务 | C41: 转包限制风险 | D41: 客户转包或丰图直签分包限制 | E41: 丰图内部关联交易无需二次评审 | F41: 有背靠背转移风险约定且可转移给供应商 | H41: 背靠背约定但丰图自行交付/供应商无法满足风险转移，违约责任超X万 | I41: 绿灯 | J41: 反馈数据为直接交付至最终客户。 | K41: 法务
A42: 9 | B42: 合规 | C42: 合规风险 | D42: 甲测/甲导资质风险、审图风险、涉密项目资质风险 | E42: 1. 无风险； 2. 已有管控举措。风险可控，不影响丰图资质。 | F42: 1. 风险存在不确定性； 2. 对资质存在明确影响，但不严重，影响范围可接受。 | H42: 对资质存在明确影响，非常严重，影响范围不可接受。 | I42: 绿灯 | J42: 1、不涉及保密资质 2、明确输出哪几个城市POI，给出量级 3、坐标应降低精度提供 4、数据不得涉密、敏感 5、数据输出必须加密，直传最终客户 | K42: 合规
...

Sheet 项目关键事项决策-信息收集与前置评审
A1: 项目关键事项决策 — 信息收集与前置评审表
A3: Part A：项目基础信息（由申请人填写-不涉及可直接留/）
A4: 项目名称 | G4: 项目代码
A5: 销售经理 | G5: 项目经理
A6: 业务线 | D6: G1 / B2 / G2（请选择） | G6: 营销区域 | I6: 请选择
A7: 最终客户 | G7: 项目阶段 | I7: 请选择
A8: 原合同金额（万元） | G8: 原贡献毛利率（%）
A9: 决策事项类型 | D9: 请选择
A10: 决策事项概述
A11: 涉及 签单与投标决策差异 / 项目成本变动 / 分包变化 时填写
A12: 变更后合同金额（万元） | G12: 变更后贡献毛利率（%）
A13: 原分包金额 | G13: 变更后分包金额
A14: 原交付成本 | G14: 变更后交付成本
A15: 原销售成本 | G15: 变更后销售成本
A16: 是否涉及分包合同超进度支付 | D16: 是 / 否（如有，请说明情况）
A17: 是否涉及签约路径变化 | D17: 是 / 否（如有，请说明情况）
A18: 是否涉及交付内容变化 | D18: 是 / 否（如有，请说明情况）
A20: Part B：非量化类关键评审指标-前置评审
A21: 序号 | B21: 评审维度 （部门） | C21: 评判指标 | D21: 辅助指标/说明 | E21: 绿灯标准 （免上会） | F21: 黄灯标准 （上会决策） | H21: 红灯标准 （红线禁止） | I21: 风险等级 （红/黄/绿） | J21: 前置评审意见 | K21: 前置评审人 （签字）
I22: 部门评审↓ | J22: 部门评审↓ | K22: 部门评审↓
A23: 1 | B23: 业务 | C23: 技术可行性 | E23: 无技术风险 | F23: 存在交付侧技术风险，但在客户需求边界/预期交付边界控制情况下可完成交付 | H23: 技术侧无法交付，因成本/资质问题无法分包 | K23: FDE工程师
A24: 2 | B24: 业务/采购 | C24: 分包合理性 | D24: 分包能力是否核心能力、是否指定性、付款条款不合理、下游分包方资质 | E24: 非公司核心能力分包，且非指定性分包、测绘类项目下游分包方有测绘资质、付款条款为背靠背、供应商资质合格 | F24: 公司核心能力被分包（指定性分包需上XO级）、付款条款不为背靠背、测绘类项目下游供应商无测绘资质、供应商资质不合格等 | K24: 采购BP/FDE
A25: 3 | B25: 财务/法务 | C25: 签单与评审的签约差异 | E25: 签约路径/客户变化但无风险 | F25: 签约路径/客户变化且有风险 | K25: 财务BP/法务
A26: 4 | B26: 财务 | C26: 项目核减 | E26: 因交付内容减少、考核扣分等合理原因导致的审计核减 | F26: 因化债导致的合同金额核减 因非合理原因导致的核减 | K26: 财务BP

Sheet 附1-预算表
A1: 江西省天地图POI数据服务项目-预算表（项目经理提供数据； 单位：元）
A2: 所属部门 | B2: 泛政业务一部 | C2: 项目名称（内部） | D2: 江西省天地图POI数据服务项目 | E2: 商务经理 | F2: 王超 | G2: 项目经理 | H2: 冯金华 | I2: 渠道调节系数 | J2: 1
A3: 所属营销大区 | B3: 华北营销处 | C3: 客户名称 | D3: 江西省自然资源测绘与监测院 | E3: 商机代码 | F3: PL00008572 | G3: 项目代码 | H3: / | I3: 预计签单时间 | J3: 46325
A4: 预计开始时间 | B4: 46325 | C4: 预计终验时间 | D4: 46476 | E4: 运维周期（质保期） | F4: 1年 | G4: 项目阶段 | H4: 投标决策 | I4: 项目难度系数 | J4: 1
A5: 成本测算 | B5: 合同金额 | D5: 项目收入 | E5: 分包采购成本 | F5: 软件类生产外包 | G5: 项目净收入 | H5: 交付成本 （含数据类生产外包） | I5: 标品成本
B6: 240000 | D6: =B6/(1+6%) -> 226415.09 | E6: =G10 -> 0 | F6: =G11 -> 0 | G6: =D6-(E6+F6)/1.06-B8 -> 226415.09 | H6: =SUM(G19:G28) -> 146896 | I6: ='附3-交付成本评估'!CK2 -> 0
A7: 毛利/率测算 | B7: 灵活用工 | D7: 销售成本 （含税金，不含激励） | E7: 销售考核利润 （含税金，不含激励） | F7: 销售考核毛利率 | G7: 贡献毛利 （已扣除激励） | H7: 贡献毛利率 | I7: 交付成本占净收入比 （与决算偏差±10%以内） | J7: 销售总成本占净收入比
B8: =G12 -> 0 | D8: =SUM(G13:G17) -> 53712.151 | E8: =G6-D8 -> 172702.94 | F8: =E8/D6 -> 0.76277133 | G8: =G6-D8-H6-G18 -> 12508.817 | H8: =G8/D6 -> 0.055247274 | I8: =H6/G6 -> 0.64879067 | J8: =SUM(G13:G18)/G6 -> 0.29596206
A9: 序号 | B9: 成本大类 | D9: 成本小类 | E9: 计算逻辑说明 | G9: 成本小计 | H9: 成本占项目收入比 | I9: 成本评估备注
A10: 1 | B10: 分成分包 | D10: / | E10: 1、项目集成分包、项目日常运维分包费用 2、定制化软件开发的分包费用 3、技术服务费 | G10: 0 | H10: =G10/1.06/$D$6 -> 0 | I10: /
B11: 软件类生产外包 | D11: / | E11: 软件类生产相关的内、外业人员的生产外包人力成本 | G11: ='附3-交付成本评估'!BF2+'附3-交付成本评估'!BL2+'附3-交付成本评估'!CB2+'附3-交付成本评估'!CH2 -> 0 | H11: =G11/$D$6 -> 0 | I11: 丰图产品不具备交付能力但是从项目层面需要进行包装整合。比如三维建模，BIM数据生产。
B12: 灵活用工 | D12: / | E12: 小创云等灵活用工平台的费用预算 | G12: 0 | H12: =G12/$D$6 -> 0 | I12: 从净收入中剔除，即【净收入=收入-分包-软件类生产外包-灵活用工】
A13: 2 | B13: 销售成本 | C13: 人力成本 | D13: 自有人员 | E13: 自有市场营销部人员成本（含销售、解决方案、CMO办公室、招投标组人力成本） | G13: =(B6-E6)/10000*1727 -> 41448 | H13: =G13/$D$6 -> 0.183062 | I13: 按财务最新发布，26年销售人力标准成本=净签单/万*1727元。 示例：某项目合同总额500万，分包300万，26年销售人力标准成本=（500-300）*1727=345400元。
C14: 销售费用包 | D14: 差旅费 | E14: 项目客户拜访等发生的差旅（需包含解决方案成本） | G14: 5000 | H14: =G14/$D$6 -> 0.022083333
D15: 招待费 | E15: 项目客户拜访等发生的招待费用（需包含解决方案成本） | G15: 5000 | H15: =G15/$D$6 -> 0.022083333
D16: 市场营销 | E16: 市场营销费用、投标阶段的专家费等 | H16: =G16/$D$6 -> 0
D17: 税金 | E17: 税后收入*1％（已设置公式，自动计算） | G17: =D6*1% -> 2264.1509 | H17: =G17/$D$6 -> 0.01
D18: 销售及售前激励 | E18: 销售考核利润（不含激励）*7.7%（包含销售与售前的激励） （已设置公式，自动计算） | G18: =E8*7.7% -> 13298.127 | H18: =G18/$D$6 -> 0.058733393 | I18: *部分银行项目销售及售前激励=销售考核利润（不含激励）*5.7%*0.4
A19: 3 | B19: 交付成本 | C19: 人力成本 | D19: 自有人员 | E19: 1、用于本项目交付实施的技术架构、研发、产品经理、交付运营、测试、运维等自有员工成本（需包含项目运维成本） | G19: ='附3-交付成本评估'!P2+'附3-交付成本评估'!BW2 -> 66144 | H19: =G19/$D$6 -> 0.292136 | I19: 1）泛政业务一部26年标准成本： ①自有人天-交付处：1,696元/天 ②自有人天-行业拓展处：2303元/天 2）企业服务发展部26年标准成本： ①自有人天-公共服务业务处：2204元/天 ②自有人天-行业售前方案处：2350元/天 ③自有人天-企业产品研发处：3001元/天 3）基础平台产品部26年标准成本： ①自有人天-数据产品处：1720元/天 ②自有人天-智能地图处：1752元/天 ③自有人天-公共组件处：1374元/天 | K19: =G19/1696 -> 39
D20: 研发外包 | E20: 1、用于本项目交付实施的项目助理、研发、产品经理、交付运营、测试、运维等外包员工成本 | H20: =G20/$D$6 -> 0 | I20: 1）泛政业务一部26年标准成本： ①研发外包：995元/天； 2）企业服务发展部26年标准成本： ①研发外包：1,022元/人天；
C21: 生产人员成本 | D21: 数据类生产外包 | E21: 数据类生产相关的内、外业人员的生产外包人力成本 | G21: ='附3-交付成本评估'!BD2+'附3-交付成本评估'!BK2+'附3-交付成本评估'!BZ2+'附3-交付成本评估'!CG2 -> 58880 | H21: =G21/$D$6 -> 0.26005333 | I21: 丰图产品具备交付能力只是用了生产资源来执行交付。比如地址治理，地图生产，数据服务交付运营等
C22: 差旅招待 | D22: 差旅费 | E22: 项目实施人员出差的长途交通费+补助+住宿费（酒店、租房、物业水电费） | G22: ='附3-交付成本评估'!BJ2+'附3-交付成本评估'!CF2 -> 3000 | H22: =G22/$D$6 -> 0.01325
C23: 项目管理费 | D23: 自有人员 | E23: 项目经理自有人员人力成本 | G23: ='附3-交付成本评估'!X2+'附3-交付成本评估'!BT2 -> 11872 | H23: =G23/$D$6 -> 0.052434667 | I23: 建设期投入5天,1年运维期投入2天
D24: 差旅、市内交通 | E24: 差旅、市内交通 | G24: 5000 | H24: =G24/$D$6 -> 0.022083333 | I24: 预留2次出差，一次2500元
D25: 招待费 | E25: 关键里程碑、验收推动招待费用 | G25: 1000 | H25: =G25/$D$6 -> 0.0044166667
D26: 项目验收 | E26: 项目技术评审专家费等 | H26: =G26/$D$6 -> 0
D27: 综合办公 | E27: 项目资料打印、资料邮寄、设备邮寄相关的快递费；项目实施需要采购的办公耗材，如插线板、路由器等；办公资产采购等 | G27: 1000 | H27: =G27/$D$6 -> 0.0044166667
D28: 专业服务 | E28: 审计律师费用、顾问费用、其它咨询费用 | H28: =G28/$D$6 -> 0
A29: 制表人： | E29: 复核人：
A30: 填写说明：标黄的部分为需人工填写，白色区域有公式带出对应数值。

Sheet 附3-交付成本评估
A1: 项目名称：江西省天地图POI数据服务项目
A2: 合计值 | J2: =SUM(J5:J15) -> 0 | K2: =SUM(K5:K15) -> 0 | L2: =SUM(L5:L15) -> 0 | M2: =SUM(M5:M15) -> 0 | N2: =SUM(N5:N15) -> 133504 | O2: =SUM(O5:O15) -> 8480 | P2: =SUM(P5:P15) -> 66144 | Q2: =SUM(Q5:Q15) -> 0 | ... BL2: =SUM(BL5:BL15) -> 0 | BN2: =SUM(BN5:BN15) -> 0 | BO2: =SUM(BO5:BO15) -> 0 | BP2: =SUM(BP5:BP15) -> 0 | BQ2: =SUM(BQ5:BQ15) -> 0 | BR2: =SUM(BR5:BR15) -> 3392 | BS2: =SUM(BS5:BS15) -> 2 | BT2: =SUM(BT5:BT15) -> 3392 | BU2: =SUM(BU5:BU15) -> 0 | ... CH2: =SUM(CH5:CH15) -> 0 | CJ2: =SUM(CJ5:CJ15) -> 0 | CK2: =SUM(CK5:CK15) -> 0
A3: 序号 | B3: 解决方案评估 | I3: 标品研发负责人评估 | J3: 1.0 实施阶段- 销售成本 | N3: 1.1 实施阶段- 交付人力成本 | W3: ① 项目经理： | Y3: ② 产品售前岗： | AC3: ③ 产 品 岗： | AG3: ④ 前 端 岗： | AK3: ⑤ 后 端 岗： | AO3: ⑥ 大数据开发岗： | AS3: ⑦ 交 付 岗： | AW3: ⑧ 架 构： | AY3: ⑨ 其他：测试、UI、实施中运维投入 | BC3: ⑩ 生产外包-数据类： | BE3: ⑪ 生产外包-软件类： | BG3: 1.2 实施阶段- 交付差旅招待 | BM3: ★工作量评估负责人 （可补充说明成本评估备注） | BN3: 2.0 运维阶段- 销售成本 | BR3: 2.1 运维阶段-人力成本： | BS3: ① 项 目 经 理： | BU3: ② 产 研 投 入： | BY3: ③ 生产外包-数据类： | CA3: ④ 生产外包-软件类： | CC3: 2.2 运维阶段-差旅成本 | CI3: 按岗位人员投入人数说明 | CJ3: 标品
B4: 建设内容 | C4: 对应标准产品名称 （下拉选择） | D4: 建设内容-细分模块 | E4: 具体功能项 | F4: 功能描述 | G4: 最终交付物 | H4: 交付方式 | I4: 是否标品交付 | J4: 销售-人力成本 | K4: 销售-差旅 | L4: 销售-招待费 | M4: 销售-市场营销 | N4: 实施阶段- 人力成本总额 | O4: ① 实施阶段- 人力成本总额 （项目经理） | P4: ② 实施阶段- 人力成本总额 （产研正编） | Q4: ③ 实施阶段- 人力成本总额 （产研外包） | R4: ④ 实施阶段- 人力成本总额 （生产外包） | S4: 实施阶段- 人天汇总 （项目经理） | T4: 实施阶段- 人天汇总 （产研正编） | U4: 实施阶段- 人天汇总 （产研外包） | V4: 实施阶段- 人天汇总 （生产外包） | W4: 项目经理 正编人天 | X4: 项目经理 正编金额 | Y4: 产品售前 正编人天 | Z4: 产品售前 外包人天 | AA4: 产品售前 正编金额 | AB4: 产品售前 外包金额 | AC4: 产品 正编人天 | AD4: 产品 外包人天 | AE4: 产品 正编金额 | AF4: 产品 外包金额 | AG4: 前端 正编人天 | AH4: 前端 外包人天 | AI4: 前端 正编金额 | AJ4: 前端 外包金额 | AK4: 后端 正编人天 | AL4: 后端 外包人天 | AM4: 后端 正编金额 | AN4: 后端 外包金额 | AO4: 大数据开发 正编人天 | AP4: 大数据开发 外包人天 | AQ4: 大数据开发 正编金额 | AR4: 大数据开发 外包金额 | AS4: 交付 正编人天 | AT4: 交付 外包人天 | AU4: 交付 正编金额 | AV4: 交付 外包金额 | AW4: 架构 正编人天 | AX4: 架构 正编金额 | AY4: 其他 正编人天 | AZ4: 其他 外包人天 | BA4: 其他 正编金额 | BB4: 其他 外包金额 | BC4: 生产外包 人天 | BD4: 生产外包 金额 | BE4: 生产外包 人天 | BF4: 生产外包 金额 | BG4: 实施阶段- 差旅成本总额 | BH4: 实施阶段-差旅成本 项目经理-差旅、市内交通 | BI4: 实施阶段-差旅成本 项目经理-招待费 | BJ4: 实施阶段-差旅成本 产研（正编+外包） | BK4: 实施阶段-差旅成本 生产外包（数据类） | BL4: 实施阶段-差旅成本 生产外包（软件类） | BN4: 销售-人力成本 | BO4: 销售-差旅 | BP4: 销售-招待费 | BQ4: 销售-市场营销 | BR4: 运维阶段- 人力成本总额 | BS4: 项目经理 正编人天 | BT4: 项目经理 正编金额 | BU4: 产研 正编人天 | BV4: 产研 外包人天 | BW4: 产研 正编金额 | BX4: 产研 外包金额 | BY4: 生产外包 人天 | BZ4: 生产外包 金额 | CA4: 生产外包 人天 | CB4: 生产外包 金额 | CC4: 运维阶段- 差旅成本总额 | CD4: 运维阶段-差旅成本 项目经理-差旅、市内交通 | CE4: 运维阶段-差旅成本 项目经理-招待费 | CF4: 运维阶段-差旅成本 产研（正编+外包） | CG4: 运维阶段-差旅成本 生产外包（数据类） | CH4: 运维阶段-差旅成本 生产外包（软件类） | CJ4: 人天 | CK4: 金额 | CL4: 标品成本评估-说明
A5: 1 | C5: 数据服务 | D5: 南昌市POI数据 | E5: 提供全市范围政务兴趣点（12类）： （1）政府及管理机构：包括各级人民政府、行政服务中心、街道办事处、乡镇政府、各类行政主管部门等，对应机构所在公开门址、楼址； （2）公检法机构：包括各级人民法院、人民检察院、公安局、派出所、看守所、拘留所等，对应机构所在公开门址、楼址； （3）宗教社团：包括各类宗教活动场所（寺庙、教堂等）、宗教团体办公机构，对应机构所在公开门址、楼址； （4）社会福利：包括养老院、福利院、救助站、残疾人服务中心、殡葬服务机构等，对应机构所在公开门址、楼址； （5）公共服务：包括政务服务大厅、公共厕所、垃圾转运站、社区服务中心、供热供水供电服务网点等，对应服务网点公开的门址、楼址； （6）商业服务：包括商场、大型超市、酒店、加油站、银行网点、快递网点等，对应经营场所公开的门址、楼址； （7）住宅设施：包括小区、公寓、别墅、保障性住房等，对应小区门址、住宅楼址； （8）科教文卫：包括幼儿园、小学、中学、高校、科研院所、图书馆、文化馆、医院、疾控中心、体育馆等，对应机构的公开门址、楼址； （9）休闲度假：包括公园、广场、游乐园、度假村、露营地等，对应单位公开的门址、楼址； （10）风景名胜：包括A级景区、历史遗迹、文物保护单位、自然景观景点等，对应景区公开的门址、地址； （11）企事业单位：包括各类国有企业、民营企业、外资企业、事业单位（非科教文卫类）、社会组织等，对应企事业单位的公开注册地址； （12）交通运输：包括火车站、汽车站、机场、码头、大型停车场、公路养护站等，对应交通运输设施的公开门址、地址。 | F5: （1）交付内容 数据字段包括：名称、类型、坐标、地址。 （2）交付指标 政务兴趣点的名称、类型、地址等信息与实际一致，政务兴趣点坐标偏差≤±10米，整体准确率达到90%以上（其中院落、单位等大型兴趣点以不超出边界为准）。 政务兴趣点的门址、楼址标准化率≥90%，正确率≥90%。 政务兴趣点标准化的门址、楼址的四级行政区完整率95%以上。 交付的数据之间重复率不超过5%。 （3）坐标系 成果数据平面基准采用2000国家大地坐标系。 （4）数据格式 GIS矢量格式（如SHP、GDB）。 （4）数据时效性 一次性交付，数据时效性要求为合同签订时间的上一个季度，需与官方最新调整信息保持一致。 | G5: 数据 | H5: 一次性交付 | N5: =O5+P5+Q5+R5 -> 133504 | O5: =X5 -> 8480 | P5: =AA5+AE5+AI5+AM5+AQ5+AU5+AX5+BA5 -> 66144 | Q5: =AB5+AF5+AJ5+AN5+AR5+AV5+BB5 -> 0 | R5: =BD5+BF5 -> 58880 | S5: =W5 -> 5 | T5: =Y5+AC5+AG5+AK5+AO5+AS5+AW5+AY5 -> 39 | U5: =Z5+AD5+AH5+AL5+AP5+AT5+AZ5 -> 0 | V5: =BC5+BE5 -> 184 | W5: 5 | X5: =W5*1696 -> 8480 | AB5: =Z5*995 -> 0 | AF5: =AD5*995 -> 0 | AJ5: =AH5*995 -> 0 | AM5: =AK5*1696 -> 0 | AN5: =AL5*995 -> 0 | AR5: =AP5*995 -> 0 | AS5: 39 | AU5: =AS5*1696 -> 66144 | AV5: =AT5*995 -> 0 | BA5: =AY5*1696 -> 0 | BB5: =AZ5*995 -> 0 | BC5: 184 | BD5: =BC5*320 -> 58880 | BF5: =BE5*320 -> 0 | BG5: =SUM(BH5:BL5) -> 6000 | BH5: 3000 | BJ5: 3000 | BR5: =SUM(BT5,BW5,BX5,BZ5,CB5) -> 3392 | BS5: 2 | BT5: =BS5*1696 -> 3392 | BX5: =BV5*995 -> 0 | BZ5: =BY5*320 -> 0 | CB5: =CA5*320 -> 0 | CC5: =SUM(CD5:CH5) -> 0 | CI5: 岗位（正编/外包）：人数+对应投入人天 ①产品岗：正编投入_人；外包投入_人 ②前端岗：正编投入_人；外包投入_人 ③后端岗：正编投入_人；外包投入_人 ④大数据开发：正编投入_人；外包投入_人 ⑤交付岗：正编投入_人 ⑥架构岗：正编投入_人；外包投入_人 ⑦其他：正编投入_人；外包投入_人 ...... | CL5: 产品、研发：
A6: 2 | C6: 数据服务 | D6: 萍乡市POI数据 | E6: 提供全市范围政务兴趣点（12类）： （1）政府及管理机构：包括各级人民政府、行政服务中心、街道办事处、乡镇政府、各类行政主管部门等，对应机构所在公开门址、楼址； （2）公检法机构：包括各级人民法院、人民检察院、公安局、派出所、看守所、拘留所等，对应机构所在公开门址、楼址； （3）宗教社团：包括各类宗教活动场所（寺庙、教堂等）、宗教团体办公机构，对应机构所在公开门址、楼址； （4）社会福利：包括养老院、福利院、救助站、残疾人服务中心、殡葬服务机构等，对应机构所在公开门址、楼址； （5）公共服务：包括政务服务大厅、公共厕所、垃圾转运站、社区服务中心、供热供水供电服务网点等，对应服务网点公开的门址、楼址； （6）商业服务：包括商场、大型超市、酒店、加油站、银行网点、快递网点等，对应经营场所公开的门址、楼址； （7）住宅设施：包括小区、公寓、别墅、保障性住房等，对应小区门址、住宅楼址； （8）科教文卫：包括幼儿园、小学、中学、高校、科研院所、图书馆、文化馆、医院、疾控中心、体育馆等，对应机构的公开门址、楼址； （9）休闲度假：包括公园、广场、游乐园、度假村、露营地等，对应单位公开的门址、楼址； （10）风景名胜：包括A级景区、历史遗迹、文物保护单位、自然景观景点等，对应景区公开的门址、地址； （11）企事业单位：包括各类国有企业、民营企业、外资企业、事业单位（非科教文卫类）、社会组织等，对应企事业单位的公开注册地址； （12）交通运输：包括火车站、汽车站、机场、码头、大型停车场、公路养护站等，对应交通运输设施的公开门址、地址。 | G6: 数据 | H6: 一次性交付 | N6: =O6+P6+Q6+R6 -> 0 | O6: =X6 -> 0 | P6: =AA6+AE6+AI6+AM6+AQ6+AU6+AX6+BA6 -> 0 | Q6: =AB6+AF6+AJ6+AN6+AR6+AV6+BB6 -> 0 | R6: =BD6+BF6 -> 0 | S6: =W6 -> 0 | T6: =Y6+AC6+AG6+AK6+AO6+AS6+AW6+AY6 -> 0 | U6: =Z6+AD6+AH6+AL6+AP6+AT6+AZ6 -> 0 | V6: =BC6+BE6 -> 0 | AB6: =Z6*995 -> 0 | AF6: =AD6*995 -> 0 | AJ6: =AH6*995 -> 0 | AM6: =AK6*1696 -> 0 | AN6: =AL6*995 -> 0 | AR6: =AP6*995 -> 0 | AV6: =AT6*995 -> 0 | BA6: =AY6*1696 -> 0 | BB6: =AZ6*995 -> 0 | BD6: =BC6*320 -> 0 | BF6: =BE6*320 -> 0 | BG6: =SUM(BH6:BL6) -> 0 | BR6: =SUM(BT6,BW6,BX6,BZ6,CB6) -> 0 | BX6: =BV6*995 -> 0 | BZ6: =BY6*320 -> 0 | CB6: =CA6*320 -> 0 | CC6: =SUM(CD6:CH6) -> 0
A7: 3 | C7: 数据服务 | D7: 抚州市POI数据 | E7: 提供全市范围政务兴趣点（12类）： （1）政府及管理机构：包括各级人民政府、行政服务中心、街道办事处、乡镇政府、各类行政主管部门等，对应机构所在公开门址、楼址； （2）公检法机构：包括各级人民法院、人民检察院、公安局、派出所、看守所、拘留所等，对应机构所在公开门址、楼址； （3）宗教社团：包括各类宗教活动场所（寺庙、教堂等）、宗教团体办公机构，对应机构所在公开门址、楼址； （4）社会福利：包括养老院、福利院、救助站、残疾人服务中心、殡葬服务机构等，对应机构所在公开门址、楼址； （5）公共服务：包括政务服务大厅、公共厕所、垃圾转运站、社区服务中心、供热供水供电服务网点等，对应服务网点公开的门址、楼址； （6）商业服务：包括商场、大型超市、酒店、加油站、银行网点、快递网点等，对应经营场所公开的门址、楼址； （7）住宅设施：包括小区、公寓、别墅、保障性住房等，对应小区门址、住宅楼址； （8）科教文卫：包括幼儿园、小学、中学、高校、科研院所、图书馆、文化馆、医院、疾控中心、体育馆等，对应机构的公开门址、楼址； （9）休闲度假：包括公园、广场、游乐园、度假村、露营地等，对应单位公开的门址、楼址； （10）风景名胜：包括A级景区、历史遗迹、文物保护单位、自然景观景点等，对应景区公开的门址、地址； （11）企事业单位：包括各类国有企业、民营企业、外资企业、事业单位（非科教文卫类）、社会组织等，对应企事业单位的公开注册地址； （12）交通运输：包括火车站、汽车站、机场、码头、大型停车场、公路养护站等，对应交通运输设施的公开门址、地址。 | G7: 数据 | H7: 一次性交付 | N7: =O7+P7+Q7+R7 -> 0 | O7: =X7 -> 0 | P7: =AA7+AE7+AI7+AM7+AQ7+AU7+AX7+BA7 -> 0 | Q7: =AB7+AF7+AJ7+AN7+AR7+AV7+BB7 -> 0 | R7: =BD7+BF7 -> 0 | S7: =W7 -> 0 | T7: =Y7+AC7+AG7+AK7+AO7+AS7+AW7+AY7 -> 0 | U7: =Z7+AD7+AH7+AL7+AP7+AT7+AZ7 -> 0 | V7: =BC7+BE7 -> 0 | AB7: =Z7*995 -> 0 | AF7: =AD7*995 -> 0 | AJ7: =AH7*995 -> 0 | AM7: =AK7*1696 -> 0 | AN7: =AL7*995 -> 0 | AR7: =AP7*995 -> 0 | AV7: =AT7*995 -> 0 | BA7: =AY7*1696 -> 0 | BB7: =AZ7*995 -> 0 | BD7: =BC7*320 -> 0 | BF7: =BE7*320 -> 0 | BG7: =SUM(BH7:BL7) -> 0 | BR7: =SUM(BT7,BW7,BX7,BZ7,CB7) -> 0 | BX7: =BV7*995 -> 0 | BZ7: =BY7*320 -> 0 | CB7: =CA7*320 -> 0 | CC7: =SUM(CD7:CH7) -> 0
A8: 4 | C8: 数据服务 | D8: 赣州市POI数据 | E8: 提供全市范围政务兴趣点（12类）： （1）政府及管理机构：包括各级人民政府、行政服务中心、街道办事处、乡镇政府、各类行政主管部门等，对应机构所在公开门址、楼址； （2）公检法机构：包括各级人民法院、人民检察院、公安局、派出所、看守所、拘留所等，对应机构所在公开门址、楼址； （3）宗教社团：包括各类宗教活动场所（寺庙、教堂等）、宗教团体办公机构，对应机构所在公开门址、楼址； （4）社会福利：包括养老院、福利院、救助站、残疾人服务中心、殡葬服务机构等，对应机构所在公开门址、楼址； （5）公共服务：包括政务服务大厅、公共厕所、垃圾转运站、社区服务中心、供热供水供电服务网点等，对应服务网点公开的门址、楼址； （6）商业服务：包括商场、大型超市、酒店、加油站、银行网点、快递网点等，对应经营场所公开的门址、楼址； （7）住宅设施：包括小区、公寓、别墅、保障性住房等，对应小区门址、住宅楼址； （8）科教文卫：包括幼儿园、小学、中学、高校、科研院所、图书馆、文化馆、医院、疾控中心、体育馆等，对应机构的公开门址、楼址； （9）休闲度假：包括公园、广场、游乐园、度假村、露营地等，对应单位公开的门址、楼址； （10）风景名胜：包括A级景区、历史遗迹、文物保护单位、自然景观景点等，对应景区公开的门址、地址； （11）企事业单位：包括各类国有企业、民营企业、外资企业、事业单位（非科教文卫类）、社会组织等，对应企事业单位的公开注册地址； （12）交通运输：包括火车站、汽车站、机场、码头、大型停车场、公路养护站等，对应交通运输设施的公开门址、地址。 | G8: 数据 | H8: 一次性交付 | N8: =O8+P8+Q8+R8 -> 0 | O8: =X8 -> 0 | P8: =AA8+AE8+AI8+AM8+AQ8+AU8+AX8+BA8 -> 0 | Q8: =AB8+AF8+AJ8+AN8+AR8+AV8+BB8 -> 0 | R8: =BD8+BF8 -> 0 | S8: =W8 -> 0 | T8: =Y8+AC8+AG8+AK8+AO8+AS8+AW8+AY8 -> 0 | U8: =Z8+AD8+AH8+AL8+AP8+AT8+AZ8 -> 0 | V8: =BC8+BE8 -> 0 | AB8: =Z8*995 -> 0 | AF8: =AD8*995 -> 0 | AJ8: =AH8*995 -> 0 | AM8: =AK8*1696 -> 0 | AN8: =AL8*995 -> 0 | AR8: =AP8*995 -> 0 | AV8: =AT8*995 -> 0 | BA8: =AY8*1696 -> 0 | BB8: =AZ8*995 -> 0 | BD8: =BC8*320 -> 0 | BF8: =BE8*320 -> 0 | BG8: =SUM(BH8:BL8) -> 0 | BR8: =SUM(BT8,BW8,BX8,BZ8,CB8) -> 0 | BX8: =BV8*995 -> 0 | BZ8: =BY8*320 -> 0 | CB8: =CA8*320 -> 0 | CC8: =SUM(CD8:CH8) -> 0
A9: 5 | C9: 数据服务 | D9: 新余市POI数据 | E9: 提供全市范围政务兴趣点（6类）： （1）政府及管理机构：包括各级人民政府、行政服务中心、街道办事处、乡镇政府、各类行政主管部门等，对应机构所在公开门址、楼址； （2）社会福利：包括养老院、福利院、救助站、残疾人服务中心、殡葬服务机构等，对应机构所在公开门址、楼址； （3）住宅设施：包括小区、公寓、别墅、保障性住房等，对应小区门址、住宅楼址； （4）科教文卫：包括幼儿园、小学、中学、高校、科研院所、图书馆、文化馆、医院、疾控中心、体育馆等，对应机构的公开门址、楼址； （5）休闲度假：包括公园、广场、游乐园、度假村、露营地等，对应单位公开的门址、楼址； （6）交通运输：包括火车站、汽车站、机场、码头、大型停车场、公路养护站等，对应交通运输设施的公开门址、地址。 | G9: 数据 | H9: 一次性交付 | N9: =O9+P9+Q9+R9 -> 0 | O9: =X9 -> 0 | P9: =AA9+AE9+AI9+AM9+AQ9+AU9+AX9+BA9 -> 0 | Q9: =AB9+AF9+AJ9+AN9+AR9+AV9+BB9 -> 0 | R9: =BD9+BF9 -> 0 | S9: =W9 -> 0 | T9: =Y9+AC9+AG9+AK9+AO9+AS9+AW9+AY9 -> 0 | U9: =Z9+AD9+AH9+AL9+AP9+AT9+AZ9 -> 0 | V9: =BC9+BE9 -> 0 | AB9: =Z9*995 -> 0 | AF9: =AD9*995 -> 0 | AJ9: =AH9*995 -> 0 | AM9: =AK9*1696 -> 0 | AN9: =AL9*995 -> 0 | AR9: =AP9*995 -> 0 | AV9: =AT9*995 -> 0 | BA9: =AY9*1696 -> 0 | BB9: =AZ9*995 -> 0 | BD9: =BC9*320 -> 0 | BF9: =BE9*320 -> 0 | BG9: =SUM(BH9:BL9) -> 0 | BR9: =SUM(BT9,BW9,BX9,BZ9,CB9) -> 0 | BX9: =BV9*995 -> 0 | BZ9: =BY9*320 -> 0 | CB9: =CA9*320 -> 0 | CC9: =SUM(CD9:CH9) -> 0
A10: 6 | C10: 数据服务 | D10: 景德镇市POI数据 | E10: 提供全市范围政务兴趣点（6类）： （1）政府及管理机构：包括各级人民政府、行政服务中心、街道办事处、乡镇政府、各类行政主管部门等，对应机构所在公开门址、楼址； （2）社会福利：包括养老院、福利院、救助站、残疾人服务中心、殡葬服务机构等，对应机构所在公开门址、楼址； （3）住宅设施：包括小区、公寓、别墅、保障性住房等，对应小区门址、住宅楼址； （4）科教文卫：包括幼儿园、小学、中学、高校、科研院所、图书馆、文化馆、医院、疾控中心、体育馆等，对应机构的公开门址、楼址； （5）休闲度假：包括公园、广场、游乐园、度假村、露营地等，对应单位公开的门址、楼址； （6）交通运输：包括火车站、汽车站、机场、码头、大型停车场、公路养护站等，对应交通运输设施的公开门址、地址。 | G10: 数据 | H10: 一次性交付 | N10: =O10+P10+Q10+R10 -> 0 | O10: =X10 -> 0 | P10: =AA10+AE10+AI10+AM10+AQ10+AU10+AX10+BA10 -> 0 | Q10: =AB10+AF10+AJ10+AN10+AR10+AV10+BB10 -> 0 | R10: =BD10+BF10 -> 0 | S10: =W10 -> 0 | T10: =Y10+AC10+AG10+AK10+AO10+AS10+AW10+AY10 -> 0 | U10: =Z10+AD10+AH10+AL10+AP10+AT10+AZ10 -> 0 | V10: =BC10+BE10 -> 0 | AB10: =Z10*995 -> 0 | AF10: =AD10*995 -> 0 | AJ10: =AH10*995 -> 0 | AM10: =AK10*1696 -> 0 | AN10: =AL10*995 -> 0 | AR10: =AP10*995 -> 0 | AV10: =AT10*995 -> 0 | BA10: =AY10*1696 -> 0 | BB10: =AZ10*995 -> 0 | BD10: =BC10*320 -> 0 | BF10: =BE10*320 -> 0 | BG10: =SUM(BH10:BL10) -> 0 | BR10: =SUM(BT10,BW10,BX10,BZ10,CB10) -> 0 | BX10: =BV10*995 -> 0 | BZ10: =BY10*320 -> 0 | CB10: =CA10*320 -> 0 | CC10: =SUM(CD10:CH10) -> 0
A11: 7 | C11: 数据服务 | D11: 九江市POI数据 | E11: 提供全市范围政务兴趣点（6类）： （1）政府及管理机构：包括各级人民政府、行政服务中心、街道办事处、乡镇政府、各类行政主管部门等，对应机构所在公开门址、楼址； （2）社会福利：包括养老院、福利院、救助站、残疾人服务中心、殡葬服务机构等，对应机构所在公开门址、楼址； （3）住宅设施：包括小区、公寓、别墅、保障性住房等，对应小区门址、住宅楼址； （4）科教文卫：包括幼儿园、小学、中学、高校、科研院所、图书馆、文化馆、医院、疾控中心、体育馆等，对应机构的公开门址、楼址； （5）休闲度假：包括公园、广场、游乐园、度假村、露营地等，对应单位公开的门址、楼址； （6）交通运输：包括火车站、汽车站、机场、码头、大型停车场、公路养护站等，对应交通运输设施的公开门址、地址。 | G11: 数据 | H11: 一次性交付 | N11: =O11+P11+Q11+R11 -> 0 | O11: =X11 -> 0 | P11: =AA11+AE11+AI11+AM11+AQ11+AU11+AX11+BA11 -> 0 | Q11: =AB11+AF11+AJ11+AN11+AR11+AV11+BB11 -> 0 | R11: =BD11+BF11 -> 0 | S11: =W11 -> 0 | T11: =Y11+AC11+AG11+AK11+AO11+AS11+AW11+AY11 -> 0 | U11: =Z11+AD11+AH11+AL11+AP11+AT11+AZ11 -> 0 | V11: =BC11+BE11 -> 0 | AB11: =Z11*995 -> 0 | AF11: =AD11*995 -> 0 | AJ11: =AH11*995 -> 0 | AN11: =AL11*995 -> 0 | AR11: =AP11*995 -> 0 | AV11: =AT11*995 -> 0 | BB11: =AZ11*995 -> 0 | BD11: =BC11*320 -> 0 | BF11: =BE11*320 -> 0 | BG11: =SUM(BH11:BL11) -> 0 | BR11: =SUM(BT11,BW11,BX11,BZ11,CB11) -> 0 | BX11: =BV11*995 -> 0 | BZ11: =BY11*320 -> 0 | CB11: =CA11*320 -> 0 | CC11: =SUM(CD11:CH11) -> 0
A12: 8 | C12: 数据服务 | D12: 鹰潭市POI数据 | E12: 提供全市范围政务兴趣点（6类）： （1）政府及管理机构：包括各级人民政府、行政服务中心、街道办事处、乡镇政府、各类行政主管部门等，对应机构所在公开门址、楼址； （2）社会福利：包括养老院、福利院、救助站、残疾人服务中心、殡葬服务机构等，对应机构所在公开门址、楼址； （3）住宅设施：包括小区、公寓、别墅、保障性住房等，对应小区门址、住宅楼址； （4）科教文卫：包括幼儿园、小学、中学、高校、科研院所、图书馆、文化馆、医院、疾控中心、体育馆等，对应机构的公开门址、楼址； （5）休闲度假：包括公园、广场、游乐园、度假村、露营地等，对应单位公开的门址、楼址； （6）交通运输：包括火车站、汽车站、机场、码头、大型停车场、公路养护站等，对应交通运输设施的公开门址、地址。 | G12: 数据 | H12: 一次性交付 | N12: =O12+P12+Q12+R12 -> 0 | O12: =X12 -> 0 | P12: =AA12+AE12+AI12+AM12+AQ12+AU12+AX12+BA12 -> 0 | Q12: =AB12+AF12+AJ12+AN12+AR12+AV12+BB12 -> 0 | R12: =BD12+BF12 -> 0 | S12: =W12 -> 0 | T12: =Y12+AC12+AG12+AK12+AO12+AS12+AW12+AY12 -> 0 | U12: =Z12+AD12+AH12+AL12+AP12+AT12+AZ12 -> 0 | V12: =BC12+BE12 -> 0 | AB12: =Z12*995 -> 0 | AF12: =AD12*995 -> 0 | AJ12: =AH12*995 -> 0 | AN12: =AL12*995 -> 0 | AR12: =AP12*995 -> 0 | AV12: =AT12*995 -> 0 | BB12: =AZ12*995 -> 0 | BD12: =BC12*320 -> 0 | BF12: =BE12*320 -> 0 | BG12: =SUM(BH12:BL12) -> 0 | BR12: =SUM(BT12,BW12,BX12,BZ12,CB12) -> 0 | BX12: =BV12*995 -> 0 | BZ12: =BY12*320 -> 0 | CB12: =CA12*320 -> 0 | CC12: =SUM(CD12:CH12) -> 0
A13: 9 | C13: 数据服务 | D13: 吉安市POI数据 | E13: 提供全市范围政务兴趣点（6类）： （1）政府及管理机构：包括各级人民政府、行政服务中心、街道办事处、乡镇政府、各类行政主管部门等，对应机构所在公开门址、楼址； （2）社会福利：包括养老院、福利院、救助站、残疾人服务中心、殡葬服务机构等，对应机构所在公开门址、楼址； （3）住宅设施：包括小区、公寓、别墅、保障性住房等，对应小区门址、住宅楼址； （4）科教文卫：包括幼儿园、小学、中学、高校、科研院所、图书馆、文化馆、医院、疾控中心、体育馆等，对应机构的公开门址、楼址； （5）休闲度假：包括公园、广场、游乐园、度假村、露营地等，对应单位公开的门址、楼址； （6）交通运输：包括火车站、汽车站、机场、码头、大型停车场、公路养护站等，对应交通运输设施的公开门址、地址。 | G13: 数据 | H13: 一次性交付 | N13: =O13+P13+Q13+R13 -> 0 | O13: =X13 -> 0 | P13: =AA13+AE13+AI13+AM13+AQ13+AU13+AX13+BA13 -> 0 | Q13: =AB13+AF13+AJ13+AN13+AR13+AV13+BB13 -> 0 | R13: =BD13+BF13 -> 0 | S13: =W13 -> 0 | T13: =Y13+AC13+AG13+AK13+AO13+AS13+AW13+AY13 -> 0 | U13: =Z13+AD13+AH13+AL13+AP13+AT13+AZ13 -> 0 | V13: =BC13+BE13 -> 0 | AB13: =Z13*995 -> 0 | AF13: =AD13*995 -> 0 | AJ13: =AH13*995 -> 0 | AN13: =AL13*995 -> 0 | AR13: =AP13*995 -> 0 | AV13: =AT13*995 -> 0 | BB13: =AZ13*995 -> 0 | BD13: =BC13*320 -> 0 | BF13: =BE13*320 -> 0 | BG13: =SUM(BH13:BL13) -> 0 | BR13: =SUM(BT13,BW13,BX13,BZ13,CB13) -> 0 | BX13: =BV13*995 -> 0 | BZ13: =BY13*320 -> 0 | CB13: =CA13*320 -> 0 | CC13: =SUM(CD13:CH13) -> 0
A14: 10 | C14: 数据服务 | D14: 宜春市POI数据 | E14: 提供全市范围政务兴趣点（6类）： （1）政府及管理机构：包括各级人民政府、行政服务中心、街道办事处、乡镇政府、各类行政主管部门等，对应机构所在公开门址、楼址； （2）社会福利：包括养老院、福利院、救助站、残疾人服务中心、殡葬服务机构等，对应机构所在公开门址、楼址； （3）住宅设施：包括小区、公寓、别墅、保障性住房等，对应小区门址、住宅楼址； （4）科教文卫：包括幼儿园、小学、中学、高校、科研院所、图书馆、文化馆、医院、疾控中心、体育馆等，对应机构的公开门址、楼址； （5）休闲度假：包括公园、广场、游乐园、度假村、露营地等，对应单位公开的门址、楼址； （6）交通运输：包括火车站、汽车站、机场、码头、大型停车场、公路养护站等，对应交通运输设施的公开门址、地址。
A15: 11 | C15: 数据服务 | D15: 上饶市POI数据 | E15: 提供全市范围政务兴趣点（6类）： （1）政府及管理机构：包括各级人民政府、行政服务中心、街道办事处、乡镇政府、各类行政主管部门等，对应机构所在公开门址、楼址； （2）社会福利：包括养老院、福利院、救助站、残疾人服务中心、殡葬服务机构等，对应机构所在公开门址、楼址； （3）住宅设施：包括小区、公寓、别墅、保障性住房等，对应小区门址、住宅楼址； （4）科教文卫：包括幼儿园、小学、中学、高校、科研院所、图书馆、文化馆、医院、疾控中心、体育馆等，对应机构的公开门址、楼址； （5）休闲度假：包括公园、广场、游乐园、度假村、露营地等，对应单位公开的门址、楼址； （6）交通运输：包括火车站、汽车站、机场、码头、大型停车场、公路养护站等，对应交通运输设施的公开门址、地址。 | G15: 数据 | H15: 一次性交付 | N15: =O15+P15+Q15+R15 -> 0 | O15: =X15 -> 0 | P15: =AA15+AE15+AI15+AM15+AQ15+AU15+AX15+BA15 -> 0 | Q15: =AB15+AF15+AJ15+AN15+AR15+AV15+BB15 -> 0 | R15: =BD15+BF15 -> 0 | S15: =W15 -> 0 | T15: =Y15+AC15+AG15+AK15+AO15+AS15+AW15+AY15 -> 0 | U15: =Z15+AD15+AH15+AL15+AP15+AT15+AZ15 -> 0 | V15: =BC15+BE15 -> 0 | AB15: =Z15*995 -> 0 | AF15: =AD15*995 -> 0 | AJ15: =AH15*995 -> 0 | AN15: =AL15*995 -> 0 | AR15: =AP15*995 -> 0 | AV15: =AT15*995 -> 0 | BB15: =AZ15*995 -> 0 | BD15: =BC15*320 -> 0 | BF15: =BE15*320 -> 0 | BG15: =SUM(BH15:BL15) -> 0 | BR15: =SUM(BT15,BW15,BX15,BZ15,CB15) -> 0 | BX15: =BV15*995 -> 0 | BZ15: =BY15*320 -> 0 | CB15: =CA15*320 -> 0 | CC15: =SUM(CD15:CH15) -> 0
A16: 填写说明： 1、红色部分由解决方案填写，蓝色部分由项目经理填写，橙色部分由交付运营填写，绿色部分由产研侧填写 2、总成本=项目经理成本（含差旅）+交付实施成本（含差旅）+标品成本 3、人天单价参考（执行时间：2026年1月1日起）（以下均不区分级别）： ① 自有人天-交付处：1696元/天 自有人天-数据产品处：1720元/天 自有人天-智能地图处：1752元/天 自有人天-公共组件处：1374元/天 自有人天-公共服务业务处：2204元/天 自有人天-行业售前方案处：2350元/天 自有人天-企业产品研发处：3001元/天 ②研发外包人员-除企服以外：995元/天 研发外包人员-企服：1022元/天 ③生产外包人员（不区分级别）：320元/天

Sheet 成本评估逻辑
A2: POI的当前指标情况
A3: 覆盖率：80%
A4: 过期率：30%
A5: 重复率：10%
A6: 属性准确率：84% | C6: =3000/17000 -> 0.17647059 | F6: 6500
A7: 本次目标 | E7: 70000 | F7: 8500
A8: 交付标准 | B8: 系统问题交付兜底后 | C8: 重点类型
A9: 普通类型：保持覆盖率80% | B9: 普通类型：保持覆盖率80% | C9: 覆盖率大于等于95% | E9: =($E$7-$F$7)*0.8+$F$7*0.95 -> 57275 | F9: =E9/$E$7 -> 0.81821429
A10: 普通类型：保持过期率30% | B10: 普通类型：保持过期率30% | C10: /
A11: 普通类型：保持重复率10% | B11: 普通类型：保持重复率8-9%，兜底1-2点 | C11: 重复率小于等于5% | E11: =($E$7-$F$7)*0.08+$F$7*0.05 -> 5345 | F11: =E11/$E$7 -> 0.076357143
A12: 普通类型：保持准确率84% | B12: 普通类型：分类和门牌不一致等部分数据问题提升，2-3个点左右；只处理12和6类型 | C12: 准确率大于等于90% | E12: =($E$7-$F$7)*0.86+$F$7*0.95 -> 60965 | F12: =E12/$E$7 -> 0.87092857
C13: 12类型提取（按照湘东区比例40%） | D13: 6类型提取（比例20%）
A14: 江西省POI数据量 | B14: 2400000 | C14: =B14*0.4 -> 960000 | D14: =B14*0.2 -> 480000 | F14: =8400/70000 -> 0.12
A15: 江西省楼栋名称量 | B15: 150000 | C15: =B15 -> 150000 | D15: =B15 -> 150000
E16: 按照6万计算，8400
C17: 重点核实量（按照内蒙1个城市12类型8500左右，6类型6500左右）
A20: 江西省11个地市 | C20: 重点类型人工核实量 | E20: 正编 | F20: 生产 | I20: 江西省POI数量 | L20: （1）政府及管理机构：包括各级人民政府、行政服务中心、街道办事处、乡镇政府、各类行政主管部门等，对应机构所在公开门址、楼址；
A21: 全省类型映射+部分地址的行政区划补充自动化处理+校验 | B21: / | C21: / | D21: =2*11*1695+1*11*320 -> 40810 | E21: 22 | F21: 11
A22: 全省基础问题修复兜底，如类型错误，门牌不一致等 | B22: / | C22: / | D22: =2*11*1695+8*4*320+6*7*320 -> 60970 | E22: 22 | F22: =8*4+6*7 -> 74 | N22: 呼和浩特市
A23: 4个-12个类型-部分重点类型，见右侧清单 | B23: =SUM(C14:C15)/11*2 -> 201818.18 | C23: =8500*4 -> 34000 | D23: =C23/200*320+2*1695 -> 57790 | E23: 2 | F23: 80 | I23: L1 | J23: 120 | L23: （2）社会福利：包括养老院、福利院、救助站、残疾人服务中心、殡葬服务机构等，对应机构所在公开门址、楼址； | N23: 重点类型二级类型 | O23: 数量
A24: 7个-6个类型-部分重点类型，见右侧清单 | B24: =SUM(D14:D15)/11*9 -> 515454.55 | C24: =6500*7 -> 45500 | D24: =C24/200*320+9*1695 -> 88055 | E24: 9 | F24: 292.5 | I24: L2 | J24: 70 | L24: （3）住宅设施：包括小区、公寓、别墅、保障性住房等，对应小区门址、住宅楼址； | M24: 政府及管理机构|公检法机构 | N24: 省/直辖市/自治区政府 | O24: 10
A25: 文档材料编辑及沟通，汇报，管理，交付差旅等 | D25: =10*1695 -> 16950 | E25: 10 | I25: L3 | J25: 60 | L25: （4）科教文卫：包括幼儿园、小学、中学、高校、科研院所、图书馆、文化馆、医院、疾控中心、体育馆等，对应机构的公开门址、楼址； | M25: 政府及管理机构 | N25: 地级市政府 | O25: 12
C26: =C23/200 -> 170 | D26: =SUM(D21:D25) -> 264575 | E26: =SUM(E21:E25) -> 65 | F26: =SUM(F21:F25) -> 457.5 | L26: （5）休闲度假：包括公园、广场、游乐园、度假村、露营地等，对应单位公开的门址、楼址； | M26: 政府及管理机构 | N26: 区县政府 | O26: 26
I27: 江西省楼栋数量 | J27: 18 | L27: （6）交通运输：包括火车站、汽车站、机场、码头、大型停车场、公路养护站等，对应交通运输设施的公开门址、地址。 | M27: 政府及管理机构 | N27: 乡、镇政府 | O27: 237
M28: 政府及管理机构 | N28: 国家级政府机关 | O28: 9
I29: 小区有名称 | J29: 227351 | M29: 政府及管理机构 | N29: 省级政府机关 | O29: 67
I30: 园区有名称 | J30: 10286 | M30: 政府及管理机构 | N30: 地级市级政府机关 | O30: 196
C31: 1696 | D31: 320 | I31: 商务楼宇 | J31: 4043 | L31: （1）政府及管理机构：包括各级人民政府、行政服务中心、街道办事处、乡镇政府、各类行政主管部门等，对应机构所在公开门址、楼址； | M31: 政府及管理机构 | N31: 区县级政府机关 | O31: 758
A32: 流程 | B32: 成果 | C32: 正编 | D32: 生产 | E32: 成本 | F32: 备注 | I32: 城中村 | J32: 61945 | L32: （2）公检法机构：包括各级人民法院、人民检察院、公安局、派出所、看守所、拘留所等，对应机构所在公开门址、楼址； | M32: 政府及管理机构 | N32: 乡、镇级政府机关 | O32: 2065
A33: 初始化交付 | B33: 自动化脚本 初始化+自动化修复成果 初始化质检报告 | C33: 10 | E33: =C33*$C$31 -> 16960 | F33: ①初始化数据获取：POI库——获取POI和AOI数据，门址库——获取楼栋数据获取 ②原始数据处理合并：根据AOI与楼栋的id上下级关系，POI库挂接提取门址库楼栋数据，合并得到各城市初始化数据 （涉及楼栋名称、地址的拼接处理） ③政务兴趣点分类：根据名称关键词+POI代码兜底，开发脚本分类到12大政务兴趣点的二级类型 ④地址处理修复：公交站地址处理，含“停运”等字眼处理；地址分列（行政区划列+主体列）+行政区划名称规范处理+点落面更新五级行政区划+无主体名称拼接+重复元素处理 ⑤成果质检：质检规则制定+脚本开发，检查明显且可修复的问题（数据重复、分类错误、地址标准化问题等）回到上述环节修复 ⑥转成果规格：转交付成果规格和坐标系 | I33: 政府机构 | J33: 3405 | L33: （3）宗教社团：包括各类宗教活动场所（寺庙、教堂等）、宗教团体办公机构，对应机构所在公开门址、楼址； | M33: 公检法机构 | N33: 公安局 | O33: 68
A34: 4城市重点类型补充和人工核实 | B34: 重点类型清单 重点类型名称、地址、坐标成果 | C34: =ROUND(77*4*10/60/8,0) -> 6 | D34: =4800*4/250 -> 76.8 | E34: =C34*$C$31+D34*$D$31 -> 34752 | F34: ①情报获取：4城市，覆盖12大类、132细类POI，其中77个预计需通过情报获取完整清单 ②自动化获取地址和坐标：坐标挖掘（参考呼和浩特和赤峰20万的poi量，需核实量级16000，自动化按70%） ③人工：检查自动化结果和人工补充地址和坐标（人工核实30%，量级平均单城市4800） ④情报清单和初始化数据去重：优先情报清单中的兴趣点 | M34: 公检法机构 | N34: 派出所 | O34: 140
A35: 7城市重点类型补充和人工核实 | B35: 重点类型清单 重点类型名称、地址、坐标成果 | C35: =ROUND(43*7*10/60/8,0) -> 6 | D35: =2400*7/250 -> 67.2 | E35: =C35*$C$31+D35*$D$31 -> 31680 | F35: ①情报获取：7城市，覆盖6大类、80细类POI，其中43个预计需通过情报获取完整清单 ②自动化获取地址和坐标：坐标挖掘（参考呼和浩特和赤峰20万的poi量，需核实量级8000，自动化按70%） ③人工：检查自动化结果和人工补充地址和坐标（人工核实30%，量级平均单城市2400） ④情报清单和初始化数据去重：优先情报清单中的兴趣点
A36: 常态化客户反馈 （数据缺失、数据正确性和数据现势性等问题） | B36: 问题核实结果和修复解决方案 | C36: 4 | D36: 40 | E36: =C36*$C$31+D36*$D$31 -> 19584 | I36: 教育 | J36: 10555 | L36: （4）社会福利：包括养老院、福利院、救助站、残疾人服务中心、殡葬服务机构等，对应机构所在公开门址、楼址； | M36: 公检法机构 | N36: 交警队 | O36: 68
A37: 一次更新 | B37: 策略：存量数据不下线， 只差分去重后补充一下库内完全新增的数据进行补充 | C37: 9 | E37: =C37*$C$31+D37*$D$31 -> 15264 | F37: 不上人工
A38: 项目验收文档编写 | C38: 4 | E38: =C38*1696 -> 6784 | I38: 医疗 | J38: 2811 | L38: （5）公共服务：包括政务服务大厅、公共厕所、垃圾转运站、社区服务中心、供热供水供电服务网点等，对应服务网点公开的门址、楼址； | M38: 公检法机构 | N38: 法院 | O38: 46
B39: 人天合计 | C39: =SUM(C33:C38) -> 39 | D39: =SUM(D33:D38) -> 184
B40: 交付成本合计： | E40: =SUM(E33:E38) -> 125024 | I40: 商业 | J40: 12415 | L40: （6）商业服务：包括商场、大型超市、酒店、加油站、银行网点、快递网点等，对应经营场所公开的门址、楼址； | M40: 公检法机构 | N40: 检察院 | O40: 46
L41: （7）住宅设施：包括小区、公寓、别墅、保障性住房等，对应小区门址、住宅楼址； | M41: 休闲度假 | N41: 公园 | O41: 230
L42: （8）科教文卫：包括幼儿园、小学、中学、高校、科研院所、图书馆、文化馆、医院、疾控中心、体育馆等，对应机构的公开门址、楼址； | M42: 休闲度假 | N42: 广场 | O42: 196
L43: （9）休闲度假：包括公园、广场、游乐园、度假村、露营地等，对应单位公开的门址、楼址； | M43: 休闲度假 | N43: 动物园 | O43: 37
...

Sheet 附2-产品与服务清单
A1: 填写责任人：解决方案 前置输入项：交付成本清单（功能项需映射标准产品名称）
A2: 一、产品份额表
A3: 项目名称：
A4: 序号 | B4: 产品名称 | C4: 产品刊例价（元） | D4: 产品报价（元） | E4: 产品折扣（=D/C） | F4: 产品交付成本（元） | G4: 产品交付总人天 | H4: 产品毛利 | I4: 说明
A5: 注： | B5: 从已有的标准产品清单目录中选择 | C5: 参考标准报价 | D5: 建设方案报价单金额 | E5: =产品报价/产品刊例价 | F5: 基于实施成本分拆，总成本<=实施总成本 | G5: 交付成本人天数 | H5: （=1-产品交付成本/（产品报价/1.06）） | I5: 特殊折扣说明
A6: 1 | B6: 统一地址运营 | C6: 347000 | D6: 229150 | E6: =D6/C6 -> 0.66037464 | F6: 86240 | G6: =SUMIFS('附3-交付成本评估'!P:P,'附3-交付成本评估'!C:C,B6)+SUMIFS('附3-交付成本评估'!Q:Q,'附3-交付成本评估'!C:C,B6)+SUMIFS('附3-交付成本评估'!R:R,'附3-交付成本评估'!C:C,B6) -> 0 | H6: =1-F6/(D6/1.06) -> 0.60107179
A7: 2 | B7: 项目定制 | E7: =D7/C7 -> #DIV/0! | G7: =SUMIFS('附3-交付成本评估'!P:P,'附3-交付成本评估'!C:C,B7)+SUMIFS('附3-交付成本评估'!Q:Q,'附3-交付成本评估'!C:C,B7)+SUMIFS('附3-交付成本评估'!R:R,'附3-交付成本评估'!C:C,B7) -> 0 | H7: =1-F7/(D7/1.06) -> #DIV/0!
A8: 3 | B8: 项目分包 | E8: =D8/C8 -> #DIV/0! | G8: =SUMIFS('附3-交付成本评估'!P:P,'附3-交付成本评估'!C:C,B8)+SUMIFS('附3-交付成本评估'!Q:Q,'附3-交付成本评估'!C:C,B8)+SUMIFS('附3-交付成本评估'!R:R,'附3-交付成本评估'!C:C,B8) -> 0 | H8: =1-F8/(D8/1.06) -> #DIV/0!
A9: 固定行 | B9: 项目合计 | C9: / | D9: 项目金额汇总 | E9: / | F9: 交付成本汇总 | G9: 交付人天汇总 | H9: 项目毛利 （注：不含销售成本/项目经理/项目管理成本等） | I9: 注：此处项目毛利≠项目贡毛（不含销售成本/项目经理/项目管理成本等）
A10: 合计值 | B10: / | C10: / | D10: =SUM(D6:D8) -> 229150 | E10: / | H10: =1-F10/(D10/1.06) -> 1 | I10: /
A12: 二、产品细项表
A13: 注：标品份额细拆（产品功能模块、刊例价、报价、折扣、功能模块说明）
A14: 标准产品明细
A15: 序号 | B15: 产品名称 | C15: 产品模块 | D15: 产品刊例价 | E15: 产品报价 | F15: 产品折扣 | G15: 产品交付总成本 | H15: 产品交付总人天 | I15: 产品交付-产研人天（正编+外包） | J15: 产品交付-生产外包人天 | K15: 产品毛利 | L15: 说明
A16: 注： | B16: 从已有的标准产品清单目录中选择 | C16: 标准产品方案的明细拆分 | D16: 参考标准报价 | E16: 建设方案报价单金额 | F16: =产品金额/产品刊例价 | G16: 基于实施成本分拆，总成本<=实施总成本 | H16: 交付成本人天数 | K16: （=1-产品交付成本/（产品报价/1.06））
A17: 1-1 | B17: 统一地址运营 | C17: 地址标准化治理工程 | D17: 347000 | E17: 229150 | F17: =E17/D17 -> 0.66037464 | G17: 86240 | H17: =I17+J17 -> 0 | I17: =SUMIFS('附3-交付成本评估'!T:T,'附3-交付成本评估'!C:C,B17,'附3-交付成本评估'!D:D,C17)+SUMIFS('附3-交付成本评估'!U:U,'附3-交付成本评估'!C:C,B17,'附3-交付成本评估'!D:D,C17) -> 0 | J17: =SUMIFS('附3-交付成本评估'!V:V,'附3-交付成本评估'!C:C,B17,'附3-交付成本评估'!D:D,C17) -> 0 | K17: =1-G17/(E17/1.06) -> 0.60107179
A18: 1-2 | B18: 地址资源运营平台 | C18: 地址服务平台 | H18: =I18+J18 -> 0 | I18: =SUMIFS('附3-交付成本评估'!T:T,'附3-交付成本评估'!C:C,B18,'附3-交付成本评估'!D:D,C18)+SUMIFS('附3-交付成本评估'!U:U,'附3-交付成本评估'!C:C,B18,'附3-交付成本评估'!D:D,C18) -> 0 | J18: =SUMIFS('附3-交付成本评估'!V:V,'附3-交付成本评估'!C:C,B18,'附3-交付成本评估'!D:D,C18) -> 0 | K18: =1-G18/(E18/1.06) -> #DIV/0!
A19: 1-3 | B19: 地址资源运营平台 | C19: 数据更新服务 | H19: =I19+J19 -> 0 | I19: =SUMIFS('附3-交付成本评估'!T:T,'附3-交付成本评估'!C:C,B19,'附3-交付成本评估'!D:D,C19)+SUMIFS('附3-交付成本评估'!U:U,'附3-交付成本评估'!C:C,B19,'附3-交付成本评估'!D:D,C19) -> 0 | J19: =SUMIFS('附3-交付成本评估'!V:V,'附3-交付成本评估'!C:C,B19,'附3-交付成本评估'!D:D,C19) -> 0 | K19: =1-G19/(E19/1.06) -> #DIV/0!
A20: 2-1 | H20: =I20+J20 -> 0 | I20: =SUMIFS('附3-交付成本评估'!T:T,'附3-交付成本评估'!C:C,B20,'附3-交付成本评估'!D:D,C20)+SUMIFS('附3-交付成本评估'!U:U,'附3-交付成本评估'!C:C,B20,'附3-交付成本评估'!D:D,C20) -> 0 | J20: =SUMIFS('附3-交付成本评估'!V:V,'附3-交付成本评估'!C:C,B20,'附3-交付成本评估'!D:D,C20) -> 0 | K20: =1-G20/(E20/1.06) -> #DIV/0!
A21: 2-2 | H21: =I21+J21 -> 0 | I21: =SUMIFS('附3-交付成本评估'!T:T,'附3-交付成本评估'!C:C,B21,'附3-交付成本评估'!D:D,C21)+SUMIFS('附3-交付成本评估'!U:U,'附3-交付成本评估'!C:C,B21,'附3-交付成本评估'!D:D,C21) -> 0 | J21: =SUMIFS('附3-交付成本评估'!V:V,'附3-交付成本评估'!C:C,B21,'附3-交付成本评估'!D:D,C21) -> 0 | K21: =1-G21/(E21/1.06) -> #DIV/0!

Sheet 附4-运维成本评估（决算用）
A1: 项目名称：
A2: 运维阶段起止时间 | F2: 运维阶段总成本
A3: 合计值 | I3: =SUM(I6:I15) -> 0 | J3: =SUM(J6:J15) -> 0 | K3: =SUM(K6:K15) -> 0 | L3: =SUM(L6:L15) -> 0 | M3: =SUM(M6:M15) -> 0 | N3: =SUM(N6:N15) -> 0 | O3: =SUM(O6:O15) -> 0 | P3: =SUM(P6:P15) -> 0 | ... U3: =SUM(U6:U15) -> 0 | X3: =SUM(X6:X15) -> 0 | Y3: =SUM(Y6:Y15) -> 0 | Z3: =SUM(Z6:Z15) -> 0 | AA3: =SUM(AA6:AA15) -> 0 | AB3: =SUM(AB6:AB15) -> 0 | AC3: =SUM(AC6:AC15) -> 0 | AD3: /
A4: 序号 | B4: 解决方案评估 | I4: 2.0 运维阶段- 销售成本 | M4: 2.1 运维阶段-人力成本： | N4: ① 项 目 经 理： | P4: ② 产 研 投 入： | T4: ③ 生产外包-数据类： | V4: ④ 生产外包-软件类： | X4: 2.2 运维阶段-差旅成本 | AD4: 按岗位人员投入人数说明
B5: 建设内容 | C5: 对应标准产品名称 （下拉选择） | D5: 建设内容-细分模块 | E5: 具体功能项 | F5: 功能描述 | G5: 最终交付物 | H5: 交付方式 | I5: 销售-人力成本 | J5: 销售-差旅 | K5: 销售-招待费 | L5: 销售-市场营销 | M5: 运维阶段- 人力成本总额 | N5: 项目经理 正编人天 | O5: 项目经理 正编金额 | P5: 产研 正编人天 | Q5: 产研 外包人天 | R5: 产研 正编金额 | S5: 产研 外包金额 | T5: 生产外包 人天 | U5: 生产外包 金额 | V5: 生产外包 人天 | W5: 生产外包 金额 | X5: 运维阶段- 差旅成本总额 | Y5: 运维阶段-差旅成本 项目经理-差旅、市内交通 | Z5: 运维阶段-差旅成本 项目经理-招待费 | AA5: 运维阶段-差旅成本 产研（正编+外包） | AB5: 运维阶段-差旅成本 生产外包（数据类） | AC5: 运维阶段-差旅成本 生产外包（软件类）
A6: 1 | C6: 统一地址运营 | M6: =SUM(O6,R6,S6,U6) -> 0 | O6: =N6*1750 -> 0 | R6: =P6*1750 -> 0 | S6: =Q6*890 -> 0 | U6: =T6*320 -> 0 | W6: =V6*320 -> 0 | X6: =SUM(Y6:AC6) -> 0 | AD6: 岗位（正编/外包）：人数+对应投入人天 ①产品岗：正编投入_人；外包投入_人 ②前端岗：正编投入_人；外包投入_人 ③后端岗：正编投入_人；外包投入_人 ④大数据开发：正编投入_人；外包投入_人 ⑤交付岗：正编投入_人 ⑥架构岗：正编投入_人；外包投入_人 ⑦其他：正编投入_人；外包投入_人 ......
A7: 2 | C7: 统一地址运营 | M7: =SUM(O7,R7,S7,U7) -> 0 | O7: =N7*1750 -> 0 | R7: =P7*1750 -> 0 | S7: =Q7*890 -> 0 | U7: =T7*320 -> 0 | W7: =V7*320 -> 0 | X7: =SUM(Y7:AC7) -> 0
A8: 3 | C8: 统一地址运营 | M8: =SUM(O8,R8,S8,U8) -> 0 | O8: =N8*1750 -> 0 | R8: =P8*1750 -> 0 | S8: =Q8*890 -> 0 | U8: =T8*320 -> 0 | W8: =V8*320 -> 0 | X8: =SUM(Y8:AC8) -> 0
A9: 4 | C9: 统一地址运营 | M9: =SUM(O9,R9,S9,U9) -> 0 | O9: =N9*1750 -> 0 | R9: =P9*1750 -> 0 | S9: =Q9*890 -> 0 | U9: =T9*320 -> 0 | W9: =V9*320 -> 0 | X9: =SUM(Y9:AC9) -> 0
A10: 5 | C10: 统一地址运营 | M10: =SUM(O10,R10,S10,U10) -> 0 | O10: =N10*1750 -> 0 | R10: =P10*1750 -> 0 | S10: =Q10*890 -> 0 | U10: =T10*320 -> 0 | W10: =V10*320 -> 0 | X10: =SUM(Y10:AC10) -> 0
A11: 6 | C11: 统一地址运营 | M11: =SUM(O11,R11,S11,U11) -> 0 | O11: =N11*1750 -> 0 | R11: =P11*1750 -> 0 | S11: =Q11*890 -> 0 | U11: =T11*320 -> 0 | W11: =V11*320 -> 0 | X11: =SUM(Y11:AC11) -> 0
A12: 7 | C12: 统一地址运营 | M12: =SUM(O12,R12,S12,U12) -> 0 | O12: =N12*1750 -> 0 | R12: =P12*1750 -> 0 | S12: =Q12*890 -> 0 | U12: =T12*320 -> 0 | W12: =V12*320 -> 0 | X12: =SUM(Y12:AC12) -> 0
A13: 8 | C13: 统一地址运营 | M13: =SUM(O13,R13,S13,U13) -> 0 | O13: =N13*1750 -> 0 | R13: =P13*1750 -> 0 | S13: =Q13*890 -> 0 | U13: =T13*320 -> 0 | W13: =V13*320 -> 0 | X13: =SUM(Y13:AC13) -> 0
A14: 9 | C14: 统一地址运营 | M14: =SUM(O14,R14,S14,U14) -> 0 | O14: =N14*1750 -> 0 | R14: =P14*1750 -> 0 | S14: =Q14*890 -> 0 | U14: =T14*320 -> 0 | W14: =V14*320 -> 0 | X14: =SUM(Y14:AC14) -> 0
A15: 10 | C15: 统一地址运营 | M15: =SUM(O15,R15,S15,U15) -> 0 | O15: =N15*1750 -> 0 | R15: =P15*1750 -> 0 | S15: =Q15*890 -> 0 | U15: =T15*320 -> 0 | W15: =V15*320 -> 0 | X15: =SUM(Y15:AC15) -> 0
A17: 填写说明： 1、红色部分由解决方案填写，蓝色部分由项目经理填写，橙色部分由交付运营填写，绿色部分由产研侧填写 2、总成本=项目经理成本（含差旅）+交付实施成本（含差旅）+标品成本 3、人天单价参考（执行时间：2025年7月1日起）： ①产研自有人天（不区分级别）：1750元/天； ②研发外包人员（不区分级别）：890元/天； ③生产外包人员（不区分级别）：320元/天
